Workbook
Name \P: #REF!
Name _: #REF!
Name __PF1: #REF!
Name _cbf1: #REF!
Name _cth1: #REF!
Name _cxe1: #REF!
Name _new97: #REF!
Name _PF2: #REF!
Name _PG1: #REF!
Name _PG2: #REF!
Name A: #N/A
Name Accounts: #REF!
Name Accounts1: #REF!
Name accts: #REF!
Name ACDATE: #REF!
Name acq: #REF!
Name Acquisition_Total_Cost: #REF!
Name Acres_Acquired: #REF!
Name address: #REF!
Name AliasTable: #REF!
Name Amenity: #REF!
Name Amenroof: #REF!
Name amo: #REF!
Name Amount: #REF!
Name Analysis_End_Date: #REF!
Name Analysis_End_Month: #REF!
Name Analysis_Length_Years: #REF!
Name Analysis_Start_Date: #REF!
Name Argus: ROW()-ROW([1]!rrFirstRow)-1
Name Argus: ROW()-ROW([1]!rrFirstRow)-1
Name Argus: ROW()-ROW([1]!rrFirstRow)-1
Name Argus: ROW()-ROW([1]!rrFirstRow)-1
Name ASDATE: #REF!
Name AsOf: #REF!
Name Asset_Number: #REF!
Name AssetChart: [1]!AssetChart
Name ASSUMP1: #REF!
Name ASSUMP2: #REF!
Name AveUnitSize: #REF!
Name Avg_Sales_Lead_Time: #REF!
Name AVILAFEES: #REF!
Name B: #N/A
Name BB_HC: #REF!
Name Beg_Bal: #REF!
Name BGRSF: #REF!
Name BillTo: #REF!
Name BillToAddress: #REF!
Name BillToCitySt: #REF!
Name BillToContact: #REF!
Name BillToCustomer: #REF!
Name BillToName: #REF!
Name BillToPhone: #REF!
Name BillToZip: #REF!
Name Blah: #REF!
Name blah8: #REF!
Name BNRSF: #REF!
Name Bud_Yr: #REF!
Name Budget_Year: #REF!
Name buildcount: '[2]Deal Sheet Inputs'!$C$77
Name buildcount: Inputs!$C$76

Sheet LENDER
B2: =[3]Inputs!D5 -> 2, 4-A & 4 Henderson Dr. | C2: =[3]Inputs!D6 -> Travelers Rest SC
B4: Lot/Unit Count : | C4: 5
B6: LTV : | C6: 0.7 | D6: Extension : | E6: 2 x 6 months x .5%
B7: LTC : | C7: 0.9 | D7: Guaranty Type : | E7: Limited Recourse
B9: Origination : | C9: 0.01
B10: Rate : | C10: 0.0925 | J10: Close | K10: Holdback | L10: Total
B11: Term : | C11: 18 | H11: Lender | I11: Lot Advance | J11: =D31 -> 59933.53 | K11: =D32 -> 302472.35 | L11: =J11+K11+J12 -> 384725.12
I12: IR + Closing | J12: =D24+D25+D26 -> 22319.234
D13: Per Unit | H13: Cash | J13: =D34 -> 65066.47 | L13: =J13+K13 -> 65066.47
B14: ARV : | C14: =D14*C4 -> 2995000 | D14: =[3]Inputs!I72 -> 599000 | E14: =C22/C14 -> 0.64227899 | F14: Lender LTV | J14: =SUM(J11:J13) -> 147319.23 | K14: =SUM(K11:K13) -> 302472.35 | L14: =SUM(L11:L13) -> 449791.59
B16: Land Purchase : | C16: 625000 | D16: =C16/$C$4 -> 125000
B18: Sitework/Horizontal Development : | C18: =D18*C4 -> 98800 | D18: ='[3]Acquisition Summary'!D22 -> 19760
B19: Vertical Construction Reserve : | C19: =D19*C4 -> 1413561.8 | D19: ='[3]Acquisition Summary'!D30 -> 282712.35
B20: Total Construction : | C20: =C19+C18 -> 1512361.8 | D20: =D19+D18 -> 302472.35
B22: Total Loan: | C22: =MIN((C14*C6),C28*C7) -> 1923625.6 | D22: =C22/$C$4 -> 384725.12
B24: Interest Reserve : | C24: =D24*$C$4 -> 82984.916 | D24: =[3]Inputs!O29 -> 16596.983
B25: Origination : | C25: =C22*C9 -> 19236.256 | D25: =C25/$C$4 -> 3847.2512
B26: Est. Closing Cost : | C26: =D26*C4 -> 9375 | D26: =[3]Inputs!D18 -> 1875
B27: Total Costs : | C27: =C28+C25+C26+C24 -> 2248957.9 | D27: =C27/$C$4 -> 449791.59
B28: Total Mortgageable Costs : | C28: =C20+C16 -> 2137361.8 | D28: =D20+D16 -> 427472.35 | E28: =C22/C28 -> 0.9 | F28: Lender LTC
B30: Net Loan after closing costs and IR: | C30: =C22-C24-C25-C26 -> 1812029.4 | D30: =D22-D24-D25-D26 -> 362405.88
B31: Lot Advance : | C31: =C30-C32 -> 299667.65 | D31: =C31/$C$4 -> 59933.53
B32: Construction Holdback : | C32: =C20 -> 1512361.8 | D32: =C32/$C$4 -> 302472.35
B34: Cash required at Close : | C34: =C28-C30 -> 325332.35 | D34: =C34/$C$4 -> 65066.47

Sheet Inputs
H1: Legend | I1: All cells need to be filled
B2: =D5 & " - Deal Sheet Inputs" -> 241 Willard Street - Deal Sheet Inputs | L2: Vertical Sources & Uses
B4: General Data | F4: Notes | L4: SOURCES | Z4: Acquistions Breakdown
B5: Address | D5: 241 Willard Street | O5: Total | P5: Cash at Close | Q5: Remaining | Z5: Commission | AA5: =D19 -> 0
B6: City, State, Zip | D6: Greenville, SC | L6: =+'Acquisition Summary'!B13 -> Renovo Loan | N6: =+O6/O8 -> 0.84722065 | O6: =+D96*buildcount -> 267728.88 | P6: =+IF(M23="Manual",P32-O7,D100) -> 77000 | Q6: =+IF(M23="Manual",Q32,O6-P6) -> 190728.88 | Z6: PHC Agent | AA6: =$AA$5*AB6 -> 0 | AB6: =1/3 -> 0.33333333 | AC6: =AC8=AA8 -> TRUE
B7: Seller Names | D7: Henderson Place LLC | L7: Total Required Equity | N7: =+O7/O8 -> 0.15277935 | O7: =+O32-O6 -> 48279.565 | P7: =+IF(M23="Manual",O7,P32-P6) -> 48279.565 | Q7: =+IF(M23="Manual",0,O7-P7) -> 0 | Z7: PHC Profit | AA7: =$AA$5*AB7 -> 0 | AB7: =2/3 -> 0.66666667 | AC7: Check
B8: Seller Mailing Address | L8: Total Sources | O8: =+O7+O6 -> 316008.44 | P8: =SUM(P6:P7) -> 125279.57 | Q8: =SUM(Q6:Q7) -> 190728.88 | Z8: Total | AA8: =SUM(AA6:AA7) -> 0 | AB8: =SUM(AB6:AB7) -> 1 | AC8: =Inputs!D19 -> 0
B9: Parcel # | D9: 54000404100 | Z9: Sales Breakdown
B10: MLS Listed | L10: USES | Z10: Sale Price | AA10: ='Investor Summary'!E12 -> 450000
B11: Home Type | D11: SFH | O11: Total | P11: Cost at Close | Q11: Remaining | R11: Per Unit | S11: Per SF Total | Z11: Agent | AA11: =$AA$10*AB11 -> 6750 | AB11: 0.015 | AC11: =AC13=AA13 -> TRUE
B12: Attorney | L12: Equity OverSubscription | O12: 0 | P12: =+O12 -> 0 | Q12: =+O12-P12 -> 0 | Z12: RCR Profit | AA12: =$AA$10*AB12 -> 4500 | AB12: 0.01 | AC12: Check
B13: Settlement Date | D13: 46081 | L13: Land Purchase | O13: =D16 -> 110000 | P13: =+O13 -> 110000 | Q13: =+O13-P13 -> 0 | R13: =O13/buildcount -> 110000 | S13: =(O13/$D$76)/buildcount -> 70.785071 | T13: <---Model assumes purchase commission is part of the land purchase price. If seller is not covering, make sure PP is inflated accordingly | Z13: RCR Total | AA13: =SUM(AA11:AA12) -> 11250 | AB13: =SUM(AB11:AB12) -> 0.025 | AC13: =Inputs!D86 -> 11250
L14: =+B19 -> Buyer Commission (RCR/PHC) | N14: =+C19 -> 0 | O14: =+D19 -> 0 | P14: =+O14 -> 0 | Q14: =+O14-P14 -> 0 | R14: =O14/buildcount -> 0 | S14: =(O14/$D$76)/buildcount -> 0
B15: Land Purchase & Closing Costs | F15: Notes | L15: PHC Fees | O15: =D20 -> 0 | P15: =+O15 -> 0 | Q15: =+O15-P15 -> 0 | R15: =O15/buildcount -> 0 | S15: =(O15/$D$76)/buildcount -> 0
B16: Contract Purchase Price (Total Project) | D16: 110000 | L16: Closing Costs | N16: =+C18 -> 0.015 | O16: =+(D17+D18+(D21*(C21="Nonapplicable"))) -> 1650 | P16: =+O16 -> 1650 | Q16: =+O16-P16 -> 0 | R16: =O16/buildcount -> 1650 | S16: =(O16/$D$76)/buildcount -> 1.0617761
B17: Seller Closing Costs | D17: 0 | L17: Total Acq Costs | O17: =+SUBTOTAL(9,O13:O16) -> 111650 | P17: =+SUBTOTAL(9,P13:P16) -> 111650 | Q17: =+O17-P17 -> 0 | R17: =O17/buildcount -> 111650 | S17: =(O17/$D$76)/buildcount -> 71.846847
B18: Buyer Closing Costs | C18: 0.015 | D18: =+D16*C18 -> 1650
B19: Buyer Commission (RCR/PHC) | C19: 0 | D19: =D16*C19 -> 0 | L19: Acquisitions Due Dilligence & Horizontal Costs | O19: =D45*buildcount -> 6850 | P19: 0 | Q19: =+O19-P19 -> 6850 | R19: =O19/buildcount -> 6850 | S19: =(O19/$D$76)/buildcount -> 4.4079794
B20: PHC Fees | L20: Site Specific Costs | O20: =D58*buildcount -> 12200 | P20: 0 | Q20: =+O20-P20 -> 12200 | R20: =O20/buildcount -> 12200 | S20: =(O20/$D$76)/buildcount -> 7.8507079
B21: Due Diligence Fee | C21: Applicable | D21: =IF(C21="Applicable",500,0) -> 500 | L21: Vertical Build | O21: =+SUBTOTAL(9,O22:O23) -> 160462.21 | P21: 0 | Q21: =+O21-P21 -> 160462.21 | R21: =O21/buildcount -> 160462.21 | S21: =(O21/$D$76)/buildcount -> 103.25754
B22: Due Diligence Date | D22: 46037 | L22: Sticks & Bricks | O22: =E76 -> 133718.51 | P22: 0 | Q22: =+O22-P22 -> 133718.51 | R22: =O22/buildcount -> 133718.51 | S22: =(O22/$D$76)/buildcount -> 86.047947
B23: Due Diligence Check Delivery Method | D23: Check | L23: =+F71 -> Builder Profit | M23: Manual | N23: 0.2 | O23: =IF(M23="Manual",O22*N23,IFERROR(MAX(0.15*O22,(Q6-SUM(Q20,Q22,Q24,Q25))),0)) -> 26743.702 | P23: 0 | Q23: =+O23-P23 -> 26743.702 | R23: =O23/buildcount -> 26743.702 | S23: =(O23/$D$76)/buildcount -> 17.209589
B24: Earnest Money | D24: 1000 | L24: Soft Costs (survey, eng, tap fees, ins, tax, etc.) | O24: =D68*buildcount -> 11216.667 | P24: 0 | Q24: =+O24-P24 -> 11216.667 | R24: =O24/buildcount -> 11216.667 | S24: =(O24/$D$76)/buildcount -> 7.2179322
B25: Earnest Money Delivery Method | D25: Wire | L25: General Conditions | N25: 0 | O25: =+O22*N25 -> 0 | P25: 0 | Q25: =+O25-P25 -> 0 | R25: =O25/buildcount -> 0 | S25: =(O25/$D$76)/buildcount -> 0
L26: Total Development Costs | O26: =+O21+O20+O24+O25+O19 -> 190728.88 | P26: =+P21+P20+P24+P25+P19 -> 0 | Q26: =+O26-P26 -> 190728.88 | R26: =O26/buildcount -> 190728.88 | S26: =(O26/$D$76)/buildcount -> 122.73416
B27: Acquisitions Due Dilligence & Horizontal Costs
B28: Subdivision Costs? | C28: N/A | D28: =+IF(C28="applicable", (725+1100+500+1200)/buildcount,0) -> 0 | L28: =+D92 & " Loan Origination" -> Renovo Loan Origination | N28: =+D94 -> 0.01 | O28: =+N28*O6 -> 2677.2888 | P28: =+O28 -> 2677.2888 | Q28: =+O28-P28 -> 0 | R28: =O28/buildcount -> 2677.2888 | S28: =(O28/$D$76)/buildcount -> 1.7228371
B29: Grading Lot / Clearing & Hauling | D29: =SUMIF('Brix Actual Budget'!D:D,Inputs!B29,'Brix Actual Budget'!C:C)+1500 -> 1500 | F29: Plus Tree clearing | L29: =+IF(D93="Yes","Interest Reserve","Interest Carry Expense") -> Interest Reserve | N29: =+D95 -> 0.1025 | O29: =+IFERROR(SUM('Monthly CF'!D35:AB35),0) -> 10952.277 | P29: =+IF(D93="Yes",O29,0) -> 10952.277 | Q29: =+O29-P29 -> 0 | R29: =O29/buildcount -> 10952.277 | S29: =(O29/$D$76)/buildcount -> 7.047797
B30: Demolition | D30: =SUMIF('Brix Actual Budget'!D:D,Inputs!B30,'Brix Actual Budget'!C:C) -> 0 | L30: Total Financing Costs | O30: =+SUBTOTAL(9,O28:O29) -> 13629.565 | P30: =+SUBTOTAL(9,P28:P29) -> 13629.565 | Q30: =+O30-P30 -> 0 | R30: =O30/buildcount -> 13629.565 | S30: =(O30/$D$76)/buildcount -> 8.7706341
B31: Survey - Initial Physical + Plot Plans | D31: =SUMIF('Brix Actual Budget'!D:D,Inputs!B31,'Brix Actual Budget'!C:C) -> 1800
B32: Survey - Set Pins (Rough Stake) | D32: =SUMIF('Brix Actual Budget'!D:D,Inputs!B32,'Brix Actual Budget'!C:C) -> 400 | L32: Total Uses | O32: =+O17+O26+O30 -> 316008.44 | P32: =+P17+P26+P30 -> 125279.57 | Q32: =+O32-P32 -> 190728.88 | R32: =O32/buildcount -> 316008.44 | S32: =(O32/$D$76)/buildcount -> 203.35164
B33: Survey - Stake Footings | D33: =SUMIF('Brix Actual Budget'!D:D,Inputs!B33,'Brix Actual Budget'!C:C) -> 450 | L33: Total Mortgageable Cost | O33: =+O13+O26 -> 300728.88 | P33: =+P13+P26 -> 110000 | Q33: =+Q13+Q26 -> 190728.88 | R33: =O33/buildcount -> 300728.88
B34: UDO Requiremenets | D34: =SUMIF('Brix Actual Budget'!D:D,Inputs!B34,'Brix Actual Budget'!C:C) -> 0
B35: LDIRL | D35: =SUMIF('Brix Actual Budget'!D:D,Inputs!B35,'Brix Actual Budget'!C:C) -> 0 | L35: PROJECT SCHEDULE
B36: Temp Drive | D36: =SUMIF('Brix Actual Budget'!D:D,Inputs!B36,'Brix Actual Budget'!C:C) -> 500 | L36: Purchase Date | P36: =Inputs!D13 -> 46081 | Q36: *If purchase date falls on any day other than the last day of the month, this will round to the end of the month first before adding the add'l construction start delay
B37: Erosion Control | D37: =SUMIF('Brix Actual Budget'!D:D,Inputs!B37,'Brix Actual Budget'!C:C) -> 2000 | L37: Construction Start | O37: 1 | P37: =+EDATE(P36,O37)+1 -> 46110
B38: Additional Driveway | D38: =SUMIF('Brix Actual Budget'!D:D,Inputs!B38,'Brix Actual Budget'!C:C) -> 0 | L38: Construction Complete | O38: =_xlfn.XLOOKUP(B72,'Reference Tab'!B5:B44,'Reference Tab'!M5:M44) -> 150 | P38: =+P37+O38 -> 46260
B39: Driveway Culvert | D39: =SUMIF('Brix Actual Budget'!D:D,Inputs!B39,'Brix Actual Budget'!C:C) -> 0 | L39: Marketing/Sale Complete | O39: 1 | P39: =+P38+(O39*30) -> 46290
B40: Soil Testing | D40: =SUMIF('Brix Actual Budget'!D:D,Inputs!B40,'Brix Actual Budget'!C:C) -> 200 | L40: TOTAL PROJECT DURATION | O40: =+P39-P36 -> 209
B41: Heritage Tree Mitigation | D41: =SUMIF('Brix Actual Budget'!D:D,Inputs!B41,'Brix Actual Budget'!C:C) -> 0
...

Sheet Fee Build Dashboard
B1: =+ "DEAL SHEET | "&D6 -> DEAL SHEET | 241 Willard Street | M1: Builder Profit | N1: 0.4 | P1: =+K6 -> 46081 | Q1: =+K7 -> 46110 | R1: =+EOMONTH(Q1,1) -> 46142 | S1: =+EOMONTH(R1,1) -> 46173 | T1: =+EOMONTH(S1,1) -> 46203 | U1: =+EOMONTH(T1,1) -> 46234 | V1: =+EOMONTH(U1,1) -> 46265 | W1: =+EOMONTH(V1,1) -> 46295 | X1: =+EOMONTH(W1,1) -> 46326 | Y1: =+EOMONTH(X1,1) -> 46356 | ... AA1: =+EOMONTH(Z1,1) -> 46418
M2: Builder Profit $ / Unit | N2: =+E24-'Acquisition Summary'!E26 -> 53487.404 | P2: 1 | Q2: 2 | R2: 3 | S2: 4 | T2: 5 | U2: 6 | V2: 7 | W2: 8 | X2: 9 | Y2: 10 | Z2: 11 | AA2: 12
M3: Fee Sticks & Bricks / SF | N3: =+E24/VLOOKUP(Inputs!#REF!,'Reference Tab'!B4:M44,3,0) -> #REF! | P3: =-D14 -> -69341.823 | Q3: =+IF(Q2=$J$9,$J$16,0) -> 0 | R3: =+IF(R2=$J$9,$J$16,0) -> 0 | S3: =+IF(S2=$J$9,$J$16,0) -> 0 | T3: =+IF(T2=$J$9,$J$16,0) -> 0 | U3: =+IF(U2=$J$9,$J$16,0) -> 0 | V3: =+IF(V2=$J$9,$J$16,0) -> 0 | W3: =+IF(W2=$J$9,$J$16,0) -> #REF! | X3: =+IF(X2=$J$9,$J$16,0) -> 0 | ... AA3: =+IF(AA2=$J$9,$J$16,0) -> 0
B5: Project Information | H5: Project Timeline / Milestones | J5: Month # | K5: Date | P5: XIRR | Q5: =+XIRR(P3:AA3,P1:AA1) -> #REF!
B6: Project Name | D6: =+Inputs!D5 -> 241 Willard Street | H6: =+Inputs!L36 -> Purchase Date | J6: 1 | K6: =+Inputs!P36 -> 46081
B7: Plan Name & # of Builds | D7: =+Inputs!#REF! & " x " & buildcount -> #REF! | H7: =+Inputs!L37 -> Construction Start | J7: =+J6+Inputs!O37 -> 2 | K7: =+Inputs!P37 -> 46110
B8: Link to Plans | D8: =+IFERROR(HYPERLINK(_xlfn.XLOOKUP(Inputs!#REF!,'Reference Tab'!B6:B35,'Reference Tab'!#REF!),Inputs!#REF! & " Plans"),"Not Available") -> Not Available | H8: =+Inputs!L38 -> Construction Complete | J8: =+ROUND(J7+(Inputs!O38/30),) -> 7 | K8: =+Inputs!P38 -> 46260
B9: Home Type & SF | D9: =VLOOKUP(Inputs!#REF!,'Reference Tab'!B4:M44,2,0)& " | " & VLOOKUP(Inputs!#REF!,'Reference Tab'!B4:M44,3,0) & " HSF" -> #REF! | H9: =TEXT(Inputs!L39,) -> Marketing/Sale Complete | J9: =+J8+Inputs!O39 -> 8 | K9: =+Inputs!P39 -> 46290
B11: Sources/Uses | C11: % of Total | D11: Amount | E11: Amount/Unit | F11: Funds at Close | H11: Cash at Sale Analysis | J11: Amount | K11: Amount/Unit
B12: Sources of Funds | H12: Gross Sales Price | J12: =+Inputs!O43 -> 0 | K12: =+J12/buildcount -> 0
B13: Construction Loan | C13: =SUM(D13)/D15 -> 0.79356541 | D13: =+(D18*0.7)+(D26*0.9) -> 266560.32 | E13: =+D13/buildcount -> 266560.32 | F13: =+F31-F14 -> 55937.742 | H13: Less: Sales Commission & Closing Costs | J13: =+Inputs!O43+Inputs!#REF! -> #REF! | K13: =+J13/buildcount -> #REF!
B14: Cash Equity | C14: =SUM(D14:D14)/D15 -> 0.20643459 | D14: =+D31-D13 -> 69341.823 | E14: =+D14/buildcount -> 69341.823 | F14: =+D14 -> 69341.823 | H14: Net Sales Proceeds | J14: =+J12+J13 -> #REF! | K14: =+K12+K13 -> #REF!
B15: Total Sources of Funds | D15: =SUM(D13:D14) -> 335902.15 | E15: =+D15/buildcount -> 335902.15 | F15: =SUM(F13:F14) -> 125279.57 | H15: Less: Senior Debt Repayment | J15: =-D13 -> -266560.32 | K15: =-E13 -> -266560.32
E16: =+D16/buildcount -> 0 | H16: Net Cash | J16: =+J14+J15 -> #REF! | K16: =+K14+K15 -> #REF!
B17: Uses of Funds | E17: =+D17/buildcount -> 0 | H17: Less: Upfront Equity | J17: =-D14 -> -69341.823 | K17: =-E14 -> -69341.823
B18: Land Purchase | D18: =+Inputs!O13 -> 110000 | E18: =+D18/buildcount -> 110000 | F18: =+Inputs!P13 -> 110000 | H18: Net Profit on Equity | J18: =+J16+J17 -> #REF! | K18: =+K16+K17 -> #REF!
B19: Acquisition Fee | D19: =+Inputs!O14 -> 0 | E19: =+D19/buildcount -> 0 | F19: =+Inputs!P14 -> 0
B20: Closing Costs | D20: =+Inputs!O16 -> 1650 | E20: =+D20/buildcount -> 1650 | F20: =+Inputs!P16 -> 1650 | H20: Return Metrics
B21: Total Acq Costs | D21: =+Inputs!O17 -> 111650 | E21: =+D21/buildcount -> 111650 | F21: =+Inputs!P17 -> 111650 | H21: XIRR | K21: =+Q5 -> #REF!
E22: =+D22/buildcount -> 0 | H22: Return Multiple | K22: =+J16/-J17 -> #REF!
B23: =+Inputs!L20 -> Site Specific Costs | D23: =+Inputs!O20 -> 12200 | E23: =+D23/buildcount -> 12200 | F23: =+Inputs!P20 -> 0
B24: Sticks & Bricks | D24: =+Inputs!O22*(1+N1) -> 187205.91 | E24: =+D24/buildcount -> 187205.91 | F24: =+Inputs!P22 -> 0
B25: =+Inputs!L24 -> Soft Costs (survey, eng, tap fees, ins, tax, etc.) | D25: =+Inputs!O24 -> 11216.667 | E25: =+D25/buildcount -> 11216.667 | F25: =+Inputs!P24 -> 0
B26: Total Development Costs | D26: =SUM(D23:D25) -> 210622.58 | E26: =SUM(E23:E25) -> 210622.58 | F26: =SUM(F23:F25) -> 0
B28: Loan Origination Fee | D28: =+Inputs!O28 -> 2677.2888 | E28: =+D28/buildcount -> 2677.2888 | F28: =+Inputs!P28 -> 2677.2888
B29: Estimated Loan Interest | D29: =+Inputs!O29 -> 10952.277 | E29: =+D29/buildcount -> 10952.277 | F29: =+Inputs!P29 -> 10952.277
B30: Total Financing Costs | D30: =+Inputs!O30 -> 13629.565 | E30: =+D30/buildcount -> 13629.565 | F30: =SUM(F28:F29) -> 13629.565
B31: Total Uses of Funds | D31: =+D21+D26+D30 -> 335902.15 | E31: =+E21+E26+E30 -> 335902.15 | F31: =+F30+F26+F21 -> 125279.57
B32: **Assumes X LTV / etc.

Sheet Acquisition Summary
B1: =+ "DEAL SHEET | "&D6 -> DEAL SHEET | 241 Willard Street | Q1: Sales Price Sensitivity | R1: 0
B5: Project Information | H5: Project Timeline / Milestones | K5: Month # | L5: Date
B6: Project Name | D6: =IF(ISBLANK(Inputs!D5),"",Inputs!D5) -> 241 Willard Street | H6: =+Inputs!L36 -> Purchase Date | K6: 1 | L6: =+Inputs!P36 -> 46081
B7: Plan Name & # of Builds | D7: =_xlfn.TEXTJOIN(" | ",TRUE,IF(AND(Inputs!B72<>"",Inputs!C72<>""),Inputs!B72 & " x " & Inputs!C72,""),IF(AND(Inputs!B73<>"",Inputs!C73<>""),Inputs!B73 & " x " & Inputs!C73,""),IF(AND(Inputs!B74<>"",Inputs!C74<>""),Inputs!B74 & " x " & Inputs!C74,""),IF(AND(Inputs!B75<>"",Inputs!C75<>""),Inputs!B75 & " x " & Inputs!C75,"")) -> Atlas II - SC x 1 | H7: =+Inputs!L37 -> Construction Start | K7: =+K6+Inputs!O37 -> 2 | L7: =+Inputs!P37 -> 46110
B8: Location | D8: =Inputs!D6 -> Greenville, SC | H8: =+Inputs!L38 -> Construction Complete | K8: =+ROUND(K7+(Inputs!O38/30),) -> 7 | L8: =+Inputs!P38 -> 46260
B9: Home Type | D9: =Inputs!D11 -> SFH | H9: =TEXT(Inputs!L39,) -> Marketing/Sale Complete | K9: =+K8+Inputs!O39 -> 8 | L9: =+Inputs!P39 -> 46290
B11: Sources/Uses | C11: % of Total | D11: Amount | E11: Amount/Build | F11: Funds at Close | H11: Profit Analysis | I11: Benchmark | J11: % | K11: Amount | L11: Amount/Unit | M11: Notes
B12: Sources of Funds | H12: Projected Sales Price | I12: 1 | J12: 1 | K12: =SUM('Monthly CF'!D26:AB26) -> 450000 | L12: =K12/buildcount -> 450000
B13: =+Inputs!D92& " Loan" -> Renovo Loan | C13: =SUM(D13)/D15 -> 0.84722065 | D13: =+Inputs!O6 -> 267728.88 | E13: =+D13/buildcount -> 267728.88 | F13: =+Inputs!P6 -> 77000 | H13: Less: Total Pad Cost | I13: =IF($D$9="SFH",_xlfn.XLOOKUP(H13,'CFO Summary'!C:C,'CFO Summary'!G:G),IF('Acquisition Summary'!$D$9="TH",_xlfn.XLOOKUP('Acquisition Summary'!H13,'CFO Summary'!C:C,'CFO Summary'!H:H))) -> 0.23 | J13: =K13/$K$12 -> 0.26333333 | K13: =D23 -> 118500 | L13: =K13/buildcount -> 118500
B14: Common Equity | C14: =SUM(D14:D14)/D15 -> 0.15277935 | D14: =+Inputs!O7 -> 48279.565 | E14: =+D14/buildcount -> 48279.565 | F14: =-'Monthly CF'!D45 -> 48279.565 | H14: Less: Total Direct Vertical | I14: =IF($D$9="SFH",_xlfn.XLOOKUP(H14,'CFO Summary'!C:C,'CFO Summary'!G:G),IF('Acquisition Summary'!$D$9="TH",_xlfn.XLOOKUP('Acquisition Summary'!H14,'CFO Summary'!C:C,'CFO Summary'!H:H))) -> 0.5 | J14: =K14/$K$12 -> 0.34918928 | K14: =D28 -> 157135.18 | L14: =K14/buildcount -> 157135.18
B15: Total Homebuilding Sources | D15: =SUM(D13:D14) -> 316008.44 | E15: =+D15/buildcount -> 316008.44 | F15: =SUM(F13:F14) -> 125279.57 | H15: Direct Profit | I15: =I12-I13-I14 -> 0.27 | J15: =J12-J13-J14 -> 0.38747739 | K15: =K12-K13-K14 -> 174364.82 | L15: =K15/buildcount -> 174364.82
H16: Less: Closing Costs | I16: 0.003 | J16: =K16/$K$12 -> 0.005 | K16: =Inputs!D89 -> 2250 | L16: =K16/buildcount -> 2250
B17: Uses of Funds | H17: Less: Incentives | I17: 0.015 | J17: =K17/$K$12 -> 0.022222222 | K17: =Inputs!D88 -> 10000 | L17: =K17/buildcount -> 10000
B18: Land Purchase | D18: =+Inputs!O13 -> 110000 | E18: =+D18/buildcount -> 110000 | F18: =+Inputs!P13 -> 110000 | H18: Less: Commissions (in-House & Outside) | I18: 0.05 | J18: =K18/$K$12 -> 0.05 | K18: =SUM(Inputs!D85:D86) -> 22500 | L18: =K18/buildcount -> 22500
B19: Acquisition Fee | D19: =+Inputs!O14 -> 0 | E19: =+D19/buildcount -> 0 | F19: =+Inputs!P14 -> 0 | H19: Gross Profit | I19: =I15-I16-I17-I18 -> 0.202 | J19: =J15-J16-J17-J18 -> 0.31025516 | K19: =K15-SUM(K16:K18) -> 139614.82 | L19: =K19/buildcount -> 139614.82
B20: Closing Costs | D20: =+Inputs!O16 -> 1650 | E20: =+D20/buildcount -> 1650 | F20: =+Inputs!P16 -> 1650
B21: Total Land Acq | D21: =+Inputs!O17 -> 111650 | E21: =+D21/buildcount -> 111650 | F21: =+Inputs!P17 -> 111650 | H21: Cash at Sale Analysis | K21: Amount | L21: Amount/Unit
B22: =Inputs!L19 -> Acquisitions Due Dilligence & Horizontal Costs | D22: =Inputs!O19 -> 6850 | E22: =+D22/buildcount -> 6850 | F22: =+Inputs!P18 -> 0 | H22: Net Sales Proceeds | K22: =K12-K16-K17-K18 -> 415250 | L22: =K22/buildcount -> 415250
B23: Total Pad Cost | C23: =+D23/D36 -> 0.37498998 | D23: =+D21+D22 -> 118500 | E23: =+E21+E22 -> 118500 | F23: =+F21+F22 -> 111650 | H23: Less: Senior Debt Repayment | K23: =D13 -> 267728.88 | L23: =K23/buildcount -> 267728.88
H24: Less: Equity/Mezz Capital Repayment | K24: =D14 -> 48279.565 | L24: =K24/buildcount -> 48279.565
B25: =+Inputs!L20 -> Site Specific Costs | D25: =+Inputs!O20 -> 12200 | E25: =+D25/buildcount -> 12200 | F25: =+Inputs!P20 -> 0 | H25: Less: Preferred Return/Mezz Interest Payment | K25: ='Monthly CF'!C51 -> 4549.0079 | L25: =K25/buildcount -> 4549.0079
B26: Sticks & Bricks | D26: =+Inputs!O22 -> 133718.51 | E26: =+D26/buildcount -> 133718.51 | F26: =+Inputs!P22 -> 0 | H26: Less: Profit Split to LP/Mezz | K26: ='Monthly CF'!C52 -> 0 | L26: =K26/buildcount -> 0
B27: =+Inputs!L24 -> Soft Costs (survey, eng, tap fees, ins, tax, etc.) | D27: =+Inputs!O24 -> 11216.667 | E27: =+D27/buildcount -> 11216.667 | F27: =+Inputs!P24 -> 0 | H27: Net Cash to RCH | K27: =K22-SUM(K23:K26) -> 94692.548 | L27: =L22-SUM(L23:L26) -> 94692.548
B28: Total Direct Vertical | D28: =D26+D27+D25 -> 157135.18 | E28: =+E26+E27+E25 -> 157135.18 | F28: =+F26+F27+F25 -> 0
B29: =+Inputs!L23 -> Builder Profit | C29: =+D29/D26 -> 0.2 | D29: =+Inputs!O23 -> 26743.702 | E29: =+D29/buildcount -> 26743.702 | F29: =+Inputs!P23 -> 0 | H29: Return Metrics
B30: Total Vertical Cost | C30: =+D30/D36 -> 0.58187964 | D30: =D28+D29 -> 183878.88 | E30: =+E28+E29 -> 183878.88 | F30: =+F28+F29 -> 0 | K30: XIRR | L30: CF Multiple
H31: Deal-Level | K31: =+XIRR('Monthly CF'!D45:AB45,'Monthly CF'!D2:AB2) -> 5.8419517 | L31: =IFERROR(SUM('Monthly CF'!D45:AB45)/-SUMIF('Monthly CF'!D45:AB45,"<0")+1, "N/A") -> 3.0555603
B32: =+Inputs!L28 -> Renovo Loan Origination | D32: =+Inputs!O28 -> 2677.2888 | E32: =+D32/buildcount -> 2677.2888 | F32: =+Inputs!P28 -> 2677.2888 | H32: =Inputs!D103 & " Equity/Mezz" -> Red Cedar SLFII Equity/Mezz | K32: =+Inputs!D108 -> 0.16769096 | L32: =+K35/J35 -> 1.0942222
B33: =+Inputs!L29 -> Interest Reserve | D33: =+Inputs!O29 -> 10952.277 | E33: =+D33/buildcount -> 10952.277 | F33: =+Inputs!P29 -> 10952.277 | H33: Red Cedar Equity | K33: =IFERROR(IRR('Monthly CF'!D58:AB58),"N/A") -> N/A
B34: Total Financing Costs | C34: =+D34/D36 -> 0.043130383 | D34: =+Inputs!O30 -> 13629.565 | E34: =+D34/buildcount -> 13629.565 | F34: =SUM(F32:F33) -> 13629.565 | J34: Contribution | K34: Total Cash Return | L34: Net Cash Return
H35: =+H32 -> Red Cedar SLFII Equity/Mezz | J35: =-'Monthly CF'!C49 -> 48279.565 | K35: =+'Monthly CF'!C53+'Acquisition Summary'!J35 -> 52828.573 | L35: =+K35-J35 -> 4549.0079
B36: Total Homebuilding Uses | D36: =+D23+D30+D34 -> 316008.44 | E36: =+E23+E30+E34 -> 316008.44 | F36: =+F23+F30+F34 -> 125279.57 | H36: RCH Promote | J36: 0 | K36: =+'Monthly CF'!C58 -> 94692.548 | L36: =+K36 -> 94692.548
B38: Sales Price Sensitivity | C38: 0 | D38: 0 | F38: 0
B39: % Change | C39: Sales Price/Build | D39: RCC Profit | E39: =+Inputs!D103 -> Red Cedar SLFII | F39: RCH Profit
B40: 0 | C40: =+K12/buildcount -> 450000 | D40: =Inputs!O23 -> 26743.702 | E40: =+L32 -> 1.0942222 | F40: =K27 -> 94692.548
B41: 0.05 | C41: 472500 | D41: 26743.702 | E41: 1.0942222 | F41: 115955.05
B42: 0.025 | C42: 461250 | D42: 26743.702 | E42: 1.0942222 | F42: 105323.8
B43: 0 | C43: 450000 | D43: 26743.702 | E43: 1.0942222 | F43: 94692.548
B44: -0.025 | C44: 438750 | D44: 26743.702 | E44: 1.0942222 | F44: 84061.298
B45: -0.05 | C45: 427500 | D45: 26743.702 | E45: 1.0942222 | F45: 73430.048
...

Sheet Investor Summary
B1: =+ "INVESTMENT DEAL SHEET | "&C6 -> INVESTMENT DEAL SHEET | 241 Willard Street
B5: Project Information | G5: Project Timeline / Milestones | I5: Month # | J5: Date
B6: Project Name | C6: =IF(ISBLANK(Inputs!D5),"",Inputs!D5) -> 241 Willard Street | G6: =+Inputs!L36 -> Purchase Date | I6: 1 | J6: =+Inputs!P36 -> 46081
B7: Plan Name & # of Builds | C7: =_xlfn.TEXTJOIN(" | ",TRUE,IF(AND(Inputs!B72<>"",Inputs!C72<>""),Inputs!B72 & " x " & Inputs!C72,""),IF(AND(Inputs!B73<>"",Inputs!C73<>""),Inputs!B73 & " x " & Inputs!C73,""),IF(AND(Inputs!B74<>"",Inputs!C74<>""),Inputs!B74 & " x " & Inputs!C74,""),IF(AND(Inputs!B75<>"",Inputs!C75<>""),Inputs!B75 & " x " & Inputs!C75,"")) -> Atlas II - SC x 1 | G7: =+Inputs!L37 -> Construction Start | I7: =+I6+Inputs!O37 -> 2 | J7: =+Inputs!P37 -> 46110
B8: Project Location | C8: =Inputs!D6 -> Greenville, SC | G8: =+Inputs!L38 -> Construction Complete | I8: =+ROUND(I7+(Inputs!O38/30),) -> 7 | J8: =+Inputs!P38 -> 46260
B9: Home Type & SF | C9: =_xlfn.TEXTJOIN(" | ",TRUE, IF(Inputs!B72<>"",Inputs!B72 & ", " & _xlfn.XLOOKUP(Inputs!B72,'Reference Tab'!B:B,'Reference Tab'!D:D,""),""), IF(Inputs!B73<>"",Inputs!B73 & ", " & _xlfn.XLOOKUP(Inputs!B73,'Reference Tab'!B:B,'Reference Tab'!D:D,""),""), IF(Inputs!B74<>"",Inputs!B74 & ", " & _xlfn.XLOOKUP(Inputs!B74,'Reference Tab'!B:B,'Reference Tab'!D:D,""),""), IF(Inputs!B75<>"",Inputs!B75 & ", " & _xlfn.XLOOKUP(Inputs!B75,'Reference Tab'!B:B,'Reference Tab'!D:D,""),"")) -> Atlas II - SC, 1554 | G9: =TEXT(Inputs!L39,) -> Marketing/Sale Complete | I9: =+I8+Inputs!O39 -> 8 | J9: =+Inputs!P39 -> 46290
B11: Profit Analysis | D11: % | E11: Amount | G11: Sources/Uses | H11: Amount | I11: Amount/Build | J11: Amount/SF
B12: Projected Sales Price | E12: =SUM('Monthly CF'!D26:AB26) -> 450000 | G12: Sources of Funds
B13: Less: Land Acquisition | E13: ='Acquisition Summary'!D21 -> 111650 | G13: =+Inputs!D92& " Loan" -> Renovo Loan | H13: =+Inputs!O6 -> 267728.88 | I13: =+H13/buildcount -> 267728.88 | J13: =I13/Inputs!$D$76 -> 172.28371
B14: Less: Site Specific Costs | E14: ='Acquisition Summary'!D25 -> 12200 | G14: Common Equity | H14: =+Inputs!O7 -> 48279.565 | I14: =+H14/buildcount -> 48279.565 | J14: =I14/Inputs!$D$76 -> 31.067931
B15: Less: Total Sticks & Bricks | E15: ='Acquisition Summary'!D26+'Acquisition Summary'!D29 -> 160462.21 | G15: Total Sources of Funds | H15: =SUM(H13:H14) -> 316008.44 | I15: =+H15/buildcount -> 316008.44 | J15: =I15/Inputs!$D$76 -> 203.35164
B16: Less: Soft Costs | E16: ='Acquisition Summary'!D27-'Acquisition Summary'!D31 -> 11216.667 | J16: =I16/Inputs!$D$76 -> 0
B17: Less: Acquisition DD, Horizontal Costs | E17: =Inputs!O19 -> 6850 | G17: Uses of Funds | J17: =I17/Inputs!$D$76 -> 0
B18: Direct Profit | D18: =E18/E12 -> 0.32804694 | E18: =E12-SUM(E13:E17) -> 147621.12 | G18: Acquisition & Closing Costs | H18: =+Inputs!O17 -> 111650 | I18: =+H18/buildcount -> 111650 | J18: =I18/Inputs!$D$76 -> 71.846847
B19: Less: Closing Costs & Incentives | E19: ='Acquisition Summary'!K16 -> 2250 | G19: Acquisition DD, Horizontal Costs | H19: =Inputs!O19 -> 6850 | I19: =H19/buildcount -> 6850 | J19: =I19/Inputs!$D$76 -> 4.4079794
B20: Less: Incentives | E20: ='Acquisition Summary'!K17 -> 10000 | G20: =+Inputs!L20 -> Site Specific Costs | H20: =+Inputs!O20 -> 12200 | I20: =+H20/buildcount -> 12200 | J20: =I20/Inputs!$D$76 -> 7.8507079
B21: Less: Commissions (in-House & Outside) | E21: ='Acquisition Summary'!K18 -> 22500 | G21: Total Sticks & Bricks | H21: =+Inputs!O22+Inputs!O23 -> 160462.21 | I21: =+H21/buildcount -> 160462.21 | J21: =I21/Inputs!$D$76 -> 103.25754
B22: Adusted Gross Gross Profit | D22: =E22/E12 -> 0.25082471 | E22: =E18-SUM(E19:E21) -> 112871.12 | G22: =+Inputs!L24 -> Soft Costs (survey, eng, tap fees, ins, tax, etc.) | H22: =+Inputs!O24 -> 11216.667 | I22: =+H22/buildcount -> 11216.667 | J22: =I22/Inputs!$D$76 -> 7.2179322
B23: Less: Financing Costs | E23: ='Acquisition Summary'!D34 -> 13629.565 | G23: Development Costs | H23: =+Inputs!O26 -> 190728.88 | I23: =+H23/buildcount -> 190728.88 | J23: =I23/Inputs!$D$76 -> 122.73416
B24: Net Sale Proceeds | D24: =E24/E12 -> 0.22053679 | E24: =E22-E23 -> 99241.556 | G24: Financing Costs | H24: =+Inputs!O30 -> 13629.565 | I24: =+H24/buildcount -> 13629.565 | J24: =I24/Inputs!$D$76 -> 8.7706341
G25: Total Uses of Funds | H25: =+H24+H23+H18 -> 316008.44 | I25: =+H25/buildcount -> 316008.44 | J25: =I25/Inputs!$D$76 -> 203.35164
B27: Investor Return Metrics
D28: XIRR | E28: CF Multiple
B29: Investor Returns | D29: =Inputs!D108 -> 0.16769096 | E29: ='Acquisition Summary'!L32 -> 1.0942222
B30: Investment Contribution | E30: =-'Acquisition Summary'!K59 -> -48279.565
B31: Accrued Preferred Return | E31: ='Monthly CF'!C51 -> 4549.0079
B32: Return of Capital | E32: =-E30 -> 48279.565
B33: Profit Split | E33: ='Monthly CF'!C52 -> 0
B34: Net Return | E34: =SUM(E30:E33) -> 4549.0079

Sheet Financing Summary
B3: =Inputs!D5 & " - Financing Summary" -> 241 Willard Street - Financing Summary
B8: Capital Stack | C8: $ | D8: %
B9: Senior Loan | C9: =Inputs!D96 -> 267728.88 | D9: =C9/$C$12 -> 0.84722065
B10: Mezzanine | C10: =IF(Inputs!D103="RCH",0,Inputs!D107) -> 48279.565 | D10: =C10/$C$12 -> 0.15277935
B11: RC Equity | C11: =IF(Inputs!D103="RCH",Inputs!D107,0) -> 0 | D11: =C11/$C$12 -> 0
B12: Total Equity | C12: =SUM(C9:C11) -> 316008.44 | D12: =SUM(D9:D11) -> 1
B15: Senior Lender | C15: =Inputs!D92 -> Renovo | D15: %
B16: Interest Reserve | C16: =Inputs!D93 -> Yes | D16: =Inputs!D95 -> 0.1025
B17: Origination | C17: =C9*D17 -> 2677.2888 | D17: =Inputs!D94 -> 0.01
B18: LTC | C18: =Inputs!D97 -> 270655.99 | D18: =Inputs!C97 -> 0.9
B19: LTV | C19: =Inputs!D98 -> 315000 | D19: =Inputs!C98 -> 0.7
B20: Custom Cap (Renovo Only) | C20: =Inputs!D99 -> 267728.88
B21: Term | C21: =DATEDIF(Inputs!P36,Inputs!P39,"M")&" MONTHS" -> 6 MONTHS
B23: Mezz Equity | C23: =Inputs!D103 -> Red Cedar SLFII | D23: %
B24: Investment | C24: =C10 -> 48279.565
B25: Preferred Return | C25: ='Acquisition Summary'!K25 -> 4549.0079 | D25: =Inputs!D105 -> 0.16
B26: Profit Split | C26: ='Acquisition Summary'!K26 -> 0 | D26: =Inputs!D106 -> 0
B27: Origination | C27: =Inputs!D104 -> 0
B28: Target Hold Time | C28: =C21 -> 6 MONTHS

Sheet CFO Summary
N1: Red Cedar Cash Flow | O1: Returns
G2: Benchmarks | N2: RCH Profit Split | O2: ='Monthly CF'!C58 -> 94692.548
F3: Actual | G3: SFH | H3: TH | N3: RCC Builder Profit | O3: ='Monthly CF'!C63 -> 26743.702
D4: Total | E4: Per Unit | F4: % | G4: % | H4: % | N4: RCH/PHC Fees & Commission | O4: ='Monthly CF'!C68 -> 4500
N5: RCCP Total Return | O5: =SUM(O2:O4) -> 125936.25
C6: Closings | D6: =buildcount -> 1
C7: ASP | D7: =IFERROR(D13/D6, "") -> 440000
C10: Revenue:
C11: Projected Sales Price | D11: ='Acquisition Summary'!K12 -> 450000 | E11: =IFERROR(D11/D$6, 0) -> 450000 | F11: =D11/D11 -> 1 | G11: 1 | H11: 1
C12: Less: Projected Sales Incentives | D12: ='Acquisition Summary'!K17 -> 10000 | E12: =IFERROR(D12/D$6, 0) -> 10000 | F12: =IFERROR(D12/D$11, "") -> 0.022222222 | G12: =0.001 -> 0.001 | H12: =0.001 -> 0.001
C13: Revenue | D13: =D11-D12 -> 440000 | E13: =E11-E12 -> 440000 | F13: =F11-F12 -> 0.97777778 | G13: =G11-G12 -> 0.999 | H13: =H11-H12 -> 0.999
C14: Cost Of Sales:
C15: Less: Total Pad Cost | D15: =Inputs!O13+Inputs!O14+Inputs!O15+Inputs!O20 -> 122200 | E15: =IFERROR(D15/D$6, 0) -> 122200 | F15: =IFERROR(D15/D$11, "") -> 0.27155556 | G15: 0.23 | H15: 0.3
C16: Less: Total Direct Vertical | D16: =Inputs!O26-Inputs!O20 -> 178528.88 | E16: =IFERROR(D16/D$6, 0) -> 178528.88 | F16: =IFERROR(D16/D$11, "") -> 0.39673084 | G16: 0.5 | H16: 0.43
C17: Less: Closing & Transaction Costs | D17: =Inputs!O16 -> 1650 | E17: =IFERROR(D17/D$6, 0) -> 1650 | F17: =IFERROR(D17/D$11, "") -> 0.0036666667 | G17: 0.003 | H17: 0.003
C18: Total Cost of Sales | D18: =SUM(D15:D17) -> 302378.88 | E18: =SUM(E15:E17) -> 302378.88 | F18: =SUM(F15:F17) -> 0.67195306 | G18: =SUM(G15:G17) -> 0.733 | H18: =SUM(H15:H17) -> 0.733
C19: Contribution Profit | D19: =D13-D18 -> 137621.12 | E19: =E13-E18 -> 137621.12 | F19: =F13-F18 -> 0.30582471 | G19: =G13-G18 -> 0.266 | H19: =H13-H18 -> 0.266
C21: Indirect Construction Expenses
C22: Less: Construction Field Management | D22: =$D$11*G22 -> 9900 | E22: =IFERROR(D22/D$6, 0) -> 9900 | F22: =D22/$D$11 -> 0.022 | G22: 0.022 | H22: 0.022
C23: Less: Office Production Support | D23: =$D$11*G23 -> 2700 | E23: =IFERROR(D23/D$6, 0) -> 2700 | F23: =D23/$D$11 -> 0.006 | G23: 0.006 | H23: 0.006
C24: Less: Warranty | D24: =$D$11*G24 -> 1575 | E24: =IFERROR(D24/D$6, 0) -> 1575 | F24: =D24/$D$11 -> 0.0035 | G24: 0.0035 | H24: 0.0035
C25: Total Indirect & Warranty | D25: =SUM(D22:D24) -> 14175 | E25: =SUM(E22:E24) -> 14175 | F25: =SUM(F22:F24) -> 0.0315 | G25: =SUM(G22:G24) -> 0.0315 | H25: =SUM(H22:H24) -> 0.0315
C27: Gross Profit | D27: =D19-D25 -> 123446.12 | E27: =E19-E25 -> 123446.12 | F27: =F19-F25 -> 0.27432471 | G27: =G19-G25 -> 0.2345 | H27: =H19-H25 -> 0.2345
C28: SG&A:
C29: Less: Outside Commissions | D29: =Inputs!D85 -> 11250 | E29: =IFERROR(D29/D$6, 0) -> 11250 | F29: =IFERROR(D29/D$13, "") -> 0.025568182 | G29: 0.025 | H29: 0.025
C30: Less: In-House Commissions | D30: =Inputs!D86 -> 11250 | E30: =IFERROR(D30/D$6, 0) -> 11250 | F30: =IFERROR(D30/D$13, "") -> 0.025568182 | G30: 0.025 | H30: 0.025
C31: Less: Advertising | D31: =$D$11*G31 -> 5400 | E31: =IFERROR(D31/D$6, 0) -> 5400 | F31: =IFERROR(D31/D$13, "") -> 0.012272727 | G31: 0.012 | H31: 0.012
C32: Less: Models | D32: =$D$11*G32 -> 0 | E32: =IFERROR(D32/D$6, 0) -> 0 | F32: =IFERROR(D32/D$13, "") -> 0 | G32: 0 | H32: 0
C33: Less: Other Sales & Marketing Expense | D33: =$D$11*G33 -> 1350 | E33: =IFERROR(D33/D$6, 0) -> 1350 | F33: =IFERROR(D33/D$13, "") -> 0.0030681818 | G33: 0.003 | H33: 0.003
C34: G & A | D34: =$D$11*G34 -> 20250 | E34: =IFERROR(D34/D$6, 0) -> 20250 | F34: =IFERROR(D34/D$13, "") -> 0.046022727 | G34: 0.045 | H34: 0.045
C35: Total SG&A | D35: =SUM(D29:D34) -> 49500 | E35: =SUM(E29:E34) -> 49500 | F35: =SUM(F29:F34) -> 0.1125 | G35: =SUM(G29:G34) -> 0.11 | H35: =SUM(H29:H34) -> 0.11
C36: EBITDA | D36: =D27-D35 -> 73946.121 | E36: =E27-E35 -> 73946.121 | F36: =IFERROR(D36/D$13, "") -> 0.16805937 | G36: =G27-G35 -> 0.1245 | H36: =H27-H35 -> 0.1245
C37: Interest, Depreciation & Amortization:
C38: Less: Senior Debt Financing Costs (Orgination & IR) | D38: =Inputs!O30 -> 13629.565 | E38: =D38/$D$6 -> 13629.565 | F38: =IFERROR(D38/D$13, "") -> 0.030976285
C39: Less: Mezz Pref | D39: ='Acquisition Summary'!K25 -> 4549.0079 | E39: =D39/$D$6 -> 4549.0079 | F39: =IFERROR(D39/D$13, "") -> 0.010338654
C40: Less: Mezz Profit Split | D40: ='Acquisition Summary'!L26 -> 0 | E40: =D40/$D$6 -> 0 | F40: =IFERROR(D40/D$13, "") -> 0
C41: Less: Depreciation | F41: =IFERROR(D41/D$13, "") -> 0 | G41: 0 | H41: 0
C42: Less: Amortization | F42: =IFERROR(D42/D$13, "") -> 0 | G42: 0 | H42: 0
C43: Total Interest, Depreciation & Amortization | D43: =SUM(D38:D42) -> 18178.573 | E43: =SUM(E38:E42) -> 18178.573 | F43: =IFERROR(D43/D$13,"") -> 0.041314939 | G43: =SUM(G41:G42) -> 0 | H43: =SUM(H41:H42) -> 0
C44: EBT From Operations [Pre-Tax Income] | D44: =D36-D43 -> 55767.548 | E44: =E36-E43 -> 55767.548 | F44: =IFERROR(D44/D$13, "") -> 0.12674443 | G44: =G36-G43 -> 0.1245 | H44: =H36-H43 -> 0.1245
...

Sheet Monthly CF
D1: 1 | E1: =+D1+1 -> 2 | F1: =+E1+1 -> 3 | G1: =+F1+1 -> 4 | H1: =+G1+1 -> 5 | I1: =+H1+1 -> 6 | J1: =+I1+1 -> 7 | K1: =+J1+1 -> 8 | L1: =+K1+1 -> 9 | ... AB1: =+AA1+1 -> 25
D2: =+Inputs!D13 -> 46081 | E2: =+EDATE(D2,1) -> 46109 | F2: =+EDATE(E2,1) -> 46140 | G2: =+EDATE(F2,1) -> 46170 | H2: =+EDATE(G2,1) -> 46201 | I2: =+EDATE(H2,1) -> 46231 | J2: =+EDATE(I2,1) -> 46262 | K2: =+EDATE(J2,1) -> 46293 | L2: =+EDATE(K2,1) -> 46323 | ... AB2: =+EDATE(AA2,1) -> 46811
D3: CLOSING | E3: {=+IF(AND(E2>Inputs!$P$36,E2<Inputs!P37),"PREDEV",IF(AND(E2>Inputs!$P$37,E2<=Inputs!$P$38),"VERTICAL",IF(AND(E2>=Inputs!$P$39,$D$3:D3<>"SALE"),"SALE","")))} -> PREDEV | F3: {=+IF(AND(F2>Inputs!$P$36,F2<Inputs!Q37),"PREDEV",IF(AND(F2>Inputs!$P$37,F2<=Inputs!$P$38),"VERTICAL",IF(AND(F2>=Inputs!$P$39,$D$3:E3<>"SALE"),"SALE","")))} -> VERTICAL | G3: {=+IF(AND(G2>Inputs!$P$36,G2<Inputs!R37),"PREDEV",IF(AND(G2>Inputs!$P$37,G2<=Inputs!$P$38),"VERTICAL",IF(AND(G2>=Inputs!$P$39,$D$3:F3<>"SALE"),"SALE","")))} -> VERTICAL | H3: {=+IF(AND(H2>Inputs!$P$36,H2<Inputs!S37),"PREDEV",IF(AND(H2>Inputs!$P$37,H2<=Inputs!$P$38),"VERTICAL",IF(AND(H2>=Inputs!$P$39,$D$3:G3<>"SALE"),"SALE","")))} -> VERTICAL | I3: {=+IF(AND(I2>Inputs!$P$36,I2<Inputs!T36),"PREDEV",IF(AND(I2>Inputs!$P$37,I2<=Inputs!$P$38),"VERTICAL",IF(AND(I2>=Inputs!$P$39,$D$3:H3<>"SALE"),"SALE","")))} -> VERTICAL | J3: {=+IF(AND(J2>Inputs!$P$36,J2<Inputs!U35),"PREDEV",IF(AND(J2>Inputs!$P$37,J2<=Inputs!$P$38),"VERTICAL",IF(AND(J2>=Inputs!$P$39,$D$3:I3<>"SALE"),"SALE","")))} | K3: {=+IF(AND(K2>Inputs!$P$36,K2<Inputs!V34),"PREDEV",IF(AND(K2>Inputs!$P$37,K2<=Inputs!$P$38),"VERTICAL",IF(AND(K2>=Inputs!$P$39,$D$3:J3<>"SALE"),"SALE","")))} -> SALE | L3: {=+IF(AND(L2>Inputs!$P$36,L2<Inputs!W34),"PREDEV",IF(AND(L2>Inputs!$P$37,L2<=Inputs!$P$38),"VERTICAL",IF(AND(L2>=Inputs!$P$39,$D$3:K3<>"SALE"),"SALE","")))} | M3: {=+IF(AND(M2>Inputs!$P$36,M2<Inputs!X34),"PREDEV",IF(AND(M2>Inputs!$P$37,M2<=Inputs!$P$38),"VERTICAL",IF(AND(M2>=Inputs!$P$39,$D$3:L3<>"SALE"),"SALE","")))} | N3: {=+IF(AND(N2>Inputs!$P$36,N2<Inputs!Y36),"PREDEV",IF(AND(N2>Inputs!$P$37,N2<=Inputs!$P$38),"VERTICAL",IF(AND(N2>=Inputs!$P$39,$D$3:M3<>"SALE"),"SALE","")))} | O3: {=+IF(AND(O2>Inputs!$P$36,O2<Inputs!Z36),"PREDEV",IF(AND(O2>Inputs!$P$37,O2<=Inputs!$P$38),"VERTICAL",IF(AND(O2>=Inputs!$P$39,$D$3:N3<>"SALE"),"SALE","")))} | P3: {=+IF(AND(P2>Inputs!$P$36,P2<Inputs!AA36),"PREDEV",IF(AND(P2>Inputs!$P$37,P2<=Inputs!$P$38),"VERTICAL",IF(AND(P2>=Inputs!$P$39,$D$3:O3<>"SALE"),"SALE","")))} | Q3: {=+IF(AND(Q2>Inputs!$P$36,Q2<Inputs!AB36),"PREDEV",IF(AND(Q2>Inputs!$P$37,Q2<=Inputs!$P$38),"VERTICAL",IF(AND(Q2>=Inputs!$P$39,$D$3:P3<>"SALE"),"SALE","")))} | R3: {=+IF(AND(R2>Inputs!$P$36,R2<Inputs!AC36),"PREDEV",IF(AND(R2>Inputs!$P$37,R2<=Inputs!$P$38),"VERTICAL",IF(AND(R2>=Inputs!$P$39,$D$3:Q3<>"SALE"),"SALE","")))} | S3: {=+IF(AND(S2>Inputs!$P$36,S2<Inputs!AD36),"PREDEV",IF(AND(S2>Inputs!$P$37,S2<=Inputs!$P$38),"VERTICAL",IF(AND(S2>=Inputs!$P$39,$D$3:R3<>"SALE"),"SALE","")))} | T3: {=+IF(AND(T2>Inputs!$P$36,T2<Inputs!AE36),"PREDEV",IF(AND(T2>Inputs!$P$37,T2<=Inputs!$P$38),"VERTICAL",IF(AND(T2>=Inputs!$P$39,$D$3:S3<>"SALE"),"SALE","")))} | U3: {=+IF(AND(U2>Inputs!$P$36,U2<Inputs!AF35),"PREDEV",IF(AND(U2>Inputs!$P$37,U2<=Inputs!$P$38),"VERTICAL",IF(AND(U2>=Inputs!$P$39,$D$3:T3<>"SALE"),"SALE","")))} | V3: {=+IF(AND(V2>Inputs!$P$36,V2<Inputs!AG35),"PREDEV",IF(AND(V2>Inputs!$P$37,V2<=Inputs!$P$38),"VERTICAL",IF(AND(V2>=Inputs!$P$39,$D$3:U3<>"SALE"),"SALE","")))} | W3: {=+IF(AND(W2>Inputs!$P$36,W2<Inputs!AH35),"PREDEV",IF(AND(W2>Inputs!$P$37,W2<=Inputs!$P$38),"VERTICAL",IF(AND(W2>=Inputs!$P$39,$D$3:V3<>"SALE"),"SALE","")))} | X3: {=+IF(AND(X2>Inputs!$P$36,X2<Inputs!AI35),"PREDEV",IF(AND(X2>Inputs!$P$37,X2<=Inputs!$P$38),"VERTICAL",IF(AND(X2>=Inputs!$P$39,$D$3:W3<>"SALE"),"SALE","")))} | Y3: {=+IF(AND(Y2>Inputs!$P$36,Y2<Inputs!AJ35),"PREDEV",IF(AND(Y2>Inputs!$P$37,Y2<=Inputs!$P$38),"VERTICAL",IF(AND(Y2>=Inputs!$P$39,$D$3:X3<>"SALE"),"SALE","")))} | Z3: {=+IF(AND(Z2>Inputs!$P$36,Z2<Inputs!AK35),"PREDEV",IF(AND(Z2>Inputs!$P$37,Z2<=Inputs!$P$38),"VERTICAL",IF(AND(Z2>=Inputs!$P$39,$D$3:Y3<>"SALE"),"SALE","")))} | AA3: {=+IF(AND(AA2>Inputs!$P$36,AA2<Inputs!AL35),"PREDEV",IF(AND(AA2>Inputs!$P$37,AA2<=Inputs!$P$38),"VERTICAL",IF(AND(AA2>=Inputs!$P$39,$D$3:Z3<>"SALE"),"SALE","")))} | AB3: {=+IF(AND(AB2>Inputs!$P$36,AB2<Inputs!AM35),"PREDEV",IF(AND(AB2>Inputs!$P$37,AB2<=Inputs!$P$38),"VERTICAL",IF(AND(AB2>=Inputs!$P$39,$D$3:AA3<>"SALE"),"SALE","")))}
C4: Total
B5: Land Closing
B6: Land Purchase | C6: =+SUM(D6:AB6) -> 110000 | D6: =Inputs!O13 -> 110000 | E6: 0 | F6: 0 | G6: 0 | H6: 0 | I6: 0 | J6: 0 | K6: 0 | L6: 0 | M6: 0 | N6: 0 | O6: 0 | P6: 0 | Q6: 0 | R6: 0 | S6: 0 | T6: 0 | U6: 0 | V6: 0 | W6: 0 | X6: 0 | Y6: 0 | Z6: 0 | AA6: 0 | AB6: 0
B7: Purchase Commission (RCR/PHC) | C7: =+SUM(D7:AB7) -> 0 | D7: =Inputs!O14+Inputs!D20 -> 0 | E7: 0 | F7: 0 | G7: 0 | H7: 0 | I7: 0 | J7: 0 | K7: 0 | L7: 0 | M7: 0 | N7: 0 | O7: 0 | P7: 0 | Q7: 0 | R7: 0 | S7: 0 | T7: 0 | U7: 0 | V7: 0 | W7: 0 | X7: 0 | Y7: 0 | Z7: 0 | AA7: 0 | AB7: 0
B8: Closing Costs | C8: =+SUM(D8:AB8) -> 1650 | D8: =Inputs!O16 -> 1650 | E8: 0 | F8: 0 | G8: 0 | H8: 0 | I8: 0 | J8: 0 | K8: 0 | L8: 0 | M8: 0 | N8: 0 | O8: 0 | P8: 0 | Q8: 0 | R8: 0 | S8: 0 | T8: 0 | U8: 0 | V8: 0 | W8: 0 | X8: 0 | Y8: 0 | Z8: 0 | AA8: 0 | AB8: 0
B10: Predev & Sitework
B11: Acquisitions Due Dilligence & Horizontal Costs | C11: =+SUM(D11:AB11) -> 6850 | D11: 0 | E11: =+IF(E$3="PREDEV",$AD11,0) -> 6850 | F11: =+IF(F$3="PREDEV",$AD11,0) -> 0 | G11: =+IF(G$3="PREDEV",$AD11,0) -> 0 | H11: =+IF(H$3="PREDEV",$AD11,0) -> 0 | I11: =+IF(I$3="PREDEV",$AD11,0) -> 0 | J11: =+IF(J$3="PREDEV",$AD11,0) -> 0 | K11: =+IF(K$3="PREDEV",$AD11,0) -> 0 | L11: =+IF(L$3="PREDEV",$AD11,0) -> 0 | ... AB11: =+IF(AB$3="PREDEV",$AD11,0) -> 0 | AD11: =Inputs!O19/COUNTIF($D$3:$AB$3,"PREDEV") -> 6850
B12: Soft Costs | C12: =+SUM(D12:AB12) -> 11216.667 | D12: 0 | E12: =+IF(E$3="PREDEV",$AD12,0) -> 11216.667 | F12: =+IF(F$3="PREDEV",$AD12,0) -> 0 | G12: =+IF(G$3="PREDEV",$AD12,0) -> 0 | H12: =+IF(H$3="PREDEV",$AD12,0) -> 0 | I12: =+IF(I$3="PREDEV",$AD12,0) -> 0 | J12: =+IF(J$3="PREDEV",$AD12,0) -> 0 | K12: =+IF(K$3="PREDEV",$AD12,0) -> 0 | L12: =+IF(L$3="PREDEV",$AD12,0) -> 0 | ... AB12: =+IF(AB$3="PREDEV",$AD12,0) -> 0 | AD12: =Inputs!O24/COUNTIF($D$3:$AB$3,"PREDEV") -> 11216.667
B13: Site Specific | C13: =+SUM(D13:AB13) -> 12200 | D13: 0 | E13: =+IF(E$3="PREDEV",$AD13,0) -> 12200 | F13: =+IF(F$3="PREDEV",$AD13,0) -> 0 | G13: =+IF(G$3="PREDEV",$AD13,0) -> 0 | H13: =+IF(H$3="PREDEV",$AD13,0) -> 0 | I13: =+IF(I$3="PREDEV",$AD13,0) -> 0 | J13: =+IF(J$3="PREDEV",$AD13,0) -> 0 | K13: =+IF(K$3="PREDEV",$AD13,0) -> 0 | L13: =+IF(L$3="PREDEV",$AD13,0) -> 0 | ... AB13: =+IF(AB$3="PREDEV",$AD13,0) -> 0 | AD13: =Inputs!O20/COUNTIF($D$3:$AB$3,"PREDEV") -> 12200
B15: =+Inputs!L28 -> Renovo Loan Origination | C15: =+SUM(D15:AB15) -> 2677.2888 | D15: =Inputs!O28 -> 2677.2888 | E15: 0 | F15: 0 | G15: 0 | H15: 0 | I15: 0 | J15: 0 | K15: 0 | L15: 0 | M15: 0 | N15: 0 | O15: 0 | P15: 0 | Q15: 0 | R15: 0 | S15: 0 | T15: 0 | U15: 0 | V15: 0 | W15: 0 | X15: 0 | Y15: 0 | Z15: 0 | AA15: 0 | AB15: 0
B17: Vertical Construction
B18: Vertical Build | C18: =+SUM(D18:AB18) -> 133718.51 | D18: 0 | E18: =+IF(E3="VERTICAL",$AD$18,0) -> 0 | F18: =+IF(F3="VERTICAL",$AD$18,0) -> 33429.628 | G18: =+IF(G3="VERTICAL",$AD$18,0) -> 33429.628 | H18: =+IF(H3="VERTICAL",$AD$18,0) -> 33429.628 | I18: =+IF(I3="VERTICAL",$AD$18,0) -> 33429.628 | J18: =+IF(J3="VERTICAL",$AD$18,0) -> 0 | K18: =+IF(K3="VERTICAL",$AD$18,0) -> 0 | L18: =+IF(L3="VERTICAL",$AD$18,0) -> 0 | ... AB18: =+IF(AB3="VERTICAL",$AD$18,0) -> 0 | AD18: =Inputs!O22/COUNTIF($D$3:$AB$3,"VERTICAL") -> 33429.628
B19: =+Inputs!L23 -> Builder Profit | C19: =+SUM(D19:AB19) -> 26743.702 | D19: 0 | E19: =+IF(E$3="VERTICAL",$AD19,0) -> 0 | F19: =+IF(F$3="VERTICAL",$AD19,0) -> 6685.9255 | G19: =+IF(G$3="VERTICAL",$AD19,0) -> 6685.9255 | H19: =+IF(H$3="VERTICAL",$AD19,0) -> 6685.9255 | I19: =+IF(I$3="VERTICAL",$AD19,0) -> 6685.9255 | J19: =+IF(J$3="VERTICAL",$AD19,0) -> 0 | K19: =+IF(K$3="VERTICAL",$AD19,0) -> 0 | L19: =+IF(L$3="VERTICAL",$AD19,0) -> 0 | ... AB19: =+IF(AB$3="VERTICAL",$AD19,0) -> 0 | AD19: =Inputs!O23/COUNTIF($D$3:$AB$3,"VERTICAL") -> 6685.9255
B20: =+Inputs!L25 -> General Conditions | C20: =+SUM(D20:AB20) -> 0 | D20: 0 | E20: =+IF(E$3="VERTICAL",$AD20,0) -> 0 | F20: =+IF(F$3="VERTICAL",$AD20,0) -> 0 | G20: =+IF(G$3="VERTICAL",$AD20,0) -> 0 | H20: =+IF(H$3="VERTICAL",$AD20,0) -> 0 | I20: =+IF(I$3="VERTICAL",$AD20,0) -> 0 | J20: =+IF(J$3="VERTICAL",$AD20,0) -> 0 | K20: =+IF(K$3="VERTICAL",$AD20,0) -> 0 | L20: =+IF(L$3="VERTICAL",$AD20,0) -> 0 | ... AB20: =+IF(AB$3="VERTICAL",$AD20,0) -> 0 | AC20: =+IF(AND(AC3="VERTICAL",AB3="PREDEV"),-Inputs!$O$25,"") | AD20: =Inputs!O25/COUNTIF($D$3:$AB$3,"VERTICAL") -> 0
B21: Total Development Costs (w/o interest) | C21: =SUM(C6:C20) -> 305056.17 | D21: =SUM(D6:D20) -> 114327.29 | E21: =SUM(E6:E20) -> 30266.667 | F21: =SUM(F6:F20) -> 40115.553 | G21: =SUM(G6:G20) -> 40115.553 | H21: =SUM(H6:H20) -> 40115.553 | I21: =SUM(I6:I20) -> 40115.553 | J21: =SUM(J6:J20) -> 0 | ... AB21: =SUM(AB6:AB20) -> 0
B23: Equity Over Subscription | C23: =SUM(D23:K23) -> 0 | D23: =-Inputs!P12 -> 0 | E23: 0 | F23: 0 | G23: 0 | H23: 0 | I23: 0 | J23: 0 | K23: =-D23 -> 0
B25: Sales
B26: Gross Sales Price | C26: =+SUM(D26:AB26) -> 450000 | D26: =+IF(D3="SALE",Inputs!$I$76*buildcount*(1+'Acquisition Summary'!$R$1),"") | E26: =+IF(E3="SALE",Inputs!$I$76*buildcount*(1+'Acquisition Summary'!$R$1),"") | F26: =+IF(F3="SALE",Inputs!$I$76*buildcount*(1+'Acquisition Summary'!$R$1),"") | G26: =+IF(G3="SALE",Inputs!$I$76*buildcount*(1+'Acquisition Summary'!$R$1),"") | H26: =+IF(H3="SALE",Inputs!$I$76*buildcount*(1+'Acquisition Summary'!$R$1),"") | I26: =+IF(I3="SALE",Inputs!$I$76*buildcount*(1+'Acquisition Summary'!$R$1),"") | J26: =+IF(J3="SALE",Inputs!$I$76*buildcount*(1+'Acquisition Summary'!$R$1),"") | K26: =+IF(K3="SALE",Inputs!$I$76*buildcount*(1+'Acquisition Summary'!$R$1),"") -> 450000 | ... AB26: =+IF(AB3="SALE",Inputs!$I$76*buildcount*(1+'Acquisition Summary'!$R$1),"")
B27: Less: Incentives | C27: =+SUM(D27:AB27) -> -10000 | D27: =+IF(D3="SALE",-Inputs!$D$88,"") | E27: =+IF(E3="SALE",-Inputs!$D$88,"") | F27: =+IF(F3="SALE",-Inputs!$D$88,"") | G27: =+IF(G3="SALE",-Inputs!$D$88,"") | H27: =+IF(H3="SALE",-Inputs!$D$88,"") | I27: =+IF(I3="SALE",-Inputs!$D$88,"") | J27: =+IF(J3="SALE",-Inputs!$D$88,"") | K27: =+IF(K3="SALE",-Inputs!$D$88,"") -> -10000 | ... AB27: =+IF(AB3="SALE",-Inputs!$D$88,"")
B28: Less: Title Costs & Commissions | C28: =+SUM(D28:AB28) -> -24750 | D28: =IF(D3="SALE",-Inputs!$D$89,"") | E28: =IF(E3="SALE",-Inputs!$D$89-Inputs!$D$85-Inputs!$D$86,"") | F28: =IF(F3="SALE",-Inputs!$D$89-Inputs!$D$85-Inputs!$D$86,"") | G28: =IF(G3="SALE",-Inputs!$D$89-Inputs!$D$85-Inputs!$D$86,"") | H28: =IF(H3="SALE",-Inputs!$D$89-Inputs!$D$85-Inputs!$D$86,"") | I28: =IF(I3="SALE",-Inputs!$D$89-Inputs!$D$85-Inputs!$D$86,"") | J28: =IF(J3="SALE",-Inputs!$D$89-Inputs!$D$85-Inputs!$D$86,"") | K28: =IF(K3="SALE",-Inputs!$D$89-Inputs!$D$85-Inputs!$D$86,"") -> -24750 | L28: =IF(L3="SALE",-Inputs!$D$89-Inputs!$D$85-Inputs!$D$86,"") | ... AB28: =IF(AB3="SALE",-Inputs!$D$89-Inputs!$D$85-Inputs!$D$86,"")
B29: Net Sales Proceeds | C29: =+SUM(D29:AB29) -> 415250 | D29: =SUM(D26:D28) -> 0 | E29: =SUM(E26:E28) -> 0 | F29: =SUM(F26:F28) -> 0 | G29: =SUM(G26:G28) -> 0 | H29: =SUM(H26:H28) -> 0 | I29: =SUM(I26:I28) -> 0 | J29: =SUM(J26:J28) -> 0 | K29: =SUM(K26:K28) -> 415250 | ... AB29: =SUM(AB26:AB28) -> 0
B32: =+Inputs!D92 &" Vertical Loan" -> Renovo Vertical Loan | C32: =+Inputs!O6 -> 267728.88
B33: Beginning Balance | D33: 0 | E33: =+D38 -> 77000 | F33: =+E38 -> 107266.67 | G33: =+F38 -> 147382.22 | H33: =+G38 -> 187497.77 | I33: =+H38 -> 227613.33 | J33: =+I38 -> 267728.88 | K33: =+J38 -> 267728.88 | L33: =+K38 -> 0 | ... AB33: =+AA38 -> 0
B34: Current Month Draw | C34: =+SUM(D34:AB34) -> 267728.88 | D34: =+Inputs!P6 -> 77000 | E34: =+MIN(E21,$C$32-E33) -> 30266.667 | F34: =+MIN(F21,$C$32-F33) -> 40115.553 | G34: =+MIN(G21,$C$32-G33) -> 40115.553 | H34: =+MIN(H21,$C$32-H33) -> 40115.553 | I34: =+MIN(I21,$C$32-I33) -> 40115.553 | J34: =+MIN(J21,$C$32-J33) -> 0 | K34: =+MIN(K21,$C$32-K33) -> 0 | L34: =+MIN(L21,$C$32-L33) -> 0 | ... AB34: =+MIN(AB21,$C$32-AB33) -> 0
B35: Interest Accrual | C35: =+SUM(D35:AB35) -> 10952.277 | D35: 0 | E35: =+E33*Inputs!$N$29/12 -> 657.70833 | F35: =+F33*Inputs!$N$29/12 -> 916.23611 | G35: =+G33*Inputs!$N$29/12 -> 1258.8898 | H35: =+H33*Inputs!$N$29/12 -> 1601.5435 | I35: =+I33*Inputs!$N$29/12 -> 1944.1972 | J35: =+J33*Inputs!$N$29/12 -> 2286.8508 | K35: =+K33*Inputs!$N$29/12 -> 2286.8508 | L35: =+L33*Inputs!$N$29/12 -> 0 | ... AB35: =+AB33*Inputs!$N$29/12 -> 0
B36: Interest Payment | C36: =+SUM(D36:AB36) -> -10952.277 | D36: =-D35 -> 0 | E36: =-E35 -> -657.70833 | F36: =-F35 -> -916.23611 | G36: =-G35 -> -1258.8898 | H36: =-H35 -> -1601.5435 | I36: =-I35 -> -1944.1972 | J36: =-J35 -> -2286.8508 | K36: =-K35 -> -2286.8508 | ... AB36: =-AB35 -> 0
B37: Payoff | C37: =+SUM(D37:AB37) -> -267728.88 | D37: 0 | E37: =-IF(E29>0,MIN(SUM(E33:E36),E29),0) -> 0 | F37: =-IF(F29>0,MIN(SUM(F33:F36),F29),0) -> 0 | G37: =-IF(G29>0,MIN(SUM(G33:G36),G29),0) -> 0 | H37: =-IF(H29>0,MIN(SUM(H33:H36),H29),0) -> 0 | I37: =-IF(I29>0,MIN(SUM(I33:I36),I29),0) -> 0 | J37: =-IF(J29>0,MIN(SUM(J33:J36),J29),0) -> 0 | K37: =-IF(K29>0,MIN(SUM(K33:K36),K29),0) -> -267728.88 | L37: =-IF(L29>0,MIN(SUM(L33:L36),L29),0) -> 0 | ... AB37: =-IF(AB29>0,MIN(SUM(AB33:AB36),AB29),0) -> 0
B38: Ending Balance | D38: =SUM(D33:D37) -> 77000 | E38: =SUM(E33:E37) -> 107266.67 | F38: =SUM(F33:F37) -> 147382.22 | G38: =SUM(G33:G37) -> 187497.77 | H38: =SUM(H33:H37) -> 227613.33 | I38: =SUM(I33:I37) -> 267728.88 | J38: =SUM(J33:J37) -> 267728.88 | K38: =SUM(K33:K37) -> 0 | ... AB38: =SUM(AB33:AB37) -> 0
B40: Interest Reserve
B41: Beginning Balance | D41: =+IF(Inputs!$D$93="Yes",Inputs!$O$29,0) -> 10952.277 | E41: =+D43 -> 10952.277 | F41: =+E43 -> 10294.568 | G41: =+F43 -> 9378.3321 | H41: =+G43 -> 8119.4423 | I41: =+H43 -> 6517.8988 | J41: =+I43 -> 4573.7017 | K41: =+J43 -> 2286.8508 | L41: =+K43 -> 0 | ... AB41: =+AA43 -> 0
B42: Adjustments | C42: =+SUM(D42:AB42) -> -10952.277 | D42: =-MIN(D35,D41) -> 0 | E42: =-MIN(E35,E41) -> -657.70833 | F42: =-MIN(F35,F41) -> -916.23611 | G42: =-MIN(G35,G41) -> -1258.8898 | H42: =-MIN(H35,H41) -> -1601.5435 | I42: =-MIN(I35,I41) -> -1944.1972 | J42: =-MIN(J35,J41) -> -2286.8508 | K42: =-MIN(K35,K41) -> -2286.8508 | ... AB42: =-MIN(AB35,AB41) -> 0
B43: Ending Balanace | D43: =SUM(D41:D42) -> 10952.277 | E43: =SUM(E41:E42) -> 10294.568 | F43: =SUM(F41:F42) -> 9378.3321 | G43: =SUM(G41:G42) -> 8119.4423 | H43: =SUM(H41:H42) -> 6517.8988 | I43: =SUM(I41:I42) -> 4573.7017 | J43: =SUM(J41:J42) -> 2286.8508 | K43: =SUM(K41:K42) -> 0 | ... AB43: =SUM(AB41:AB42) -> 0
B45: Net CF to Equity Sources | C45: =+SUM(D45:AB45) -> 99241.556 | D45: =-Inputs!O7 -> -48279.565 | E45: =-E21+E29+E34-E35-E42+E37+E23 -> 0 | F45: =-F21+F29+F34-F35-F42+F37+F23 -> 0 | G45: =-G21+G29+G34-G35-G42+G37+G23 -> 0 | H45: =-H21+H29+H34-H35-H42+H37+H23 -> 0 | I45: =-I21+I29+I34-I35-I42+I37+I23 -> 0 | J45: =-J21+J29+J34-J35-J42+J37+J23 -> 0 | K45: =-K21+K29+K34-K35-K42+K37+K23 -> 147521.12 | L45: =IF(L3="SALE",-L21+L29+L34-L35-L42+L37+L23,0) -> 0 | M45: =IF(M3="SALE",-M21+M29+M34-M35-M42+M37+M23,0) -> 0 | N45: =IF(N3="SALE",-N21+N29+N34-N35-N42+N37+N23,0) -> 0 | O45: =IF(O3="SALE",-O21+O29+O34-O35-O42+O37+O23,0) -> 0 | P45: =IF(P3="SALE",-P21+P29+P34-P35-P42+P37+P23,0) -> 0 | Q45: =IF(Q3="SALE",-Q21+Q29+Q34-Q35-Q42+Q37+Q23,0) -> 0 | R45: =IF(R3="SALE",-R21+R29+R34-R35-R42+R37+R23,0) -> 0 | S45: =IF(S3="SALE",-S21+S29+S34-S35-S42+S37+S23,0) -> 0 | ... AB45: =IF(AB3="SALE",-AB21+AB29+AB34-AB35-AB42+AB37+AB23,0) -> 0
B47: Interested Parties Cash Flows
B48: Limited Partner/Mezzanine
B49: Equity In | C49: =+SUM(D49:AB49) -> -48279.565 | D49: =-IF(Inputs!D103<>"RCH", Inputs!D107, 0) -> -48279.565 | E49: 0 | F49: 0 | G49: 0 | H49: 0 | I49: 0 | J49: 0 | K49: =+IF(K45<0,K45,0) -> 0 | L49: =+IF(L45<0,L45,0) -> 0 | M49: =+IF(M45<0,M45,0) -> 0 | N49: =+IF(N45<0,N45,0) -> 0 | O49: =+IF(O45<0,O45,0) -> 0 | P49: =+IF(P45<0,P45,0) -> 0 | Q49: =+IF(Q45<0,Q45,0) -> 0 | R49: =+IF(R45<0,R45,0) -> 0 | ... AB49: =+IF(AB45<0,AB45,0) -> 0
B50: Return of Capital | C50: =+SUM(D50:AB50) -> 48279.565 | E50: =+IF(E3="SALE",-$C$49,) -> 0 | F50: =+IF(F3="SALE",-$C$49,) -> 0 | G50: =+IF(G3="SALE",-$C$49,) -> 0 | H50: =+IF(H3="SALE",-$C$49,) -> 0 | I50: =+IF(I3="SALE",-$C$49,) -> 0 | J50: =+IF(J3="SALE",-$C$49,) -> 0 | K50: =+IF(K3="SALE",-$C$49,) -> 48279.565 | L50: =+IF(L3="SALE",-$C$49,) -> 0 | ... AB50: =+IF(AB3="SALE",-$C$49,) -> 0
...

Sheet Comps
A1: Comps below for Williard and Birnie: Some are over 1700 sqft, closer to 2000sqft I think our target is $450k - $475k Best comps: 109 Gates St (best comp) 1636 sqft $470k 15 Woodlawn $460k (1824 sqft) 15 E 5th st 26 b e main Old houses sold in the high $3's
A9: 109 Gates St (best comp) 1636 sqft $470k
A10: 15 Woodlawn $460k (1824 sqft)
A11: 15 E 5th st
A12: 26 b e main
A14: Old houses sold in the high $3's

Sheet Common Eq. WF
C2: COMMON EQUITY WATERFALL
D4: XIRR | E4: Multiple
C5: Deal-Level | D5: =+D11 -> 5.8419517 | E5: =+IFERROR(SUM(E15:AZ15)/-SUMIF(E15:AZ15,"<0")+1,"N/A") -> 3.0555603
C6: Common LP Equity | D6: =D9 -> 0.17307672 | E6: =+IFERROR(SUM(E51:AZ51)/-SUMIF(E51:AZ51,"<0")+1,"N/A") -> 1.0971507
A7: =IF('Acquisition Summary'!J57="Preferred",0,IF('Acquisition Summary'!J57="First Hurdle",1,IF('Acquisition Summary'!J57="Second Hurdle",2,3))) -> 0
E8: Year 0 | F8: 1 | G8: 2 | H8: 3 | I8: 4 | J8: 5 | K8: 6 | L8: 7 | M8: 8 | N8: 9 | O8: 10
C9: Common Equity LP Returns | D9: =+IFERROR(XIRR(E51:AZ51,E14:AZ14),"N/A") -> 0.17307672 | E9: =+E51 -> -48279.565 | F9: =+SUM(OFFSET($F$51,,(F8-1)*12,,12)) -> 52969.961 | G9: =+SUM(OFFSET($F$51,,(G8-1)*12,,12)) -> 0 | H9: =+SUM(OFFSET($F$51,,(H8-1)*12,,12)) -> 0 | I9: =+SUM(OFFSET($F$51,,(I8-1)*12,,12)) -> 0 | J9: =+SUM(OFFSET($F$51,,(J8-1)*12,,12)) -> 0 | K9: =+SUM(OFFSET($F$51,,(K8-1)*12,,12)) -> 0 | L9: =+SUM(OFFSET($F$51,,(L8-1)*12,,12)) -> 0 | M9: =+SUM(OFFSET($F$51,,(M8-1)*12,,12)) -> 0 | ... O9: =+SUM(OFFSET($F$51,,(O8-1)*12,,12)) -> 0
C10: Sponsor Total Returns | D10: =+IFERROR(IRR(E10:Q10),"N/A") -> N/A | E10: =+E52 -> 0 | F10: =+SUM(OFFSET($F$52,,(F8-1)*12,2,12)) -> 94551.16 | G10: =+SUM(OFFSET($F$52,,(G8-1)*12,2,12)) -> 0 | H10: =+SUM(OFFSET($F$52,,(H8-1)*12,2,12)) -> 0 | I10: =+SUM(OFFSET($F$52,,(I8-1)*12,2,12)) -> 0 | J10: =+SUM(OFFSET($F$52,,(J8-1)*12,2,12)) -> 0 | K10: =+SUM(OFFSET($F$52,,(K8-1)*12,2,12)) -> 0 | L10: =+SUM(OFFSET($F$52,,(L8-1)*12,2,12)) -> 0 | M10: =+SUM(OFFSET($F$52,,(M8-1)*12,2,12)) -> 0 | ... O10: =+SUM(OFFSET($F$52,,(O8-1)*12,2,12)) -> 0
C11: Deal-Level Returns | D11: =+XIRR(E15:AZ15,E14:AZ14) -> 5.8419517 | E11: =SUM(E9:E10) -> -48279.565 | F11: =SUM(F9:F10) -> 147521.12 | G11: =SUM(G9:G10) -> 0 | H11: =SUM(H9:H10) -> 0 | I11: =SUM(I9:I10) -> 0 | J11: =SUM(J9:J10) -> 0 | K11: =SUM(K9:K10) -> 0 | L11: =SUM(L9:L10) -> 0 | ... O11: =SUM(O9:O10) -> 0
C14: Month Number | E14: =+'Monthly CF'!D2 -> 46081 | F14: =+'Monthly CF'!E2 -> 46109 | G14: =+'Monthly CF'!F2 -> 46140 | H14: =+'Monthly CF'!G2 -> 46170 | I14: =+'Monthly CF'!H2 -> 46201 | J14: =+'Monthly CF'!I2 -> 46231 | K14: =+'Monthly CF'!J2 -> 46262 | L14: =+'Monthly CF'!K2 -> 46293 | ... AY14: =+'Monthly CF'!AX2 -> 0 | AZ14: 47057 | BB14: Exit Year | BD14: =+SUMIFS(E14:Q14,E16:Q16,">0") -> 0
C15: Project Cash Flow After Debt Service | E15: =+'Monthly CF'!D45 -> -48279.565 | F15: =+'Monthly CF'!E45 -> 0 | G15: =+'Monthly CF'!F45 -> 0 | H15: =+'Monthly CF'!G45 -> 0 | I15: =+'Monthly CF'!H45 -> 0 | J15: =+'Monthly CF'!I45 -> 0 | K15: =+'Monthly CF'!J45 -> 0 | L15: =+'Monthly CF'!K45 -> 147521.12 | ... AZ15: =+'Monthly CF'!AY45 -> 0
BB16: Cash Flow to Equity | BD16: =+HLOOKUP(BD14,E14:Q15,2,FALSE) -> #N/A
B17: x | C17: Preferred Return | BB17: Preferred Return
C18: LP Capital Account Balance | F18: =E20 -> -48279.565 | G18: =F22 -> -48923.293 | H18: =G22 -> -49575.603 | I18: =H22 -> -50236.611 | J18: =I22 -> -50906.433 | K18: =J22 -> -51585.185 | L18: =K22 -> -52272.988 | M18: =L22 -> 0 | N18: =M22 -> 0 | ... AZ18: =AY22 -> 0
C19: Pref Accrual | F19: =F18*'Acquisition Summary'!$J$53/12 -> -643.72754 | G19: =G18*'Acquisition Summary'!$J$53/12 -> -652.31057 | H19: =H18*'Acquisition Summary'!$J$53/12 -> -661.00805 | I19: =I18*'Acquisition Summary'!$J$53/12 -> -669.82149 | J19: =J18*'Acquisition Summary'!$J$53/12 -> -678.75244 | K19: =K18*'Acquisition Summary'!$J$53/12 -> -687.80247 | L19: =L18*'Acquisition Summary'!$J$53/12 -> -696.97317 | M19: =M18*'Acquisition Summary'!$J$53/12 -> 0 | ... AZ19: =AZ18*'Acquisition Summary'!$J$53/12 -> 0 | BB19: Pref Accrual | BD19: =+SUMIFS(F19:Q19,$F$14:$Q$14,$BD$14) -> 0
C20: Preferred CF | E20: =+E15 -> -48279.565 | F20: =+IF(F15>0,MIN(-SUM(F19),F15),F15) -> 0 | G20: =+IF(G15>0,MIN(-SUM(G19),G15),G15) -> 0 | H20: =+IF(H15>0,MIN(-SUM(H19),H15),H15) -> 0 | I20: =+IF(I15>0,MIN(-SUM(I19),I15),I15) -> 0 | J20: =+IF(J15>0,MIN(-SUM(J19),J15),J15) -> 0 | K20: =+IF(K15>0,MIN(-SUM(K19),K15),K15) -> 0 | L20: =+IF(L15>0,MIN(-SUM(L19),L15),L15) -> 696.97317 | M20: =+IF(M15>0,MIN(-SUM(M19),M15),M15) -> 0 | ... AZ20: =+IF(AZ15>0,MIN(-SUM(AZ19),AZ15),AZ15) -> 0 | BB20: Preferred CF | BD20: #N/A
C21: Net Sale Proceeds Payout | F21: =+IF(F15>0,MIN(F15-F20,-SUM(F18:F20)),0) -> 0 | G21: =+IF(G15>0,MIN(G15-G20,-SUM(G18:G20)),0) -> 0 | H21: =+IF(H15>0,MIN(H15-H20,-SUM(H18:H20)),0) -> 0 | I21: =+IF(I15>0,MIN(I15-I20,-SUM(I18:I20)),0) -> 0 | J21: =+IF(J15>0,MIN(J15-J20,-SUM(J18:J20)),0) -> 0 | K21: =+IF(K15>0,MIN(K15-K20,-SUM(K18:K20)),0) -> 0 | L21: =+IF(L15>0,MIN(L15-L20,-SUM(L18:L20)),0) -> 52272.988 | M21: =+IF(M15>0,MIN(M15-M20,-SUM(M18:M20)),0) -> 0 | ... AZ21: =+IF(AZ15>0,MIN(AZ15-AZ20,-SUM(AZ18:AZ20)),0) -> 0
C22: Ending Capital Account Balance | F22: =SUM(F18:F21) -> -48923.293 | G22: =SUM(G18:G21) -> -49575.603 | H22: =SUM(H18:H21) -> -50236.611 | I22: =SUM(I18:I21) -> -50906.433 | J22: =SUM(J18:J21) -> -51585.185 | K22: =SUM(K18:K21) -> -52272.988 | L22: =SUM(L18:L21) -> 0 | M22: =SUM(M18:M21) -> 0 | ... AZ22: =SUM(AZ18:AZ21) -> 0
BB23: Tier 1
C24: Remainder to Tier 1 | F24: =+F15+F16-F20-F21 -> 0 | G24: =+G15+G16-G20-G21 -> 0 | H24: =+H15+H16-H20-H21 -> 0 | I24: =+I15+I16-I20-I21 -> 0 | J24: =+J15+J16-J20-J21 -> 0 | K24: =+K15+K16-K20-K21 -> 0 | L24: =+L15+L16-L20-L21 -> 94551.16 | M24: =+M15+M16-M20-M21 -> 0 | ... AZ24: =+AZ15+AZ16-AZ20-AZ21 -> 0 | BB24: Pref Accrual | BD24: =+SUMIFS(F28:Q28,$F$14:$Q$14,$BD$14) -> 0
B25: x | C25: Tier 1 | D25: Passthru? | E25: No | BB25: Preferred CF | BD25: =+BD20 -> #N/A
BB26: Tier 1 CF | BD26: #REF!
C27: LP Capital Account Balance | F27: =E29 -> -48279.565 | G27: =F31 -> -48923.293 | H27: =G31 -> -49575.603 | I27: =H31 -> -50236.611 | J27: =I31 -> -50906.433 | K27: =J31 -> -51585.185 | L27: =K31 -> -52272.988 | M27: =L31 -> 0 | N27: =M31 -> 0 | ... AZ27: =AY31 -> 0
C28: Pref Accrual | F28: =IF($E$25="YES",F27*100%,F27*'Acquisition Summary'!$J$53/12) -> -643.72754 | G28: =IF($E$25="YES",G27*100%,G27*'Acquisition Summary'!$J$53/12) -> -652.31057 | H28: =IF($E$25="YES",H27*100%,H27*'Acquisition Summary'!$J$53/12) -> -661.00805 | I28: =IF($E$25="YES",I27*100%,I27*'Acquisition Summary'!$J$53/12) -> -669.82149 | J28: =IF($E$25="YES",J27*100%,J27*'Acquisition Summary'!$J$53/12) -> -678.75244 | K28: =IF($E$25="YES",K27*100%,K27*'Acquisition Summary'!$J$53/12) -> -687.80247 | L28: =IF($E$25="YES",L27*100%,L27*'Acquisition Summary'!$J$53/12) -> -696.97317 | M28: =IF($E$25="YES",M27*100%,M27*'Acquisition Summary'!$J$53/12) -> 0 | ... AZ28: =IF($E$25="YES",AZ27*100%,AZ27*'Acquisition Summary'!$J$53/12) -> 0 | BB28: CF to GP | BD28: #REF!
C29: Preferred CF | E29: =+E20 -> -48279.565 | F29: =+F20+F21 -> 0 | G29: =+G20+G21 -> 0 | H29: =+H20+H21 -> 0 | I29: =+I20+I21 -> 0 | J29: =+J20+J21 -> 0 | K29: =+K20+K21 -> 0 | L29: =+L20+L21 -> 52969.961 | M29: =+M20+M21 -> 0 | ... AZ29: =+AZ20+AZ21 -> 0 | BB29: Remainder to Tier 2 | BD29: =+#REF!-BD26-BD28 -> #REF!
