Workbook

Sheet Summary
A1: Red Cedar Model Comparison
A3: County | B3: None
A5: Model | B5: SFR/TH | C5: Heated SF | D5: Bed | E5: Bath | F5: Garage | G5: Unheated SF | H5: Floors | I5: Total $/ Heated SF | J5: Soft Cost | K5: Site Specific | L5: Sticks & Bricks | M5: S&B $/ Heated SF | N5: Total | O5: Classic | P5: Elegance | Q5: Harmony | R5: Pad Size | S5: Floorplan | T5: Notes
A6: Acacia | B6: SFH | C6: 2236 | D6: 4 | E6: 3 | F6: 2 | G6: 413 | H6: 1.5 | I6: =N6/C6 -> 79.846668 | J6: =IFERROR(_xlfn.XLOOKUP(A6,'MODEL SUMMARY'!$B$3:$AL$3,'MODEL SUMMARY'!$B$71:$AL$71)+_xlfn.XLOOKUP($B$3,'Water & Sewer Data'!$C:$C,'Water & Sewer Data'!$K:$K),"") -> 2650 | K6: =IFERROR(_xlfn.XLOOKUP(A6,'MODEL SUMMARY'!$B$3:$AL$3,'MODEL SUMMARY'!$B$66:$AL$66),"") -> 10875 | L6: =IFERROR(_xlfn.XLOOKUP(A6,'MODEL SUMMARY'!$B$3:$AL$3,'MODEL SUMMARY'!$B$58:$AL$58),"") -> 165012.15 | M6: =L6/C6 -> 73.79792 | N6: =SUM(J6:L6) -> 178537.15 | O6: 4200 | P6: 10000 | Q6: TBD | R6: 39/54 | T6: Standard covered back porch | U6: =LEFT(FIND("/",R6)
A7: Aspen 2-Story | B7: SFH | C7: 1788 | D7: 3 | E7: 2.5 | F7: 2 | G7: 400 | H7: 2 | I7: =N7/C7 -> 85.534972 | J7: =IFERROR(_xlfn.XLOOKUP(A7,'MODEL SUMMARY'!$B$3:$AL$3,'MODEL SUMMARY'!$B$71:$AL$71)+_xlfn.XLOOKUP($B$3,'Water & Sewer Data'!$C:$C,'Water & Sewer Data'!$K:$K),"") -> 2650 | K7: =IFERROR(_xlfn.XLOOKUP(A7,'MODEL SUMMARY'!$B$3:$AL$3,'MODEL SUMMARY'!$B$66:$AL$66),"") -> 10875 | L7: =IFERROR(_xlfn.XLOOKUP(A7,'MODEL SUMMARY'!$B$3:$AL$3,'MODEL SUMMARY'!$B$58:$AL$58),"") -> 139411.53 | M7: =L7/C7 -> 77.970654 | N7: =SUM(J7:L7) -> 152936.53 | O7: 4750 | P7: 9600 | Q7: TBD | R7: 24-33 | AA7: Last Updated 12.14.2024
A8: Atlas | B8: SFH | C8: 1554 | D8: 3 | E8: 2.5 | F8: 0 | G8: 0 | H8: 2 | I8: =N8/C8 -> 81.918745 | J8: =IFERROR(_xlfn.XLOOKUP(A8,'MODEL SUMMARY'!$B$3:$AL$3,'MODEL SUMMARY'!$B$71:$AL$71)+_xlfn.XLOOKUP($B$3,'Water & Sewer Data'!$C:$C,'Water & Sewer Data'!$K:$K),"") -> 2650 | K8: =IFERROR(_xlfn.XLOOKUP(A8,'MODEL SUMMARY'!$B$3:$AL$3,'MODEL SUMMARY'!$B$66:$AL$66),"") -> 10875 | L8: =IFERROR(_xlfn.XLOOKUP(A8,'MODEL SUMMARY'!$B$3:$AL$3,'MODEL SUMMARY'!$B$58:$AL$58),"") -> 113776.73 | M8: =L8/C8 -> 73.215399 | N8: =SUM(J8:L8) -> 127301.73 | O8: 4200 | P8: 8800 | Q8: TBD | R8: 24/33 | AA8: Old Pricing numbers from old deal sheet
A9: Banyan | B9: SFH | C9: 1400 | D9: 3 | E9: 3 | F9: 2 | G9: 582 | H9: 3 | I9: =N9/C9 -> 105.4161 | J9: =IFERROR(_xlfn.XLOOKUP(A9,'MODEL SUMMARY'!$B$3:$AL$3,'MODEL SUMMARY'!$B$71:$AL$71)+_xlfn.XLOOKUP($B$3,'Water & Sewer Data'!$C:$C,'Water & Sewer Data'!$K:$K),"") -> 2650 | K9: =IFERROR(_xlfn.XLOOKUP(A9,'MODEL SUMMARY'!$B$3:$AL$3,'MODEL SUMMARY'!$B$66:$AL$66),"") -> 10875 | L9: =IFERROR(_xlfn.XLOOKUP(A9,'MODEL SUMMARY'!$B$3:$AL$3,'MODEL SUMMARY'!$B$58:$AL$58),"") -> 134057.54 | M9: =L9/C9 -> 95.755386 | N9: =SUM(J9:L9) -> 147582.54 | O9: 4600 | P9: 10300 | Q9: TBD | R9: 28/24 | AA9: Archived Models. No pricing updates
A10: Cherry | B10: SFH | C10: 2214 | D10: 4 | E10: 3 | F10: 2 | G10: 428 | H10: 2 | I10: =N10/C10 -> 76.981965 | J10: =IFERROR(_xlfn.XLOOKUP(A10,'MODEL SUMMARY'!$B$3:$AL$3,'MODEL SUMMARY'!$B$71:$AL$71)+_xlfn.XLOOKUP($B$3,'Water & Sewer Data'!$C:$C,'Water & Sewer Data'!$K:$K),"") -> 2650 | K10: =IFERROR(_xlfn.XLOOKUP(A10,'MODEL SUMMARY'!$B$3:$AL$3,'MODEL SUMMARY'!$B$66:$AL$66),"") -> 10875 | L10: =IFERROR(_xlfn.XLOOKUP(A10,'MODEL SUMMARY'!$B$3:$AL$3,'MODEL SUMMARY'!$B$58:$AL$58),"") -> 156913.07 | M10: =L10/C10 -> 70.873112 | N10: =SUM(J10:L10) -> 170438.07 | O10: 5000 | P10: 11000 | Q10: TBD | R10: 38/38 | AA10: One time models
A11: Dogwood | B11: SFH | C11: 1541 | D11: 3 | E11: 2.5 | F11: 2 | G11: 397 | H11: 2 | I11: =N11/C11 -> 89.264101 | J11: =IFERROR(_xlfn.XLOOKUP(A11,'MODEL SUMMARY'!$B$3:$AL$3,'MODEL SUMMARY'!$B$71:$AL$71)+_xlfn.XLOOKUP($B$3,'Water & Sewer Data'!$C:$C,'Water & Sewer Data'!$K:$K),"") -> 2650 | K11: =IFERROR(_xlfn.XLOOKUP(A11,'MODEL SUMMARY'!$B$3:$AL$3,'MODEL SUMMARY'!$B$66:$AL$66),"") -> 10875 | L11: =IFERROR(_xlfn.XLOOKUP(A11,'MODEL SUMMARY'!$B$3:$AL$3,'MODEL SUMMARY'!$B$58:$AL$58),"") -> 124030.98 | M11: =L11/C11 -> 80.487333 | N11: =SUM(J11:L11) -> 137555.98 | O11: 4000 | P11: 8300 | Q11: TBD | R11: 29/36 | AA11: Future Plans - No line-itemed budget. Still being bidded out
A12: Hazel | B12: SFH | C12: 1713 | D12: 4 | E12: 2.5 | F12: 2 | G12: 677 | H12: 2 | I12: =N12/C12 -> 86.237741 | J12: =IFERROR(_xlfn.XLOOKUP(A12,'MODEL SUMMARY'!$B$3:$AL$3,'MODEL SUMMARY'!$B$71:$AL$71)+_xlfn.XLOOKUP($B$3,'Water & Sewer Data'!$C:$C,'Water & Sewer Data'!$K:$K),"") -> 2650 | K12: =IFERROR(_xlfn.XLOOKUP(A12,'MODEL SUMMARY'!$B$3:$AL$3,'MODEL SUMMARY'!$B$66:$AL$66),"") -> 10875 | L12: =IFERROR(_xlfn.XLOOKUP(A12,'MODEL SUMMARY'!$B$3:$AL$3,'MODEL SUMMARY'!$B$58:$AL$58),"") -> 134200.25 | M12: =L12/C12 -> 78.342236 | N12: =SUM(J12:L12) -> 147725.25 | O12: 4450 | P12: 9100 | Q12: TBD | R12: 28/34
A13: Holly | B13: SFH | C13: 2000 | D13: 4 | E13: 2.5 | F13: 2 | G13: 404 | H13: 2 | I13: =N13/C13 -> 78.9401 | J13: =IFERROR(_xlfn.XLOOKUP(A13,'MODEL SUMMARY'!$B$3:$AL$3,'MODEL SUMMARY'!$B$71:$AL$71)+_xlfn.XLOOKUP($B$3,'Water & Sewer Data'!$C:$C,'Water & Sewer Data'!$K:$K),"") -> 2650 | K13: =IFERROR(_xlfn.XLOOKUP(A13,'MODEL SUMMARY'!$B$3:$AL$3,'MODEL SUMMARY'!$B$66:$AL$66),"") -> 10875 | L13: =IFERROR(_xlfn.XLOOKUP(A13,'MODEL SUMMARY'!$B$3:$AL$3,'MODEL SUMMARY'!$B$58:$AL$58),"") -> 144355.2 | M13: =L13/C13 -> 72.1776 | N13: =SUM(J13:L13) -> 157880.2 | O13: 4000 | P13: 8500 | Q13: TBD | R13: 29/48
A14: Elm | B14: SFH | C14: 1712 | D14: 4 | E14: 2.5 | F14: 2 | G14: 408 | H14: 2 | I14: =N14/C14 -> 86.4866 | J14: =IFERROR(_xlfn.XLOOKUP(A14,'MODEL SUMMARY'!$B$3:$AL$3,'MODEL SUMMARY'!$B$71:$AL$71)+_xlfn.XLOOKUP($B$3,'Water & Sewer Data'!$C:$C,'Water & Sewer Data'!$K:$K),"") -> 2650 | K14: =IFERROR(_xlfn.XLOOKUP(A14,'MODEL SUMMARY'!$B$3:$AL$3,'MODEL SUMMARY'!$B$66:$AL$66),"") -> 10875 | L14: =IFERROR(_xlfn.XLOOKUP(A14,'MODEL SUMMARY'!$B$3:$AL$3,'MODEL SUMMARY'!$B$58:$AL$58),"") -> 134540.06 | M14: =L14/C14 -> 78.586484 | N14: =SUM(J14:L14) -> 148065.06 | O14: 4300 | P14: 9000 | Q14: TBD | R14: 28/35
A15: Lilac | B15: SFH | C15: 1382 | D15: 3 | E15: 3 | F15: 1 | G15: 425 | H15: 1.5 | I15: =N15/C15 -> 98.447808 | J15: =IFERROR(_xlfn.XLOOKUP(A15,'MODEL SUMMARY'!$B$3:$AL$3,'MODEL SUMMARY'!$B$71:$AL$71)+_xlfn.XLOOKUP($B$3,'Water & Sewer Data'!$C:$C,'Water & Sewer Data'!$K:$K),"") -> 2650 | K15: =IFERROR(_xlfn.XLOOKUP(A15,'MODEL SUMMARY'!$B$3:$AL$3,'MODEL SUMMARY'!$B$66:$AL$66),"") -> 10875 | L15: =IFERROR(_xlfn.XLOOKUP(A15,'MODEL SUMMARY'!$B$3:$AL$3,'MODEL SUMMARY'!$B$58:$AL$58),"") -> 122529.87 | M15: =L15/C15 -> 88.661266 | N15: =SUM(J15:L15) -> 136054.87 | O15: 4000 | P15: 9000 | Q15: TBD | R15: 30/46
A16: Lily | B16: SFH | C16: 2293 | D16: 4 | E16: 3.5 | F16: 0 | G16: 0 | H16: 2.5 | I16: =N16/C16 -> 74.779773 | J16: =IFERROR(_xlfn.XLOOKUP(A16,'MODEL SUMMARY'!$B$3:$AL$3,'MODEL SUMMARY'!$B$71:$AL$71)+_xlfn.XLOOKUP($B$3,'Water & Sewer Data'!$C:$C,'Water & Sewer Data'!$K:$K),"") -> 2650 | K16: =IFERROR(_xlfn.XLOOKUP(A16,'MODEL SUMMARY'!$B$3:$AL$3,'MODEL SUMMARY'!$B$66:$AL$66),"") -> 10875 | L16: =IFERROR(_xlfn.XLOOKUP(A16,'MODEL SUMMARY'!$B$3:$AL$3,'MODEL SUMMARY'!$B$58:$AL$58),"") -> 157945.02 | M16: =L16/C16 -> 68.881387 | N16: =SUM(J16:L16) -> 171470.02 | O16: 5400 | P16: 10700 | Q16: TBD | R16: 34/30 | T16: Widest point of plan, 26 ft at marrowest depth
A17: Magnolia | B17: SFH | C17: 2771 | D17: 4 | E17: 3 | F17: 2 | G17: 423 | H17: 2 | I17: =N17/C17 -> 69.184168 | J17: =IFERROR(_xlfn.XLOOKUP(A17,'MODEL SUMMARY'!$B$3:$AL$3,'MODEL SUMMARY'!$B$71:$AL$71)+_xlfn.XLOOKUP($B$3,'Water & Sewer Data'!$C:$C,'Water & Sewer Data'!$K:$K),"") -> 2650 | K17: =IFERROR(_xlfn.XLOOKUP(A17,'MODEL SUMMARY'!$B$3:$AL$3,'MODEL SUMMARY'!$B$66:$AL$66),"") -> 10875 | L17: =IFERROR(_xlfn.XLOOKUP(A17,'MODEL SUMMARY'!$B$3:$AL$3,'MODEL SUMMARY'!$B$58:$AL$58),"") -> 178184.33 | M17: =L17/C17 -> 64.303259 | N17: =SUM(J17:L17) -> 191709.33 | O17: 4600 | P17: 11100 | Q17: TBD | R17: 38/40
A18: Spindle | B18: SFH | C18: 2001 | D18: 3 | E18: 2 | F18: 0 | G18: 0 | H18: 2 | I18: =N18/C18 -> 80.476032 | J18: =IFERROR(_xlfn.XLOOKUP(A18,'MODEL SUMMARY'!$B$3:$AL$3,'MODEL SUMMARY'!$B$71:$AL$71)+_xlfn.XLOOKUP($B$3,'Water & Sewer Data'!$C:$C,'Water & Sewer Data'!$K:$K),"") -> 2650 | K18: =IFERROR(_xlfn.XLOOKUP(A18,'MODEL SUMMARY'!$B$3:$AL$3,'MODEL SUMMARY'!$B$66:$AL$66),"") -> 10875 | L18: =IFERROR(_xlfn.XLOOKUP(A18,'MODEL SUMMARY'!$B$3:$AL$3,'MODEL SUMMARY'!$B$58:$AL$58),"") -> 147507.54 | M18: =L18/C18 -> 73.716912 | N18: =SUM(J18:L18) -> 161032.54 | O18: 4100 | P18: 8800 | Q18: TBD | R18: 24/51
A19: Spruce | B19: SFH | C19: 1545 | D19: 3 | E19: 2 | F19: 2 | G19: 425 | H19: 1 | I19: =N19/C19 -> 92.584311 | J19: =IFERROR(_xlfn.XLOOKUP(A19,'MODEL SUMMARY'!$B$3:$AL$3,'MODEL SUMMARY'!$B$71:$AL$71)+_xlfn.XLOOKUP($B$3,'Water & Sewer Data'!$C:$C,'Water & Sewer Data'!$K:$K),"") -> 2650 | K19: =IFERROR(_xlfn.XLOOKUP(A19,'MODEL SUMMARY'!$B$3:$AL$3,'MODEL SUMMARY'!$B$66:$AL$66),"") -> 10875 | L19: =IFERROR(_xlfn.XLOOKUP(A19,'MODEL SUMMARY'!$B$3:$AL$3,'MODEL SUMMARY'!$B$58:$AL$58),"") -> 129517.76 | M19: =L19/C19 -> 83.830265 | N19: =SUM(J19:L19) -> 143042.76 | O19: 2800 | P19: 7300 | Q19: TBD | R19: 39/54
A20: Tulip | B20: SFH | C20: 1170 | D20: 3 | E20: 2 | F20: 1 | G20: 246 | H20: 1 | I20: =N20/C20 -> 102.00524 | J20: =IFERROR(_xlfn.XLOOKUP(A20,'MODEL SUMMARY'!$B$3:$AL$3,'MODEL SUMMARY'!$B$71:$AL$71)+_xlfn.XLOOKUP($B$3,'Water & Sewer Data'!$C:$C,'Water & Sewer Data'!$K:$K),"") -> 2650 | K20: =IFERROR(_xlfn.XLOOKUP(A20,'MODEL SUMMARY'!$B$3:$AL$3,'MODEL SUMMARY'!$B$66:$AL$66),"") -> 10875 | L20: =IFERROR(_xlfn.XLOOKUP(A20,'MODEL SUMMARY'!$B$3:$AL$3,'MODEL SUMMARY'!$B$58:$AL$58),"") -> 105821.13 | M20: =L20/C20 -> 90.44541 | N20: =SUM(J20:L20) -> 119346.13 | O20: 3000 | P20: 6500 | Q20: TBD | R20: 30/50
A21: White Oak | B21: SFH | C21: 2005 | D21: 4 | E21: 2.5 | F21: 2 | G21: 442 | H21: 2 | I21: =N21/C21 -> 78.492544 | J21: =IFERROR(_xlfn.XLOOKUP(A21,'MODEL SUMMARY'!$B$3:$AL$3,'MODEL SUMMARY'!$B$71:$AL$71)+_xlfn.XLOOKUP($B$3,'Water & Sewer Data'!$C:$C,'Water & Sewer Data'!$K:$K),"") -> 2650 | K21: =IFERROR(_xlfn.XLOOKUP(A21,'MODEL SUMMARY'!$B$3:$AL$3,'MODEL SUMMARY'!$B$66:$AL$66),"") -> 10875 | L21: =IFERROR(_xlfn.XLOOKUP(A21,'MODEL SUMMARY'!$B$3:$AL$3,'MODEL SUMMARY'!$B$58:$AL$58),"") -> 143852.55 | M21: =L21/C21 -> 71.746908 | N21: =SUM(J21:L21) -> 157377.55 | O21: 4400 | P21: 6700 | Q21: TBD | R21: 38/35
A22: Willow | B22: SFH | C22: 1857 | D22: 4 | E22: 2.5 | F22: 1 | G22: 250 | H22: 2 | I22: =N22/C22 -> 79.383759 | J22: =IFERROR(_xlfn.XLOOKUP(A22,'MODEL SUMMARY'!$B$3:$AL$3,'MODEL SUMMARY'!$B$71:$AL$71)+_xlfn.XLOOKUP($B$3,'Water & Sewer Data'!$C:$C,'Water & Sewer Data'!$K:$K),"") -> 2650 | K22: =IFERROR(_xlfn.XLOOKUP(A22,'MODEL SUMMARY'!$B$3:$AL$3,'MODEL SUMMARY'!$B$66:$AL$66),"") -> 10875 | L22: =IFERROR(_xlfn.XLOOKUP(A22,'MODEL SUMMARY'!$B$3:$AL$3,'MODEL SUMMARY'!$B$58:$AL$58),"") -> 133890.64 | M22: =L22/C22 -> 72.100506 | N22: =SUM(J22:L22) -> 147415.64 | O22: 4100 | P22: 9000 | Q22: TBD | R22: 30/40
A23: Jasmine | B23: TH | C23: 1500 | D23: 3 | E23: 2.5 | F23: 1 | G23: 244 | H23: 2 | I23: =N23/C23 -> 93.777893 | J23: =IFERROR(_xlfn.XLOOKUP(A23,'MODEL SUMMARY'!$B$3:$AL$3,'MODEL SUMMARY'!$B$71:$AL$71)+_xlfn.XLOOKUP($B$3,'Water & Sewer Data'!$C:$C,'Water & Sewer Data'!$K:$K),"") -> 2650 | K23: =IFERROR(_xlfn.XLOOKUP(A23,'MODEL SUMMARY'!$B$3:$AL$3,'MODEL SUMMARY'!$B$66:$AL$66),"") -> 10875 | L23: =IFERROR(_xlfn.XLOOKUP(A23,'MODEL SUMMARY'!$B$3:$AL$3,'MODEL SUMMARY'!$B$58:$AL$58),"") -> 127141.84 | M23: =L23/C23 -> 84.761227 | N23: =SUM(J23:L23) -> 140666.84 | O23: 3800 | P23: 8000 | Q23: 4500 | R23: 20/49
A24: Palmetto | B24: TH | C24: 1304 | D24: 3 | E24: 2.5 | F24: 0 | G24: 0 | H24: 2 | I24: =N24/C24 -> 94.760874 | J24: =IFERROR(_xlfn.XLOOKUP(A24,'MODEL SUMMARY'!$B$3:$AL$3,'MODEL SUMMARY'!$B$71:$AL$71)+_xlfn.XLOOKUP($B$3,'Water & Sewer Data'!$C:$C,'Water & Sewer Data'!$K:$K),"") -> 2650 | K24: =IFERROR(_xlfn.XLOOKUP(A24,'MODEL SUMMARY'!$B$3:$AL$3,'MODEL SUMMARY'!$B$66:$AL$66),"") -> 10875 | L24: =IFERROR(_xlfn.XLOOKUP(A24,'MODEL SUMMARY'!$B$3:$AL$3,'MODEL SUMMARY'!$B$58:$AL$58),"") -> 110043.18 | M24: =L24/C24 -> 84.388942 | N24: =SUM(J24:L24) -> 123568.18 | O24: 3900 | P24: 8200 | Q24: TBD | R24: 20/42
A25: Palmetto II | B25: TH | C25: 1424 | D25: 3 | E25: 2.5 | F25: 0 | G25: 32 | H25: 2 | I25: =N25/C25 -> 87.485744 | J25: =IFERROR(_xlfn.XLOOKUP(A25,'MODEL SUMMARY'!$B$3:$AL$3,'MODEL SUMMARY'!$B$71:$AL$71)+_xlfn.XLOOKUP($B$3,'Water & Sewer Data'!$C:$C,'Water & Sewer Data'!$K:$K),"") -> 2650 | K25: =IFERROR(_xlfn.XLOOKUP(A25,'MODEL SUMMARY'!$B$3:$AL$3,'MODEL SUMMARY'!$B$66:$AL$66),"") -> 10875 | L25: =IFERROR(_xlfn.XLOOKUP(A25,'MODEL SUMMARY'!$B$3:$AL$3,'MODEL SUMMARY'!$B$58:$AL$58),"") -> 111054.7 | M25: =L25/C25 -> 77.987851 | N25: =SUM(J25:L25) -> 124579.7 | O25: 4100 | P25: 7200 | Q25: 5000 | R25: 20x37
A26: Palm II | B26: TH | C26: 1689 | D26: 3 | E26: 2.5 | F26: 1F | G26: 261 | H26: 2 | I26: =N26/C26 -> 86.398615 | J26: =IFERROR(_xlfn.XLOOKUP(A26,'MODEL SUMMARY'!$B$3:$AL$3,'MODEL SUMMARY'!$B$71:$AL$71)+_xlfn.XLOOKUP($B$3,'Water & Sewer Data'!$C:$C,'Water & Sewer Data'!$K:$K),"") -> 2650 | K26: =IFERROR(_xlfn.XLOOKUP(A26,'MODEL SUMMARY'!$B$3:$AL$3,'MODEL SUMMARY'!$B$66:$AL$66),"") -> 10875 | L26: =IFERROR(_xlfn.XLOOKUP(A26,'MODEL SUMMARY'!$B$3:$AL$3,'MODEL SUMMARY'!$B$58:$AL$58),"") -> 132402.26 | M26: =L26/C26 -> 78.390918 | N26: =SUM(J26:L26) -> 145927.26 | O26: 5000 | P26: 8500 | Q26: TBD | R26: 20/50
A27: Bayberry | B27: TH | C27: 1500 | D27: 3 | E27: 2.5 | F27: 1F | G27: 259 | H27: 2 | I27: =N27/C27 -> 92.517893 | J27: =IFERROR(_xlfn.XLOOKUP(A27,'MODEL SUMMARY'!$B$3:$AL$3,'MODEL SUMMARY'!$B$71:$AL$71)+_xlfn.XLOOKUP($B$3,'Water & Sewer Data'!$C:$C,'Water & Sewer Data'!$K:$K),"") -> 2650 | K27: =IFERROR(_xlfn.XLOOKUP(A27,'MODEL SUMMARY'!$B$3:$AL$3,'MODEL SUMMARY'!$B$66:$AL$66),"") -> 10875 | L27: =IFERROR(_xlfn.XLOOKUP(A27,'MODEL SUMMARY'!$B$3:$AL$3,'MODEL SUMMARY'!$B$58:$AL$58),"") -> 125251.84 | M27: =L27/C27 -> 83.501227 | N27: =SUM(J27:L27) -> 138776.84 | O27: 3600 | P27: 5500 | Q27: 6100 | R27: 20/50 | T27: Width is per unit
A28: Cottonwood | B28: TH | C28: 1729 | D28: 3 | E28: 2.5 | F28: 1F | G28: 270 | H28: 3 | I28: =N28/C28 -> 89.995899 | J28: =IFERROR(_xlfn.XLOOKUP(A28,'MODEL SUMMARY'!$B$3:$AL$3,'MODEL SUMMARY'!$B$71:$AL$71)+_xlfn.XLOOKUP($B$3,'Water & Sewer Data'!$C:$C,'Water & Sewer Data'!$K:$K),"") -> 2650 | K28: =IFERROR(_xlfn.XLOOKUP(A28,'MODEL SUMMARY'!$B$3:$AL$3,'MODEL SUMMARY'!$B$66:$AL$66),"") -> 10875 | L28: =IFERROR(_xlfn.XLOOKUP(A28,'MODEL SUMMARY'!$B$3:$AL$3,'MODEL SUMMARY'!$B$58:$AL$58),"") -> 142077.91 | M28: =L28/C28 -> 82.173459 | N28: =SUM(J28:L28) -> 155602.91 | O28: 6500 | P28: 7100 | Q28: TBD | R28: 18/40 | T28: Width is per unit
A29: Linville | B29: TH | C29: 2188 | D29: 4 | E29: 2.5 | F29: 2F | G29: =36+404+88 -> 528 | H29: 2 | I29: =N29/C29 -> 79.587669 | J29: =IFERROR(_xlfn.XLOOKUP(A29,'MODEL SUMMARY'!$B$3:$AL$3,'MODEL SUMMARY'!$B$71:$AL$71)+_xlfn.XLOOKUP($B$3,'Water & Sewer Data'!$C:$C,'Water & Sewer Data'!$K:$K),"") -> 2650 | K29: =IFERROR(_xlfn.XLOOKUP(A29,'MODEL SUMMARY'!$B$3:$AL$3,'MODEL SUMMARY'!$B$66:$AL$66),"") -> 10875 | L29: =IFERROR(_xlfn.XLOOKUP(A29,'MODEL SUMMARY'!$B$3:$AL$3,'MODEL SUMMARY'!$B$58:$AL$58),"") -> 160612.82 | M29: =L29/C29 -> 73.406225 | N29: =SUM(J29:L29) -> 174137.82 | O29: 4700 | P29: 8900 | Q29: 7300 | R29: 27/56
A30: Locust | B30: TH | C30: 1669 | D30: 3 | E30: 2.5 | F30: 1F | G30: 258 | H30: 2 | I30: =N30/C30 -> 88.359551 | J30: =IFERROR(_xlfn.XLOOKUP(A30,'MODEL SUMMARY'!$B$3:$AL$3,'MODEL SUMMARY'!$B$71:$AL$71)+_xlfn.XLOOKUP($B$3,'Water & Sewer Data'!$C:$C,'Water & Sewer Data'!$K:$K),"") -> 2650 | K30: =IFERROR(_xlfn.XLOOKUP(A30,'MODEL SUMMARY'!$B$3:$AL$3,'MODEL SUMMARY'!$B$66:$AL$66),"") -> 10875 | L30: =IFERROR(_xlfn.XLOOKUP(A30,'MODEL SUMMARY'!$B$3:$AL$3,'MODEL SUMMARY'!$B$58:$AL$58),"") -> 133947.09 | M30: =L30/C30 -> 80.255896 | N30: =SUM(J30:L30) -> 147472.09 | O30: 4600 | P30: 7200 | Q30: TBD | R30: 22/47 | T30: Width is per unit
A31: Fig | B31: TH | C31: 1798 | D31: 3 | E31: 3.5 | F31: 1R | G31: 324 | H31: 3 | I31: =N31/C31 -> 91.045445 | J31: =IFERROR(_xlfn.XLOOKUP(A31,'MODEL SUMMARY'!$B$3:$AL$3,'MODEL SUMMARY'!$B$71:$AL$71)+_xlfn.XLOOKUP($B$3,'Water & Sewer Data'!$C:$C,'Water & Sewer Data'!$K:$K),"") -> 2650 | K31: =IFERROR(_xlfn.XLOOKUP(A31,'MODEL SUMMARY'!$B$3:$AL$3,'MODEL SUMMARY'!$B$66:$AL$66),"") -> 10875 | L31: =IFERROR(_xlfn.XLOOKUP(A31,'MODEL SUMMARY'!$B$3:$AL$3,'MODEL SUMMARY'!$B$58:$AL$58),"") -> 150174.71 | M31: =L31/C31 -> 83.523198 | N31: =SUM(J31:L31) -> 163699.71 | O31: 3900 | P31: 8200 | Q31: 9000 | R31: 18/40 | T31: Width is per unit
A32: Poplar | B32: TH | C32: 1483 | D32: 3 | E32: 2.5 | F32: 2R | G32: 439 | H32: 2 | I32: =N32/C32 -> 97.328935 | J32: =IFERROR(_xlfn.XLOOKUP(A32,'MODEL SUMMARY'!$B$3:$AL$3,'MODEL SUMMARY'!$B$71:$AL$71)+_xlfn.XLOOKUP($B$3,'Water & Sewer Data'!$C:$C,'Water & Sewer Data'!$K:$K),"") -> 2650 | K32: =IFERROR(_xlfn.XLOOKUP(A32,'MODEL SUMMARY'!$B$3:$AL$3,'MODEL SUMMARY'!$B$66:$AL$66),"") -> 10875 | L32: =IFERROR(_xlfn.XLOOKUP(A32,'MODEL SUMMARY'!$B$3:$AL$3,'MODEL SUMMARY'!$B$58:$AL$58),"") -> 130813.81 | M32: =L32/C32 -> 88.208908 | N32: =SUM(J32:L32) -> 144338.81 | O32: 3900 | P32: 8200 | Q32: 3600 | R32: 20/50
A33: Fraser | B33: TH | C33: 1689 | D33: 3 | E33: 2.5 | F33: 2R | G33: 445 | H33: 2R | I33: =N33/C33 -> 87.085968 | J33: =IFERROR(_xlfn.XLOOKUP(A33,'MODEL SUMMARY'!$B$3:$AL$3,'MODEL SUMMARY'!$B$71:$AL$71)+_xlfn.XLOOKUP($B$3,'Water & Sewer Data'!$C:$C,'Water & Sewer Data'!$K:$K),"") -> 2650 | K33: =IFERROR(_xlfn.XLOOKUP(A33,'MODEL SUMMARY'!$B$3:$AL$3,'MODEL SUMMARY'!$B$66:$AL$66),"") -> 10875 | L33: =IFERROR(_xlfn.XLOOKUP(A33,'MODEL SUMMARY'!$B$3:$AL$3,'MODEL SUMMARY'!$B$58:$AL$58),"") -> 133563.2 | M33: =L33/C33 -> 79.078271 | N33: =SUM(J33:L33) -> 147088.2 | O33: 3300 | P33: 2700 | Q33: TBD | R33: 22/50
A34: Sycamore | B34: TH | C34: 1993 | D34: 3 | E34: 2.5 | F34: 2R | G34: 480 | H34: 2 | I34: =N34/C34 -> 80.474691 | J34: =IFERROR(_xlfn.XLOOKUP(A34,'MODEL SUMMARY'!$B$3:$AL$3,'MODEL SUMMARY'!$B$71:$AL$71)+_xlfn.XLOOKUP($B$3,'Water & Sewer Data'!$C:$C,'Water & Sewer Data'!$K:$K),"") -> 2650 | K34: =IFERROR(_xlfn.XLOOKUP(A34,'MODEL SUMMARY'!$B$3:$AL$3,'MODEL SUMMARY'!$B$66:$AL$66),"") -> 10875 | L34: =IFERROR(_xlfn.XLOOKUP(A34,'MODEL SUMMARY'!$B$3:$AL$3,'MODEL SUMMARY'!$B$58:$AL$58),"") -> 146861.06 | M34: =L34/C34 -> 73.68844 | N34: =SUM(J34:L34) -> 160386.06 | O34: 5500 | P34: 8600 | Q34: 4400
A35: Alder | B35: TH | C35: 1700 | D35: 3 | E35: 2.5 | F35: 1R | G35: 241 | H35: 2 | I35: =N35/C35 -> 84.541547 | J35: =IFERROR(_xlfn.XLOOKUP(A35,'MODEL SUMMARY'!$B$3:$AL$3,'MODEL SUMMARY'!$B$71:$AL$71)+_xlfn.XLOOKUP($B$3,'Water & Sewer Data'!$C:$C,'Water & Sewer Data'!$K:$K),"") -> 2650 | K35: =IFERROR(_xlfn.XLOOKUP(A35,'MODEL SUMMARY'!$B$3:$AL$3,'MODEL SUMMARY'!$B$66:$AL$66),"") -> 10875 | L35: =IFERROR(_xlfn.XLOOKUP(A35,'MODEL SUMMARY'!$B$3:$AL$3,'MODEL SUMMARY'!$B$58:$AL$58),"") -> 130195.63 | M35: =L35/C35 -> 76.585665 | N35: =SUM(J35:L35) -> 143720.63 | O35: 4600 | P35: 8800 | Q35: 5900 | R35: 20/49 | T35: Per Ryan, Alder is identical to Palm but with a flipped garages
A36: Boxelder | B36: TH | C36: 1796 | D36: 4 | E36: 2.5 | F36: 2 | G36: 354 | H36: 1R | I36: =N36/C36 -> 86.3126 | J36: =IFERROR(_xlfn.XLOOKUP(A36,'MODEL SUMMARY'!$B$3:$AL$3,'MODEL SUMMARY'!$B$71:$AL$71)+_xlfn.XLOOKUP($B$3,'Water & Sewer Data'!$C:$C,'Water & Sewer Data'!$K:$K),"") -> 2650 | K36: =IFERROR(_xlfn.XLOOKUP(A36,'MODEL SUMMARY'!$B$3:$AL$3,'MODEL SUMMARY'!$B$66:$AL$66),"") -> 10875 | L36: =IFERROR(_xlfn.XLOOKUP(A36,'MODEL SUMMARY'!$B$3:$AL$3,'MODEL SUMMARY'!$B$58:$AL$58),"") -> 141492.43 | M36: =L36/C36 -> 78.781977 | N36: =SUM(J36:L36) -> 155017.43 | O36: 6300 | P36: 9200 | Q36: 4800 | R36: 22/54
A37: Bur Oak | B37: TH | C37: 1548 | D37: 3 | E37: 2.5 | F37: 1 | I37: =N37/C37 -> 89.412791 | J37: =IFERROR(_xlfn.XLOOKUP(A37,'MODEL SUMMARY'!$B$3:$AL$3,'MODEL SUMMARY'!$B$71:$AL$71)+_xlfn.XLOOKUP($B$3,'Water & Sewer Data'!$C:$C,'Water & Sewer Data'!$K:$K),"") -> 2650 | K37: =IFERROR(_xlfn.XLOOKUP(A37,'MODEL SUMMARY'!$B$3:$AL$3,'MODEL SUMMARY'!$B$66:$AL$66),"") -> 10875 | L37: =IFERROR(_xlfn.XLOOKUP(A37,'MODEL SUMMARY'!$B$3:$AL$3,'MODEL SUMMARY'!$B$58:$AL$58),"") -> 124886 | M37: =L37/C37 -> 80.675711 | N37: =SUM(J37:L37) -> 138411 | O37: 5700 | P37: 8500 | Q37: 5200
A38: Conifer | B38: TH | C38: 1892 | F38: 2 | I38: =N38/C38 -> 93.315793 | J38: =IFERROR(_xlfn.XLOOKUP(A38,'MODEL SUMMARY'!$B$3:$AL$3,'MODEL SUMMARY'!$B$71:$AL$71)+_xlfn.XLOOKUP($B$3,'Water & Sewer Data'!$C:$C,'Water & Sewer Data'!$K:$K),"") -> 2650 | K38: =IFERROR(_xlfn.XLOOKUP(A38,'MODEL SUMMARY'!$B$3:$AL$3,'MODEL SUMMARY'!$B$66:$AL$66),"") -> 10875 | L38: =IFERROR(_xlfn.XLOOKUP(A38,'MODEL SUMMARY'!$B$3:$AL$3,'MODEL SUMMARY'!$B$58:$AL$58),"") -> 163028.48 | M38: =L38/C38 -> 86.167273 | N38: =SUM(J38:L38) -> 176553.48 | O38: 4700 | P38: 5900 | Q38: 7700
A39: Pinyon | B39: TH | C39: 1748 | D39: 3 | E39: 3.5 | F39: 2 | I39: =N39/C39 -> 94.490446 | J39: =IFERROR(_xlfn.XLOOKUP(A39,'MODEL SUMMARY'!$B$3:$AL$3,'MODEL SUMMARY'!$B$71:$AL$71)+_xlfn.XLOOKUP($B$3,'Water & Sewer Data'!$C:$C,'Water & Sewer Data'!$K:$K),"") -> 2650 | K39: =IFERROR(_xlfn.XLOOKUP(A39,'MODEL SUMMARY'!$B$3:$AL$3,'MODEL SUMMARY'!$B$66:$AL$66),"") -> 10875 | L39: =IFERROR(_xlfn.XLOOKUP(A39,'MODEL SUMMARY'!$B$3:$AL$3,'MODEL SUMMARY'!$B$58:$AL$58),"") -> 151644.3 | M39: =L39/C39 -> 86.753032 | N39: =SUM(J39:L39) -> 165169.3 | O39: 6600 | P39: 11200 | Q39: 6200
A40: Aspen 3-Story | B40: SFH | C40: 2168 | D40: 3 | E40: 2.5 | F40: 2 | G40: 400 | H40: 2 | I40: =N40/C40 -> 80.229027 | J40: =IFERROR(_xlfn.XLOOKUP(A40,'MODEL SUMMARY'!$B$3:$AL$3,'MODEL SUMMARY'!$B$71:$AL$71)+_xlfn.XLOOKUP($B$3,'Water & Sewer Data'!$C:$C,'Water & Sewer Data'!$K:$K),"") -> 2650 | K40: =IFERROR(_xlfn.XLOOKUP(A40,'MODEL SUMMARY'!$B$3:$AL$3,'MODEL SUMMARY'!$B$66:$AL$66),"") -> 10875 | L40: =IFERROR(_xlfn.XLOOKUP(A40,'MODEL SUMMARY'!$B$3:$AL$3,'MODEL SUMMARY'!$B$58:$AL$58),"") -> 160411.53 | M40: =L40/C40 -> 73.990558 | N40: =SUM(J40:L40) -> 173936.53 | O40: 5050 | P40: 10100 | Q40: TBD | R40: 24/33
A41: Arborbrook | B41: SFH | C41: 2219 | D41: 3 | E41: 3 | F41: 2 | G41: 496 | H41: 1.5 | I41: =N41/C41 -> 84.730509 | J41: 2650 | K41: 10875 | L41: 174492 | M41: =L41/C41 -> 78.635421 | N41: =SUM(J41:L41) -> 188017 | R41: 44/52 | T41: Widest point of plan, 47 ft at narrowest depth
A42: Ash | B42: SFH | C42: 1188 | D42: 3 | E42: 2 | F42: 2 | G42: 406 | H42: 1 | I42: =N42/C42 -> 145.25421 | J42: 19289 | K42: 12513 | L42: 140760 | M42: =L42/C42 -> 118.48485 | N42: =SUM(J42:L42) -> 172562 | R42: 30/62
...

Sheet Trends
A1: Red Cedar Model Historical Trends
R2: Historical Data | X2: 45922 | Y2: 45883 | Z2: 45835 | AA2: 45813 | AB2: 45775 | AC2: 03.31.2025 | AD2: 02.27.2025 | AE2: 1.28.2025 | AF2: 1.10.2025 | AG2: 11.25.2024 | AH2: 10.29.2024 | AI2: 09.23.2024 | AJ2: 8.27.2024 | AK2: 7.22.2024 | AL2: 3.15.2024
A3: Current Month Variance to Historical Data | X3: September | Y3: August | Z3: June | AA3: May | AB3: April | AC3: March | AD3: February | AE3: January | AF3: December | AG3: November | AH3: October | AI3: September | AJ3: August | AK3: July | AL3: March
A4: Model | B4: September | C4: August | D4: June | E4: May | F4: April | G4: March | H4: February | I4: January | J4: December | K4: November | L4: October | M4: September | N4: August | O4: July | R4: Model | S4: SFR/TH | T4: SF | U4: Bed | V4: Bath | W4: Garage | X4: Sticks & Bricks | Y4: Sticks & Bricks | Z4: Sticks & Bricks | AA4: Sticks & Bricks | AB4: Sticks & Bricks | AC4: Sticks & Bricks | AD4: Sticks & Bricks | AE4: Sticks & Bricks | AF4: Sticks & Bricks | AG4: Sticks & Bricks | AH4: Sticks & Bricks | AI4: Sticks & Bricks | AJ4: Sticks & Bricks | AK4: Sticks & Bricks | AL4: Sticks & Bricks
A5: Acacia | B5: =IFERROR(X5/Y5-1,0) -> -0.0011998641 | C5: =IFERROR(Y5/Z5-1,0) -> -0.021133305 | D5: =IFERROR(Z5/AA5-1,0) -> 0.0051333042 | E5: =IFERROR(AA5/AB5-1,0) -> -0.018192947 | F5: =IFERROR(AB5/AC5-1,0) -> 0 | G5: =IFERROR(AC5/AD5-1,0) -> 0 | H5: =IFERROR(AD5/AE5-1,0) -> 0 | I5: =IFERROR(AE5/AF5-1,0) -> 0 | ... O5: =IFERROR(AK5/AL5-1,0) -> 0 | R5: Acacia | S5: =_xlfn.XLOOKUP(R5,Summary!A:A,Summary!B:B) -> SFH | T5: =_xlfn.XLOOKUP(R5,Summary!A:A,Summary!C:C) -> 2236 | U5: =_xlfn.XLOOKUP(R5,Summary!A:A,Summary!D:D) -> 4 | V5: =_xlfn.XLOOKUP(R5,Summary!A:A,Summary!E:E) -> 3 | W5: =_xlfn.XLOOKUP(R5,Summary!A:A,Summary!F:F) -> 2 | X5: =_xlfn.XLOOKUP(R5,Summary!A:A,Summary!L:L) -> 165012.15 | Y5: 165210.38 | Z5: 168777.2 | AA5: 167915.24 | AB5: 171026.72
A6: Aspen 2-Story | B6: =IFERROR(X6/Y6-1,0) -> -0.0015095011 | C6: =IFERROR(Y6/Z6-1,0) -> -0.023034239 | D6: =IFERROR(Z6/AA6-1,0) -> -0.03084456 | E6: =IFERROR(AA6/AB6-1,0) -> -0.0085214802 | F6: =IFERROR(AB6/AC6-1,0) -> 0.0057164824 | G6: =IFERROR(AC6/AD6-1,0) -> -0.014673166 | H6: =IFERROR(AD6/AE6-1,0) -> 0.019293909 | I6: =IFERROR(AE6/AF6-1,0) -> 0.007703446 | ... O6: =IFERROR(AK6/AL6-1,0) -> 0 | R6: Aspen 2-Story | S6: =_xlfn.XLOOKUP(R6,Summary!A:A,Summary!B:B) -> SFH | T6: =_xlfn.XLOOKUP(R6,Summary!A:A,Summary!C:C) -> 1788 | U6: =_xlfn.XLOOKUP(R6,Summary!A:A,Summary!D:D) -> 3 | V6: =_xlfn.XLOOKUP(R6,Summary!A:A,Summary!E:E) -> 2.5 | W6: =_xlfn.XLOOKUP(R6,Summary!A:A,Summary!F:F) -> 2 | X6: =_xlfn.XLOOKUP(R6,Summary!A:A,Summary!L:L) -> 139411.53 | Y6: 139622.29 | Z6: 142914.21 | AA6: 147462.63 | AB6: 148730.03 | AC6: 147884.65 | AD6: 150086.9 | AE6: 147245.95 | AF6: 146120.32 | AG6: 144275.17 | AH6: 141527.42 | AI6: 141527.42
A7: Atlas | B7: =IFERROR(X7/Y7-1,0) -> -0.00097578443 | C7: =IFERROR(Y7/Z7-1,0) -> -0.045152821 | D7: =IFERROR(Z7/AA7-1,0) -> -0.0015298502 | E7: =IFERROR(AA7/AB7-1,0) -> -0.0157654 | F7: =IFERROR(AB7/AC7-1,0) -> 0.0031560223 | G7: =IFERROR(AC7/AD7-1,0) -> 0.013243598 | H7: =IFERROR(AD7/AE7-1,0) -> 0.024901195 | I7: =IFERROR(AE7/AF7-1,0) -> 0.0059212852 | ... O7: =IFERROR(AK7/AL7-1,0) -> -0.025486934 | R7: Atlas | S7: =_xlfn.XLOOKUP(R7,Summary!A:A,Summary!B:B) -> SFH | T7: =_xlfn.XLOOKUP(R7,Summary!A:A,Summary!C:C) -> 1554 | U7: =_xlfn.XLOOKUP(R7,Summary!A:A,Summary!D:D) -> 3 | V7: =_xlfn.XLOOKUP(R7,Summary!A:A,Summary!E:E) -> 2.5 | W7: =_xlfn.XLOOKUP(R7,Summary!A:A,Summary!F:F) -> 0 | X7: =_xlfn.XLOOKUP(R7,Summary!A:A,Summary!L:L) -> 113776.73 | Y7: 113887.86 | Z7: 119273.39 | AA7: 119456.14 | AB7: 121369.58 | AC7: 120987.74 | AD7: 119406.37 | AE7: 116505.25 | AF7: 115819.45 | AG7: 117393 | AH7: 117268.41 | AI7: 120252.8 | AJ7: 120257.64 | AK7: 125936.46 | AL7: 129230.14
A8: Banyan | B8: =IFERROR(X8/Y8-1,0) -> -0.002807751 | C8: =IFERROR(Y8/Z8-1,0) -> -0.034428875 | D8: =IFERROR(Z8/AA8-1,0) -> 0.011011894 | E8: =IFERROR(AA8/AB8-1,0) -> -0.0077560483 | F8: =IFERROR(AB8/AC8-1,0) -> 0.0015862173 | G8: =IFERROR(AC8/AD8-1,0) -> 0.0047270556 | H8: =IFERROR(AD8/AE8-1,0) -> 0.019112735 | I8: =IFERROR(AE8/AF8-1,0) -> 0.051308309 | ... O8: =IFERROR(AK8/AL8-1,0) -> 0 | R8: Banyan | S8: =_xlfn.XLOOKUP(R8,Summary!A:A,Summary!B:B) -> SFH | T8: =_xlfn.XLOOKUP(R8,Summary!A:A,Summary!C:C) -> 1400 | U8: =_xlfn.XLOOKUP(R8,Summary!A:A,Summary!D:D) -> 3 | V8: =_xlfn.XLOOKUP(R8,Summary!A:A,Summary!E:E) -> 3 | W8: =_xlfn.XLOOKUP(R8,Summary!A:A,Summary!F:F) -> 2 | X8: =_xlfn.XLOOKUP(R8,Summary!A:A,Summary!L:L) -> 134057.54 | Y8: 134435 | Z8: 139228.48 | AA8: 137712.01 | AB8: 138788.46 | AC8: 138568.66 | AD8: 137916.72 | AE8: 135330.19 | AF8: 128725.5 | AG8: 127617.64 | AH8: 125378.71 | AI8: 125378.71
A9: Cherry | B9: =IFERROR(X9/Y9-1,0) -> -0.0055609798 | C9: =IFERROR(Y9/Z9-1,0) -> -0.0061237909 | D9: =IFERROR(Z9/AA9-1,0) -> 0.016814876 | E9: =IFERROR(AA9/AB9-1,0) -> -0.0029255636 | F9: =IFERROR(AB9/AC9-1,0) -> 0.0059418451 | G9: =IFERROR(AC9/AD9-1,0) -> 0.0053798986 | H9: =IFERROR(AD9/AE9-1,0) -> 0.01680861 | I9: =IFERROR(AE9/AF9-1,0) -> 0.016767479 | ... O9: =IFERROR(AK9/AL9-1,0) -> -0.056532855 | R9: Cherry | S9: =_xlfn.XLOOKUP(R9,Summary!A:A,Summary!B:B) -> SFH | T9: =_xlfn.XLOOKUP(R9,Summary!A:A,Summary!C:C) -> 2214 | U9: =_xlfn.XLOOKUP(R9,Summary!A:A,Summary!D:D) -> 4 | V9: =_xlfn.XLOOKUP(R9,Summary!A:A,Summary!E:E) -> 3 | W9: =_xlfn.XLOOKUP(R9,Summary!A:A,Summary!F:F) -> 2 | X9: =_xlfn.XLOOKUP(R9,Summary!A:A,Summary!L:L) -> 156913.07 | Y9: 157790.54 | Z9: 158762.77 | AA9: 156137.34 | AB9: 156595.47 | AC9: 155670.5 | AD9: 154837.49 | AE9: 152277.91 | AF9: 149766.7 | AG9: 151699.79 | AH9: 151515.73 | AI9: 155786.41 | AJ9: 155778.74 | AK9: 156950.76 | AL9: 166355.3
A10: Dogwood | B10: =IFERROR(X10/Y10-1,0) -> -0.0015276836 | C10: =IFERROR(Y10/Z10-1,0) -> -0.032542498 | D10: =IFERROR(Z10/AA10-1,0) -> 0.010693027 | E10: =IFERROR(AA10/AB10-1,0) -> -0.0030007903 | F10: =IFERROR(AB10/AC10-1,0) -> -0.0031234757 | G10: =IFERROR(AC10/AD10-1,0) -> 0.0054473447 | H10: =IFERROR(AD10/AE10-1,0) -> 0.016772164 | I10: =IFERROR(AE10/AF10-1,0) -> 0.035977873 | ... O10: =IFERROR(AK10/AL10-1,0) -> -0.066664213 | R10: Dogwood | S10: =_xlfn.XLOOKUP(R10,Summary!A:A,Summary!B:B) -> SFH | T10: =_xlfn.XLOOKUP(R10,Summary!A:A,Summary!C:C) -> 1541 | U10: =_xlfn.XLOOKUP(R10,Summary!A:A,Summary!D:D) -> 3 | V10: =_xlfn.XLOOKUP(R10,Summary!A:A,Summary!E:E) -> 2.5 | W10: =_xlfn.XLOOKUP(R10,Summary!A:A,Summary!F:F) -> 2 | X10: =_xlfn.XLOOKUP(R10,Summary!A:A,Summary!L:L) -> 124030.98 | Y10: 124220.75 | Z10: 128399.18 | AA10: 127040.73 | AB10: 127423.1 | AC10: 127822.35 | AD10: 127129.83 | AE10: 125032.76 | AF10: 120690.57 | AG10: 122061.15 | AH10: 122601.99 | AI10: 125295.09 | AJ10: 124464.88 | AK10: 125788.24 | AL10: 134772.76
A11: Hazel | B11: =IFERROR(X11/Y11-1,0) -> -0.0015925388 | C11: =IFERROR(Y11/Z11-1,0) -> -0.035070173 | D11: =IFERROR(Z11/AA11-1,0) -> 0.00893274 | E11: =IFERROR(AA11/AB11-1,0) -> 0.00017277299 | F11: =IFERROR(AB11/AC11-1,0) -> 0.0061235881 | G11: =IFERROR(AC11/AD11-1,0) -> 0.0085069702 | H11: =IFERROR(AD11/AE11-1,0) -> 0 | I11: =IFERROR(AE11/AF11-1,0) -> 0 | ... O11: =IFERROR(AK11/AL11-1,0) -> 0 | R11: Hazel | S11: =_xlfn.XLOOKUP(R11,Summary!A:A,Summary!B:B) -> SFH | T11: =_xlfn.XLOOKUP(R11,Summary!A:A,Summary!C:C) -> 1713 | U11: =_xlfn.XLOOKUP(R11,Summary!A:A,Summary!D:D) -> 4 | V11: =_xlfn.XLOOKUP(R11,Summary!A:A,Summary!E:E) -> 2.5 | W11: =_xlfn.XLOOKUP(R11,Summary!A:A,Summary!F:F) -> 2 | X11: =_xlfn.XLOOKUP(R11,Summary!A:A,Summary!L:L) -> 134200.25 | Y11: 134414.31 | Z11: 139299.57 | AA11: 138066.26 | AB11: 138042.41 | AC11: 137202.24 | AD11: 136044.91
A12: Holly | B12: =IFERROR(X12/Y12-1,0) -> -0.00097725611 | C12: =IFERROR(Y12/Z12-1,0) -> -0.017998863 | D12: =IFERROR(Z12/AA12-1,0) -> 0.0086222225 | E12: =IFERROR(AA12/AB12-1,0) -> -0.0067742138 | F12: =IFERROR(AB12/AC12-1,0) -> 0.0070257054 | G12: =IFERROR(AC12/AD12-1,0) -> 0.0062582916 | H12: =IFERROR(AD12/AE12-1,0) -> 0.020306011 | I12: =IFERROR(AE12/AF12-1,0) -> 0.015760936 | ... O12: =IFERROR(AK12/AL12-1,0) -> -0.057570298 | R12: Holly | S12: =_xlfn.XLOOKUP(R12,Summary!A:A,Summary!B:B) -> SFH | T12: =_xlfn.XLOOKUP(R12,Summary!A:A,Summary!C:C) -> 2000 | U12: =_xlfn.XLOOKUP(R12,Summary!A:A,Summary!D:D) -> 4 | V12: =_xlfn.XLOOKUP(R12,Summary!A:A,Summary!E:E) -> 2.5 | W12: =_xlfn.XLOOKUP(R12,Summary!A:A,Summary!F:F) -> 2 | X12: =_xlfn.XLOOKUP(R12,Summary!A:A,Summary!L:L) -> 144355.2 | Y12: 144496.41 | Z12: 147144.85 | AA12: 145886.98 | AB12: 146881.99 | AC12: 145857.24 | AD12: 144950.1 | AE12: 142065.32 | AF12: 139860.98 | AG12: 138711.9 | AH12: 137885.26 | AI12: 144934.63 | AJ12: 144903.38 | AK12: 147649.01 | AL12: 156668.46
A13: Elm | B13: =IFERROR(X13/Y13-1,0) -> -0.0013137906 | C13: =IFERROR(Y13/Z13-1,0) -> -0.0272222 | D13: =IFERROR(Z13/AA13-1,0) -> -0.012635111 | E13: =IFERROR(AA13/AB13-1,0) -> -0.0039013977 | F13: =IFERROR(AB13/AC13-1,0) -> 0.005491451 | G13: =IFERROR(AC13/AD13-1,0) -> -0.0010262274 | H13: =IFERROR(AD13/AE13-1,0) -> 0.024633447 | I13: =IFERROR(AE13/AF13-1,0) -> 0.027571259 | ... O13: =IFERROR(AK13/AL13-1,0) -> -0.052439154 | R13: Elm | S13: =_xlfn.XLOOKUP(R13,Summary!A:A,Summary!B:B) -> SFH | T13: =_xlfn.XLOOKUP(R13,Summary!A:A,Summary!C:C) -> 1712 | U13: =_xlfn.XLOOKUP(R13,Summary!A:A,Summary!D:D) -> 4 | V13: =_xlfn.XLOOKUP(R13,Summary!A:A,Summary!E:E) -> 2.5 | W13: =_xlfn.XLOOKUP(R13,Summary!A:A,Summary!F:F) -> 2 | X13: =_xlfn.XLOOKUP(R13,Summary!A:A,Summary!L:L) -> 134540.06 | Y13: 134717.05 | Z13: 138486.97 | AA13: 140259.16 | AB13: 140808.51 | AC13: 140039.49 | AD13: 140183.35 | AE13: 136813.17 | AF13: 133142.27 | AG13: 133555.91 | AH13: 136379.31 | AI13: 141504.52 | AJ13: 140535.5 | AK13: 141574.09 | AL13: 149408.97
A14: Lilac | B14: =IFERROR(X14/Y14-1,0) -> -0.0021993494 | C14: =IFERROR(Y14/Z14-1,0) -> -0.022188215 | D14: =IFERROR(Z14/AA14-1,0) -> -0.00024479124 | E14: =IFERROR(AA14/AB14-1,0) -> -0.0041715995 | F14: =IFERROR(AB14/AC14-1,0) -> 0.0019366219 | G14: =IFERROR(AC14/AD14-1,0) -> 0.015159626 | H14: =IFERROR(AD14/AE14-1,0) -> 0.032021491 | I14: =IFERROR(AE14/AF14-1,0) -> 0.010948172 | ... O14: =IFERROR(AK14/AL14-1,0) -> -0.023383773 | R14: Lilac | S14: =_xlfn.XLOOKUP(R14,Summary!A:A,Summary!B:B) -> SFH | T14: =_xlfn.XLOOKUP(R14,Summary!A:A,Summary!C:C) -> 1382 | U14: =_xlfn.XLOOKUP(R14,Summary!A:A,Summary!D:D) -> 3 | V14: =_xlfn.XLOOKUP(R14,Summary!A:A,Summary!E:E) -> 3 | W14: =_xlfn.XLOOKUP(R14,Summary!A:A,Summary!F:F) -> 1 | X14: =_xlfn.XLOOKUP(R14,Summary!A:A,Summary!L:L) -> 122529.87 | Y14: 122799.95 | Z14: 125586.49 | AA14: 125617.24 | AB14: 126143.46 | AC14: 125899.64 | AD14: 124019.55 | AE14: 120171.48 | AF14: 118870.07 | AG14: 120229.66 | AH14: 120885.54 | AI14: 123700.75 | AJ14: 123663.79 | AK14: 126480.21 | AL14: 129508.61
A15: Lily | B15: =IFERROR(X15/Y15-1,0) -> 0.0048645375 | C15: =IFERROR(Y15/Z15-1,0) -> -0.020035539 | D15: =IFERROR(Z15/AA15-1,0) -> -0.054948496 | E15: =IFERROR(AA15/AB15-1,0) -> -0.017850463 | F15: =IFERROR(AB15/AC15-1,0) -> 0.0035479844 | G15: =IFERROR(AC15/AD15-1,0) -> 0.0074092995 | H15: =IFERROR(AD15/AE15-1,0) -> -0.0088741284 | I15: =IFERROR(AE15/AF15-1,0) -> 0.058523199 | ... O15: =IFERROR(AK15/AL15-1,0) -> 0 | R15: Lily | S15: =_xlfn.XLOOKUP(R15,Summary!A:A,Summary!B:B) -> SFH | T15: =_xlfn.XLOOKUP(R15,Summary!A:A,Summary!C:C) -> 2293 | U15: =_xlfn.XLOOKUP(R15,Summary!A:A,Summary!D:D) -> 4 | V15: =_xlfn.XLOOKUP(R15,Summary!A:A,Summary!E:E) -> 3.5 | W15: =_xlfn.XLOOKUP(R15,Summary!A:A,Summary!F:F) -> 0 | X15: =_xlfn.XLOOKUP(R15,Summary!A:A,Summary!L:L) -> 157945.02 | Y15: 157180.41 | Z15: 160393.99 | AA15: 169719.84 | AB15: 172804.48 | AC15: 172193.54 | AD15: 170927.09 | AE15: 172457.5 | AF15: 162922.74 | AG15: 164965.33 | AH15: 164315.42 | AI15: 169487.86 | AJ15: 169172.9
A16: Magnolia | B16: =IFERROR(X16/Y16-1,0) -> -0.0012045456 | C16: =IFERROR(Y16/Z16-1,0) -> -0.016115807 | D16: =IFERROR(Z16/AA16-1,0) -> 0.0028516236 | E16: =IFERROR(AA16/AB16-1,0) -> 0.012138388 | F16: =IFERROR(AB16/AC16-1,0) -> -0.01384975 | G16: =IFERROR(AC16/AD16-1,0) -> 0.024055893 | H16: =IFERROR(AD16/AE16-1,0) -> 0.014545681 | I16: =IFERROR(AE16/AF16-1,0) -> 0.0074613045 | ... O16: =IFERROR(AK16/AL16-1,0) -> -0.066980979 | R16: Magnolia | S16: =_xlfn.XLOOKUP(R16,Summary!A:A,Summary!B:B) -> SFH | T16: =_xlfn.XLOOKUP(R16,Summary!A:A,Summary!C:C) -> 2771 | U16: =_xlfn.XLOOKUP(R16,Summary!A:A,Summary!D:D) -> 4 | V16: =_xlfn.XLOOKUP(R16,Summary!A:A,Summary!E:E) -> 3 | W16: =_xlfn.XLOOKUP(R16,Summary!A:A,Summary!F:F) -> 2 | X16: =_xlfn.XLOOKUP(R16,Summary!A:A,Summary!L:L) -> 178184.33 | Y16: 178399.22 | Z16: 181321.36 | AA16: 180805.77 | AB16: 178637.4 | AC16: 181146.23 | AD16: 176890.96 | AE16: 174354.85 | AF16: 173063.57 | AG16: 175115.46 | AH16: 173953.79 | AI16: 178920.09 | AJ16: 178913.31 | AK16: 179862.07 | AL16: 192774.28
A17: Spindle | B17: =IFERROR(X17/Y17-1,0) -> -0.0015564094 | C17: =IFERROR(Y17/Z17-1,0) -> -0.040861341 | D17: =IFERROR(Z17/AA17-1,0) -> 0.021973591 | E17: =IFERROR(AA17/AB17-1,0) -> -0.0071631752 | F17: =IFERROR(AB17/AC17-1,0) -> 0.00062618654 | G17: =IFERROR(AC17/AD17-1,0) -> 0.0071316149 | H17: =IFERROR(AD17/AE17-1,0) -> 0.012006067 | I17: =IFERROR(AE17/AF17-1,0) -> 0.019940461 | ... O17: =IFERROR(AK17/AL17-1,0) -> 0 | R17: Spindle | S17: =_xlfn.XLOOKUP(R17,Summary!A:A,Summary!B:B) -> SFH | T17: =_xlfn.XLOOKUP(R17,Summary!A:A,Summary!C:C) -> 2001 | U17: =_xlfn.XLOOKUP(R17,Summary!A:A,Summary!D:D) -> 3 | V17: =_xlfn.XLOOKUP(R17,Summary!A:A,Summary!E:E) -> 2 | W17: =_xlfn.XLOOKUP(R17,Summary!A:A,Summary!F:F) -> 0 | X17: =_xlfn.XLOOKUP(R17,Summary!A:A,Summary!L:L) -> 147507.54 | Y17: 147737.48 | Z17: 154031.41 | AA17: 150719.56 | AB17: 151806.98 | AC17: 151711.98 | AD17: 150637.69 | AE17: 148850.58 | AF17: 145940.46 | AG17: 147648.2 | AH17: 145479.36 | AI17: 149428.13 | AJ17: 149645.2
A18: Spruce | B18: =IFERROR(X18/Y18-1,0) -> -0.010555581 | C18: =IFERROR(Y18/Z18-1,0) -> 0.058148182 | D18: =IFERROR(Z18/AA18-1,0) -> -0.063721217 | E18: =IFERROR(AA18/AB18-1,0) -> -0.006503931 | F18: =IFERROR(AB18/AC18-1,0) -> 0.0030174162 | G18: =IFERROR(AC18/AD18-1,0) -> 0.011308958 | H18: =IFERROR(AD18/AE18-1,0) -> 0.021206373 | I18: =IFERROR(AE18/AF18-1,0) -> -0.007317559 | ... O18: =IFERROR(AK18/AL18-1,0) -> -0.027419458 | R18: Spruce | S18: =_xlfn.XLOOKUP(R18,Summary!A:A,Summary!B:B) -> SFH | T18: =_xlfn.XLOOKUP(R18,Summary!A:A,Summary!C:C) -> 1545 | U18: =_xlfn.XLOOKUP(R18,Summary!A:A,Summary!D:D) -> 3 | V18: =_xlfn.XLOOKUP(R18,Summary!A:A,Summary!E:E) -> 2 | W18: =_xlfn.XLOOKUP(R18,Summary!A:A,Summary!F:F) -> 2 | X18: =_xlfn.XLOOKUP(R18,Summary!A:A,Summary!L:L) -> 129517.76 | Y18: 130899.48 | Z18: 123706.19 | AA18: 132125.38 | AB18: 132990.34 | AC18: 132590.26 | AD18: 131107.57 | AE18: 128384.99 | AF18: 129331.38 | AG18: 130566.06 | AH18: 128971.36 | AI18: 132483.38 | AJ18: 132414.33 | AK18: 133718.99 | AL18: 137488.86
A19: Tulip | B19: =IFERROR(X19/Y19-1,0) -> -0.001589213 | C19: =IFERROR(Y19/Z19-1,0) -> -0.016204429 | D19: =IFERROR(Z19/AA19-1,0) -> -0.00071856012 | E19: =IFERROR(AA19/AB19-1,0) -> -0.0065245509 | F19: =IFERROR(AB19/AC19-1,0) -> -0.0020232499 | G19: =IFERROR(AC19/AD19-1,0) -> 0.010893182 | H19: =IFERROR(AD19/AE19-1,0) -> 0.027881551 | I19: =IFERROR(AE19/AF19-1,0) -> 0.0051888819 | ... O19: =IFERROR(AK19/AL19-1,0) -> -0.034063175 | R19: Tulip | S19: =_xlfn.XLOOKUP(R19,Summary!A:A,Summary!B:B) -> SFH | T19: =_xlfn.XLOOKUP(R19,Summary!A:A,Summary!C:C) -> 1170 | U19: =_xlfn.XLOOKUP(R19,Summary!A:A,Summary!D:D) -> 3 | V19: =_xlfn.XLOOKUP(R19,Summary!A:A,Summary!E:E) -> 2 | W19: =_xlfn.XLOOKUP(R19,Summary!A:A,Summary!F:F) -> 1 | X19: =_xlfn.XLOOKUP(R19,Summary!A:A,Summary!L:L) -> 105821.13 | Y19: 105989.57 | Z19: 107735.36 | AA19: 107812.83 | AB19: 108520.88 | AC19: 108740.89 | AD19: 107569.12 | AE19: 104651.28 | AF19: 104111.06 | AG19: 104069.33 | AH19: 104896.85 | AI19: 108136.37 | AJ19: 107741.02 | AK19: 109507.63 | AL19: 113369.35
A20: White Oak | B20: =IFERROR(X20/Y20-1,0) -> -0.0035472673 | C20: =IFERROR(Y20/Z20-1,0) -> -0.013117 | D20: =IFERROR(Z20/AA20-1,0) -> 0.005071755 | E20: =IFERROR(AA20/AB20-1,0) -> -0.011525289 | F20: =IFERROR(AB20/AC20-1,0) -> 0.0048349251 | G20: =IFERROR(AC20/AD20-1,0) -> 0.0055654297 | H20: =IFERROR(AD20/AE20-1,0) -> 0.015631235 | I20: =IFERROR(AE20/AF20-1,0) -> 0.0049491001 | ... O20: =IFERROR(AK20/AL20-1,0) -> -0.065552158 | R20: White Oak | S20: =_xlfn.XLOOKUP(R20,Summary!A:A,Summary!B:B) -> SFH | T20: =_xlfn.XLOOKUP(R20,Summary!A:A,Summary!C:C) -> 2005 | U20: =_xlfn.XLOOKUP(R20,Summary!A:A,Summary!D:D) -> 4 | V20: =_xlfn.XLOOKUP(R20,Summary!A:A,Summary!E:E) -> 2.5 | W20: =_xlfn.XLOOKUP(R20,Summary!A:A,Summary!F:F) -> 2 | X20: =_xlfn.XLOOKUP(R20,Summary!A:A,Summary!L:L) -> 143852.55 | Y20: 144364.65 | Z20: 146283.45 | AA20: 145545.28 | AB20: 147242.29 | AC20: 146533.81 | AD20: 145722.8 | AE20: 143480.03 | AF20: 142773.43 | AG20: 144645.94 | AH20: 144328.83 | AI20: 148424.43 | AJ20: 148365.62 | AK20: 149768.74 | AL20: 160275.12
A21: Willow | B21: =IFERROR(X21/Y21-1,0) -> -0.00051075306 | C21: =IFERROR(Y21/Z21-1,0) -> -0.019972266 | D21: =IFERROR(Z21/AA21-1,0) -> -0.0097718787 | E21: =IFERROR(AA21/AB21-1,0) -> -0.0077300307 | F21: =IFERROR(AB21/AC21-1,0) -> -0.00088812632 | G21: =IFERROR(AC21/AD21-1,0) -> 0.0075013607 | H21: =IFERROR(AD21/AE21-1,0) -> 0.021840128 | I21: =IFERROR(AE21/AF21-1,0) -> 0.0098417535 | ... O21: =IFERROR(AK21/AL21-1,0) -> -0.076824428 | R21: Willow | S21: =_xlfn.XLOOKUP(R21,Summary!A:A,Summary!B:B) -> SFH | T21: =_xlfn.XLOOKUP(R21,Summary!A:A,Summary!C:C) -> 1857 | U21: =_xlfn.XLOOKUP(R21,Summary!A:A,Summary!D:D) -> 4 | V21: =_xlfn.XLOOKUP(R21,Summary!A:A,Summary!E:E) -> 2.5 | W21: =_xlfn.XLOOKUP(R21,Summary!A:A,Summary!F:F) -> 1 | X21: =_xlfn.XLOOKUP(R21,Summary!A:A,Summary!L:L) -> 133890.64 | Y21: 133959.06 | Z21: 136689.05 | AA21: 138037.94 | AB21: 139113.29 | AC21: 139236.95 | AD21: 138200.26 | AE21: 135246.46 | AF21: 133928.37 | AG21: 135679.25 | AH21: 135999.59 | AI21: 139868.8 | AJ21: 139840.92 | AK21: 140530.9 | AL21: 152225.54
A22: Jasmine | B22: =IFERROR(X22/Y22-1,0) -> 0.0018729094 | C22: =IFERROR(Y22/Z22-1,0) -> -0.024778198 | D22: =IFERROR(Z22/AA22-1,0) -> -0.0082503722 | E22: =IFERROR(AA22/AB22-1,0) -> -0.0012665036 | F22: =IFERROR(AB22/AC22-1,0) -> -0.022053576 | G22: =IFERROR(AC22/AD22-1,0) -> 0.0070090284 | H22: =IFERROR(AD22/AE22-1,0) -> 0.029692611 | I22: =IFERROR(AE22/AF22-1,0) -> 0.0083674046 | ... O22: =IFERROR(AK22/AL22-1,0) -> 0.19855415 | R22: Jasmine | S22: =_xlfn.XLOOKUP(R22,Summary!A:A,Summary!B:B) -> TH | T22: =_xlfn.XLOOKUP(R22,Summary!A:A,Summary!C:C) -> 1500 | U22: =_xlfn.XLOOKUP(R22,Summary!A:A,Summary!D:D) -> 3 | V22: =_xlfn.XLOOKUP(R22,Summary!A:A,Summary!E:E) -> 2.5 | W22: =_xlfn.XLOOKUP(R22,Summary!A:A,Summary!F:F) -> 1 | X22: =_xlfn.XLOOKUP(R22,Summary!A:A,Summary!L:L) -> 127141.84 | Y22: 126904.16 | Z22: 130128.51 | AA22: 131211.05 | AB22: 131377.44 | AC22: 134340.12 | AD22: 133405.08 | AE22: 129558.16 | AF22: 128483.09 | AG22: 130698.67 | AH22: 130204.41 | AI22: 126796.97 | AJ22: 126530.55 | AK22: 169723.25 | AL22: 141606.66
A23: Palmetto | B23: =IFERROR(X23/Y23-1,0) -> -0.0016834085 | C23: =IFERROR(Y23/Z23-1,0) -> -0.026310241 | D23: =IFERROR(Z23/AA23-1,0) -> 0.0033806978 | E23: =IFERROR(AA23/AB23-1,0) -> -0.0064170068 | F23: =IFERROR(AB23/AC23-1,0) -> -0.026499427 | G23: =IFERROR(AC23/AD23-1,0) -> 0.011013404 | H23: =IFERROR(AD23/AE23-1,0) -> 0.041452426 | I23: =IFERROR(AE23/AF23-1,0) -> 0.02145097 | ... O23: =IFERROR(AK23/AL23-1,0) -> -0.075860161 | R23: Palmetto | S23: =_xlfn.XLOOKUP(R23,Summary!A:A,Summary!B:B) -> TH | T23: =_xlfn.XLOOKUP(R23,Summary!A:A,Summary!C:C) -> 1304 | U23: =_xlfn.XLOOKUP(R23,Summary!A:A,Summary!D:D) -> 3 | V23: =_xlfn.XLOOKUP(R23,Summary!A:A,Summary!E:E) -> 2.5 | W23: =_xlfn.XLOOKUP(R23,Summary!A:A,Summary!F:F) -> 0 | X23: =_xlfn.XLOOKUP(R23,Summary!A:A,Summary!L:L) -> 110043.18 | Y23: 110228.74 | Z23: 113207.25 | AA23: 112825.82 | AB23: 113554.5 | AC23: 116645.54 | AD23: 115374.87 | AE23: 110782.66 | AF23: 108456.17 | AG23: 110021.48 | AH23: 110042.23 | AI23: 112463.93 | AJ23: 112159.95 | AK23: 113126 | AL23: 122412.21
A24: Palmetto II | B24: =IFERROR(X24/Y24-1,0) -> -0.00024063428 | C24: =IFERROR(Y24/Z24-1,0) -> 0 | D24: =IFERROR(Z24/AA24-1,0) -> 0 | E24: =IFERROR(AA24/AB24-1,0) -> 0 | F24: =IFERROR(AB24/AC24-1,0) -> 0 | G24: =IFERROR(AC24/AD24-1,0) -> 0 | H24: =IFERROR(AD24/AE24-1,0) -> 0 | I24: =IFERROR(AE24/AF24-1,0) -> 0 | ... O24: =IFERROR(AK24/AL24-1,0) -> 0 | R24: Palmetto II | S24: TH | T24: 1424 | U24: 3 | V24: 2.5 | W24: 0 | X24: =_xlfn.XLOOKUP(R24,Summary!A:A,Summary!L:L) -> 111054.7 | Y24: 111081.43
A25: Palm II | B25: =IFERROR(X25/Y25-1,0) -> -0.0015174564 | C25: =IFERROR(Y25/Z25-1,0) -> 0 | D25: =IFERROR(Z25/AA25-1,0) -> 0 | E25: =IFERROR(AA25/AB25-1,0) -> 0 | F25: =IFERROR(AB25/AC25-1,0) -> 0 | G25: =IFERROR(AC25/AD25-1,0) -> 0 | H25: =IFERROR(AD25/AE25-1,0) -> 0 | I25: =IFERROR(AE25/AF25-1,0) -> 0 | ... O25: =IFERROR(AK25/AL25-1,0) -> 0 | R25: Palm II | S25: TH | T25: 1689 | U25: 3 | V25: 2.5 | W25: =_xlfn.XLOOKUP(R25,Summary!A:A,Summary!F:F) -> 1F | X25: =_xlfn.XLOOKUP(R25,Summary!A:A,Summary!L:L) -> 132402.26 | Y25: 132603.48
A26: Bayberry | B26: =IFERROR(X26/Y26-1,0) -> -0.0017035748 | C26: =IFERROR(Y26/Z26-1,0) -> -0.026674873 | D26: =IFERROR(Z26/AA26-1,0) -> 0.022250007 | E26: =IFERROR(AA26/AB26-1,0) -> -0.0088221458 | F26: =IFERROR(AB26/AC26-1,0) -> 0 | G26: =IFERROR(AC26/AD26-1,0) -> 0 | H26: =IFERROR(AD26/AE26-1,0) -> 0 | I26: =IFERROR(AE26/AF26-1,0) -> 0 | ... O26: =IFERROR(AK26/AL26-1,0) -> 0 | R26: Bayberry | S26: =_xlfn.XLOOKUP(R26,Summary!A:A,Summary!B:B) -> TH | T26: =_xlfn.XLOOKUP(R26,Summary!A:A,Summary!C:C) -> 1500 | U26: =_xlfn.XLOOKUP(R26,Summary!A:A,Summary!D:D) -> 3 | V26: =_xlfn.XLOOKUP(R26,Summary!A:A,Summary!E:E) -> 2.5 | W26: =_xlfn.XLOOKUP(R26,Summary!A:A,Summary!F:F) -> 1F | X26: =_xlfn.XLOOKUP(R26,Summary!A:A,Summary!L:L) -> 125251.84 | Y26: 125465.58 | Z26: 128904.08 | AA26: 126098.39 | AB26: 127220.75
A27: Cottonwood | B27: =IFERROR(X27/Y27-1,0) -> -0.00088647314 | C27: =IFERROR(Y27/Z27-1,0) -> -0.0053447587 | D27: =IFERROR(Z27/AA27-1,0) -> 0.0012093526 | E27: =IFERROR(AA27/AB27-1,0) -> -0.021927742 | F27: =IFERROR(AB27/AC27-1,0) -> 0 | G27: =IFERROR(AC27/AD27-1,0) -> 0 | H27: =IFERROR(AD27/AE27-1,0) -> 0 | I27: =IFERROR(AE27/AF27-1,0) -> 0 | ... O27: =IFERROR(AK27/AL27-1,0) -> 0 | R27: Cottonwood | S27: =_xlfn.XLOOKUP(R27,Summary!A:A,Summary!B:B) -> TH | T27: =_xlfn.XLOOKUP(R27,Summary!A:A,Summary!C:C) -> 1729 | U27: =_xlfn.XLOOKUP(R27,Summary!A:A,Summary!D:D) -> 3 | V27: =_xlfn.XLOOKUP(R27,Summary!A:A,Summary!E:E) -> 2.5 | W27: =_xlfn.XLOOKUP(R27,Summary!A:A,Summary!F:F) -> 1F | X27: =_xlfn.XLOOKUP(R27,Summary!A:A,Summary!L:L) -> 142077.91 | Y27: 142203.97 | Z27: 142968.1 | AA27: 142795.41 | AB27: 145996.79
A28: Linville | B28: =IFERROR(X28/Y28-1,0) -> -0.00039912383 | C28: =IFERROR(Y28/Z28-1,0) -> 0 | D28: =IFERROR(Z28/AA28-1,0) -> 0 | E28: =IFERROR(AA28/AB28-1,0) -> 0 | F28: =IFERROR(AB28/AC28-1,0) -> 0 | G28: =IFERROR(AC28/AD28-1,0) -> 0 | H28: =IFERROR(AD28/AE28-1,0) -> 0 | I28: =IFERROR(AE28/AF28-1,0) -> 0 | ... O28: =IFERROR(AK28/AL28-1,0) -> 0 | R28: Linville | S28: =_xlfn.XLOOKUP(R28,Summary!A:A,Summary!B:B) -> TH | T28: 2188 | U28: 4 | V28: 2.5 | W28: 2F | X28: =_xlfn.XLOOKUP(R28,Summary!A:A,Summary!L:L) -> 160612.82 | Y28: 160676.95
A29: Locust | B29: =IFERROR(X29/Y29-1,0) -> -0.0013079832 | C29: =IFERROR(Y29/Z29-1,0) -> -0.0188174 | D29: =IFERROR(Z29/AA29-1,0) -> 0.016328799 | E29: =IFERROR(AA29/AB29-1,0) -> -0.0097257021 | F29: =IFERROR(AB29/AC29-1,0) -> 0 | G29: =IFERROR(AC29/AD29-1,0) -> 0 | H29: =IFERROR(AD29/AE29-1,0) -> 0 | I29: =IFERROR(AE29/AF29-1,0) -> 0 | ... O29: =IFERROR(AK29/AL29-1,0) -> 0 | R29: Locust | S29: =_xlfn.XLOOKUP(R29,Summary!A:A,Summary!B:B) -> TH | T29: =_xlfn.XLOOKUP(R29,Summary!A:A,Summary!C:C) -> 1669 | U29: =_xlfn.XLOOKUP(R29,Summary!A:A,Summary!D:D) -> 3 | V29: =_xlfn.XLOOKUP(R29,Summary!A:A,Summary!E:E) -> 2.5 | W29: =_xlfn.XLOOKUP(R29,Summary!A:A,Summary!F:F) -> 1F | X29: =_xlfn.XLOOKUP(R29,Summary!A:A,Summary!L:L) -> 133947.09 | Y29: 134122.52 | Z29: 136694.76 | AA29: 134498.56 | AB29: 135819.5
A30: Fig | B30: =IFERROR(X30/Y30-1,0) -> 0.0047165403 | C30: =IFERROR(Y30/Z30-1,0) -> -0.01632041 | D30: =IFERROR(Z30/AA30-1,0) -> 0.0042832344 | E30: =IFERROR(AA30/AB30-1,0) -> -0.085437571 | F30: =IFERROR(AB30/AC30-1,0) -> 0 | G30: =IFERROR(AC30/AD30-1,0) -> 0 | H30: =IFERROR(AD30/AE30-1,0) -> 0 | I30: =IFERROR(AE30/AF30-1,0) -> 0 | ... O30: =IFERROR(AK30/AL30-1,0) -> 0 | R30: Fig | S30: =_xlfn.XLOOKUP(R30,Summary!A:A,Summary!B:B) -> TH | T30: =_xlfn.XLOOKUP(R30,Summary!A:A,Summary!C:C) -> 1798 | U30: =_xlfn.XLOOKUP(R30,Summary!A:A,Summary!D:D) -> 3 | V30: =_xlfn.XLOOKUP(R30,Summary!A:A,Summary!E:E) -> 3.5 | W30: =_xlfn.XLOOKUP(R30,Summary!A:A,Summary!F:F) -> 1R | X30: =_xlfn.XLOOKUP(R30,Summary!A:A,Summary!L:L) -> 150174.71 | Y30: 149469.73 | Z30: 151949.61 | AA30: 151301.55 | AB30: 165436 | AC30: 165436 | AD30: 165436 | AE30: 165436 | AF30: 165436
A31: Poplar | B31: =IFERROR(X31/Y31-1,0) -> -0.0015029306 | C31: =IFERROR(Y31/Z31-1,0) -> -0.0043543397 | D31: =IFERROR(Z31/AA31-1,0) -> 0 | E31: =IFERROR(AA31/AB31-1,0) -> 0 | F31: =IFERROR(AB31/AC31-1,0) -> 0 | G31: =IFERROR(AC31/AD31-1,0) -> 0 | H31: =IFERROR(AD31/AE31-1,0) -> 0 | I31: =IFERROR(AE31/AF31-1,0) -> 0 | ... O31: =IFERROR(AK31/AL31-1,0) -> 0 | R31: Poplar | S31: =_xlfn.XLOOKUP(R31,Summary!A:A,Summary!B:B) -> TH | T31: =_xlfn.XLOOKUP(R31,Summary!A:A,Summary!C:C) -> 1483 | U31: =_xlfn.XLOOKUP(R31,Summary!A:A,Summary!D:D) -> 3 | V31: =_xlfn.XLOOKUP(R31,Summary!A:A,Summary!E:E) -> 2.5 | W31: =_xlfn.XLOOKUP(R31,Summary!A:A,Summary!F:F) -> 2R | X31: =_xlfn.XLOOKUP(R31,Summary!A:A,Summary!L:L) -> 130813.81 | Y31: 131010.71 | Z31: 131583.67
A32: Fraser | B32: =IFERROR(X32/Y32-1,0) -> -0.0015324271 | C32: =IFERROR(Y32/Z32-1,0) -> -0.030648361 | D32: =IFERROR(Z32/AA32-1,0) -> 0 | E32: =IFERROR(AA32/AB32-1,0) -> 0 | F32: =IFERROR(AB32/AC32-1,0) -> 0 | G32: =IFERROR(AC32/AD32-1,0) -> 0 | H32: =IFERROR(AD32/AE32-1,0) -> 0 | I32: =IFERROR(AE32/AF32-1,0) -> 0 | ... O32: =IFERROR(AK32/AL32-1,0) -> 0 | R32: Fraser | S32: =_xlfn.XLOOKUP(R32,Summary!A:A,Summary!B:B) -> TH | T32: =_xlfn.XLOOKUP(R32,Summary!A:A,Summary!C:C) -> 1689 | U32: =_xlfn.XLOOKUP(R32,Summary!A:A,Summary!D:D) -> 3 | V32: =_xlfn.XLOOKUP(R32,Summary!A:A,Summary!E:E) -> 2.5 | W32: =_xlfn.XLOOKUP(R32,Summary!A:A,Summary!F:F) -> 2R | X32: =_xlfn.XLOOKUP(R32,Summary!A:A,Summary!L:L) -> 133563.2 | Y32: 133768.19 | Z32: 137997.59
A33: Sycamore | B33: =IFERROR(X33/Y33-1,0) -> 0.00042807059 | C33: =IFERROR(Y33/Z33-1,0) -> -0.027083784 | D33: =IFERROR(Z33/AA33-1,0) -> 0 | E33: =IFERROR(AA33/AB33-1,0) -> 0 | F33: =IFERROR(AB33/AC33-1,0) -> 0 | G33: =IFERROR(AC33/AD33-1,0) -> 0 | H33: =IFERROR(AD33/AE33-1,0) -> 0 | I33: =IFERROR(AE33/AF33-1,0) -> 0 | ... O33: =IFERROR(AK33/AL33-1,0) -> 0 | R33: Sycamore | S33: =_xlfn.XLOOKUP(R33,Summary!A:A,Summary!B:B) -> TH | T33: =_xlfn.XLOOKUP(R33,Summary!A:A,Summary!C:C) -> 1993 | U33: =_xlfn.XLOOKUP(R33,Summary!A:A,Summary!D:D) -> 3 | V33: =_xlfn.XLOOKUP(R33,Summary!A:A,Summary!E:E) -> 2.5 | W33: =_xlfn.XLOOKUP(R33,Summary!A:A,Summary!F:F) -> 2R | X33: =_xlfn.XLOOKUP(R33,Summary!A:A,Summary!L:L) -> 146861.06 | Y33: 146798.22 | Z33: 150884.75
A34: Alder | B34: =IFERROR(X34/Y34-1,0) -> 0 | C34: =IFERROR(Y34/Z34-1,0) -> 0 | D34: =IFERROR(Z34/AA34-1,0) -> 0 | E34: =IFERROR(AA34/AB34-1,0) -> 0 | F34: =IFERROR(AB34/AC34-1,0) -> 0 | G34: =IFERROR(AC34/AD34-1,0) -> 0 | H34: =IFERROR(AD34/AE34-1,0) -> 0 | I34: =IFERROR(AE34/AF34-1,0) -> 0 | R34: Alder | S34: =_xlfn.XLOOKUP(R34,Summary!A:A,Summary!B:B) -> TH | T34: =_xlfn.XLOOKUP(R34,Summary!A:A,Summary!C:C) -> 1700 | U34: =_xlfn.XLOOKUP(R34,Summary!A:A,Summary!D:D) -> 3 | V34: =_xlfn.XLOOKUP(R34,Summary!A:A,Summary!E:E) -> 2.5 | W34: =_xlfn.XLOOKUP(R34,Summary!A:A,Summary!F:F) -> 1R | X34: =_xlfn.XLOOKUP(R34,Summary!A:A,Summary!L:L) -> 130195.63
A35: Boxelder | B35: =IFERROR(X35/Y35-1,0) -> 0 | C35: =IFERROR(Y35/Z35-1,0) -> 0 | D35: =IFERROR(Z35/AA35-1,0) -> 0 | E35: =IFERROR(AA35/AB35-1,0) -> 0 | F35: =IFERROR(AB35/AC35-1,0) -> 0 | G35: =IFERROR(AC35/AD35-1,0) -> 0 | H35: =IFERROR(AD35/AE35-1,0) -> 0 | I35: =IFERROR(AE35/AF35-1,0) -> 0 | R35: Boxelder | S35: =_xlfn.XLOOKUP(R35,Summary!A:A,Summary!B:B) -> TH | T35: =_xlfn.XLOOKUP(R35,Summary!A:A,Summary!C:C) -> 1796 | U35: =_xlfn.XLOOKUP(R35,Summary!A:A,Summary!D:D) -> 4 | V35: =_xlfn.XLOOKUP(R35,Summary!A:A,Summary!E:E) -> 2.5 | W35: =_xlfn.XLOOKUP(R35,Summary!A:A,Summary!F:F) -> 2 | X35: =_xlfn.XLOOKUP(R35,Summary!A:A,Summary!L:L) -> 141492.43
A36: Bur Oak | B36: =IFERROR(X36/Y36-1,0) -> 0 | C36: =IFERROR(Y36/Z36-1,0) -> 0 | D36: =IFERROR(Z36/AA36-1,0) -> 0 | E36: =IFERROR(AA36/AB36-1,0) -> 0 | F36: =IFERROR(AB36/AC36-1,0) -> 0 | G36: =IFERROR(AC36/AD36-1,0) -> 0 | H36: =IFERROR(AD36/AE36-1,0) -> 0 | I36: =IFERROR(AE36/AF36-1,0) -> 0 | R36: Bur Oak | S36: =_xlfn.XLOOKUP(R36,Summary!A:A,Summary!B:B) -> TH | T36: =_xlfn.XLOOKUP(R36,Summary!A:A,Summary!C:C) -> 1548 | U36: =_xlfn.XLOOKUP(R36,Summary!A:A,Summary!D:D) -> 3 | V36: =_xlfn.XLOOKUP(R36,Summary!A:A,Summary!E:E) -> 2.5 | W36: =_xlfn.XLOOKUP(R36,Summary!A:A,Summary!F:F) -> 1 | X36: =_xlfn.XLOOKUP(R36,Summary!A:A,Summary!L:L) -> 124886
A37: Conifer | B37: =IFERROR(X37/Y37-1,0) -> 0 | C37: =IFERROR(Y37/Z37-1,0) -> 0 | D37: =IFERROR(Z37/AA37-1,0) -> 0 | E37: =IFERROR(AA37/AB37-1,0) -> 0 | F37: =IFERROR(AB37/AC37-1,0) -> 0 | G37: =IFERROR(AC37/AD37-1,0) -> 0 | H37: =IFERROR(AD37/AE37-1,0) -> 0 | I37: =IFERROR(AE37/AF37-1,0) -> 0 | R37: Conifer | S37: =_xlfn.XLOOKUP(R37,Summary!A:A,Summary!B:B) -> TH | T37: =_xlfn.XLOOKUP(R37,Summary!A:A,Summary!C:C) -> 1892 | U37: =_xlfn.XLOOKUP(R37,Summary!A:A,Summary!D:D) -> 0 | V37: =_xlfn.XLOOKUP(R37,Summary!A:A,Summary!E:E) -> 0 | W37: =_xlfn.XLOOKUP(R37,Summary!A:A,Summary!F:F) -> 2 | X37: =_xlfn.XLOOKUP(R37,Summary!A:A,Summary!L:L) -> 163028.48
A38: Pinyon | B38: =IFERROR(X38/Y38-1,0) -> 0 | C38: =IFERROR(Y38/Z38-1,0) -> 0 | D38: =IFERROR(Z38/AA38-1,0) -> 0 | E38: =IFERROR(AA38/AB38-1,0) -> 0 | F38: =IFERROR(AB38/AC38-1,0) -> 0 | G38: =IFERROR(AC38/AD38-1,0) -> 0 | H38: =IFERROR(AD38/AE38-1,0) -> 0 | I38: =IFERROR(AE38/AF38-1,0) -> 0 | R38: Pinyon | S38: =_xlfn.XLOOKUP(R38,Summary!A:A,Summary!B:B) -> TH | T38: =_xlfn.XLOOKUP(R38,Summary!A:A,Summary!C:C) -> 1748 | U38: =_xlfn.XLOOKUP(R38,Summary!A:A,Summary!D:D) -> 3 | V38: =_xlfn.XLOOKUP(R38,Summary!A:A,Summary!E:E) -> 3.5 | W38: =_xlfn.XLOOKUP(R38,Summary!A:A,Summary!F:F) -> 2 | X38: =_xlfn.XLOOKUP(R38,Summary!A:A,Summary!L:L) -> 151644.3
A40: Retired
A41: Arborbrook | D41: =IFERROR(Z41/AA41-1,0) -> -0.015338364 | E41: =IFERROR(AA41/AB41-1,0) -> -0.017791546 | F41: =IFERROR(AB41/AC41-1,0) -> 0.002137465 | G41: =IFERROR(AC41/AD41-1,0) -> 0.0031937584 | H41: =IFERROR(AD41/AE41-1,0) -> 0.01705282 | I41: =IFERROR(AE41/AF41-1,0) -> 0.01661383 | J41: =IFERROR(AF41/AG41-1,0) -> 4.4408921e-16 | K41: =IFERROR(AG41/AH41-1,0) -> 0.00030031511 | ... O41: =IFERROR(AK41/AL41-1,0) -> 0 | R41: Arborbrook | S41: =_xlfn.XLOOKUP(R41,Summary!A:A,Summary!B:B) -> SFH | T41: =_xlfn.XLOOKUP(R41,Summary!A:A,Summary!C:C) -> 2219 | U41: =_xlfn.XLOOKUP(R41,Summary!A:A,Summary!D:D) -> 3 | V41: =_xlfn.XLOOKUP(R41,Summary!A:A,Summary!E:E) -> 3 | W41: =_xlfn.XLOOKUP(R41,Summary!A:A,Summary!F:F) -> 2 | Z41: 174492.44 | AA41: 177210.56 | AB41: 180420.52 | AC41: 180035.7 | AD41: 179462.54 | AE41: 176453.51 | AF41: 173569.85 | AG41: 173569.85 | AH41: 173517.74 | AI41: 177694.73 | AJ41: 177503.33 | AK41: 174809.89
...

Sheet MODEL SUMMARY
A1: County | B1: =Summary!B3 -> None | AI1: 21000 | AJ1: =C58+21000 -> 160411.53 | AM1: =AI1/6 -> 3500
A2: MODEL | AK2: Do not copy models to deal sheet
A3: ACTIVITY | B3: Acacia | C3: Aspen 2-Story | D3: Atlas | E3: Banyan | F3: Cherry | G3: Dogwood | H3: Hazel | I3: Holly | J3: Elm | K3: Lilac | L3: Lily | M3: Magnolia | N3: Spindle | O3: Spruce | P3: Tulip | Q3: White Oak | R3: Willow | S3: Jasmine | T3: Palm II | U3: Palmetto | V3: Palmetto II | W3: Linville | X3: Bayberry | Y3: Alder | Z3: Boxelder | AA3: Bur Oak | AB3: Conifer | AC3: Pinyon | AD3: Cottonwood | AE3: Locust | AF3: Fraser | AG3: Sycamore | AH3: Poplar | AI3: Fig | AJ3: Aspen 3-Story | AK3: West End | AL3: Long Farm | AM3: Fir
A4: Dumpster | B4: {=IFERROR(_xlfn.XLOOKUP($A4, INDIRECT("'" & B$3 & "'!A:A"), INDIRECT("'" & B$3 & "'!B:B")),0)} -> 3000 | C4: {=IFERROR(_xlfn.XLOOKUP($A4, INDIRECT("'" & C$3 & "'!A:A"), INDIRECT("'" & C$3 & "'!B:B")),0)} -> 3000 | D4: {=IFERROR(_xlfn.XLOOKUP($A4, INDIRECT("'" & D$3 & "'!A:A"), INDIRECT("'" & D$3 & "'!B:B")),0)} -> 3000 | E4: {=IFERROR(_xlfn.XLOOKUP($A4, INDIRECT("'" & E$3 & "'!A:A"), INDIRECT("'" & E$3 & "'!B:B")),0)} -> 3000 | F4: {=IFERROR(_xlfn.XLOOKUP($A4, INDIRECT("'" & F$3 & "'!A:A"), INDIRECT("'" & F$3 & "'!B:B")),0)} -> 3000 | G4: {=IFERROR(_xlfn.XLOOKUP($A4, INDIRECT("'" & G$3 & "'!A:A"), INDIRECT("'" & G$3 & "'!B:B")),0)} -> 3000 | H4: {=IFERROR(_xlfn.XLOOKUP($A4, INDIRECT("'" & H$3 & "'!A:A"), INDIRECT("'" & H$3 & "'!B:B")),0)} -> 3000 | I4: {=IFERROR(_xlfn.XLOOKUP($A4, INDIRECT("'" & I$3 & "'!A:A"), INDIRECT("'" & I$3 & "'!B:B")),0)} -> 3000 | ... AI4: {=IFERROR(_xlfn.XLOOKUP($A4, INDIRECT("'" & AI$3 & "'!A:A"), INDIRECT("'" & AI$3 & "'!B:B")),0)} -> 1500 | AJ4: =C4 -> 3000 | AK4: {=IFERROR(_xlfn.XLOOKUP($A4, INDIRECT("'" & AK$3 & "'!A:A"), INDIRECT("'" & AK$3 & "'!B:B")),0)} -> 1750 | AL4: {=IFERROR(_xlfn.XLOOKUP($A4, INDIRECT("'" & AL$3 & "'!A:A"), INDIRECT("'" & AL$3 & "'!B:B")),0)} -> 1750 | AM4: {=IFERROR(_xlfn.XLOOKUP($A4, INDIRECT("'" & AM$3 & "'!A:A"), INDIRECT("'" & AM$3 & "'!B:B")),0)} -> 1750
A5: Utilities | B5: {=IFERROR(_xlfn.XLOOKUP($A5, INDIRECT("'" & B$3 & "'!A:A"), INDIRECT("'" & B$3 & "'!B:B")),0)} -> 300 | C5: {=IFERROR(_xlfn.XLOOKUP($A5, INDIRECT("'" & C$3 & "'!A:A"), INDIRECT("'" & C$3 & "'!B:B")),0)} -> 300 | D5: {=IFERROR(_xlfn.XLOOKUP($A5, INDIRECT("'" & D$3 & "'!A:A"), INDIRECT("'" & D$3 & "'!B:B")),0)} -> 300 | E5: {=IFERROR(_xlfn.XLOOKUP($A5, INDIRECT("'" & E$3 & "'!A:A"), INDIRECT("'" & E$3 & "'!B:B")),0)} -> 300 | F5: {=IFERROR(_xlfn.XLOOKUP($A5, INDIRECT("'" & F$3 & "'!A:A"), INDIRECT("'" & F$3 & "'!B:B")),0)} -> 300 | G5: {=IFERROR(_xlfn.XLOOKUP($A5, INDIRECT("'" & G$3 & "'!A:A"), INDIRECT("'" & G$3 & "'!B:B")),0)} -> 300 | H5: {=IFERROR(_xlfn.XLOOKUP($A5, INDIRECT("'" & H$3 & "'!A:A"), INDIRECT("'" & H$3 & "'!B:B")),0)} -> 300 | I5: {=IFERROR(_xlfn.XLOOKUP($A5, INDIRECT("'" & I$3 & "'!A:A"), INDIRECT("'" & I$3 & "'!B:B")),0)} -> 300 | ... AI5: {=IFERROR(_xlfn.XLOOKUP($A5, INDIRECT("'" & AI$3 & "'!A:A"), INDIRECT("'" & AI$3 & "'!B:B")),0)} -> 300 | AJ5: =C5 -> 300 | AK5: {=IFERROR(_xlfn.XLOOKUP($A5, INDIRECT("'" & AK$3 & "'!A:A"), INDIRECT("'" & AK$3 & "'!B:B")),0)} -> 200 | AL5: {=IFERROR(_xlfn.XLOOKUP($A5, INDIRECT("'" & AL$3 & "'!A:A"), INDIRECT("'" & AL$3 & "'!B:B")),0)} -> 200 | AM5: {=IFERROR(_xlfn.XLOOKUP($A5, INDIRECT("'" & AM$3 & "'!A:A"), INDIRECT("'" & AM$3 & "'!B:B")),0)} -> 200
A6: Portable toilet | B6: {=IFERROR(_xlfn.XLOOKUP($A6, INDIRECT("'" & B$3 & "'!A:A"), INDIRECT("'" & B$3 & "'!B:B")),0)} -> 875 | C6: {=IFERROR(_xlfn.XLOOKUP($A6, INDIRECT("'" & C$3 & "'!A:A"), INDIRECT("'" & C$3 & "'!B:B")),0)} -> 875 | D6: {=IFERROR(_xlfn.XLOOKUP($A6, INDIRECT("'" & D$3 & "'!A:A"), INDIRECT("'" & D$3 & "'!B:B")),0)} -> 875 | E6: {=IFERROR(_xlfn.XLOOKUP($A6, INDIRECT("'" & E$3 & "'!A:A"), INDIRECT("'" & E$3 & "'!B:B")),0)} -> 875 | F6: {=IFERROR(_xlfn.XLOOKUP($A6, INDIRECT("'" & F$3 & "'!A:A"), INDIRECT("'" & F$3 & "'!B:B")),0)} -> 875 | G6: {=IFERROR(_xlfn.XLOOKUP($A6, INDIRECT("'" & G$3 & "'!A:A"), INDIRECT("'" & G$3 & "'!B:B")),0)} -> 875 | H6: {=IFERROR(_xlfn.XLOOKUP($A6, INDIRECT("'" & H$3 & "'!A:A"), INDIRECT("'" & H$3 & "'!B:B")),0)} -> 875 | I6: {=IFERROR(_xlfn.XLOOKUP($A6, INDIRECT("'" & I$3 & "'!A:A"), INDIRECT("'" & I$3 & "'!B:B")),0)} -> 875 | ... AI6: {=IFERROR(_xlfn.XLOOKUP($A6, INDIRECT("'" & AI$3 & "'!A:A"), INDIRECT("'" & AI$3 & "'!B:B")),0)} -> 437.5 | AJ6: =C6 -> 875 | AK6: {=IFERROR(_xlfn.XLOOKUP($A6, INDIRECT("'" & AK$3 & "'!A:A"), INDIRECT("'" & AK$3 & "'!B:B")),0)} -> 350 | AL6: {=IFERROR(_xlfn.XLOOKUP($A6, INDIRECT("'" & AL$3 & "'!A:A"), INDIRECT("'" & AL$3 & "'!B:B")),0)} -> 350 | AM6: {=IFERROR(_xlfn.XLOOKUP($A6, INDIRECT("'" & AM$3 & "'!A:A"), INDIRECT("'" & AM$3 & "'!B:B")),0)} -> 350
