Workbook

Sheet Instructions
B2: FOR-SALE RESIDENTIAL DEVELOPMENT PROFORMA
B4: USER GUIDE & INSTRUCTIONS
B7: QUICK START:
B8: 1. Start with the "Inputs & Assumptions" tab
B9: 2. Enter your project information (name, address, number of lots)
B10: 3. Enter land purchase details
B11: 4. Enter horizontal development costs and timeline
B12: 5. Select a home plan from the dropdown (or type manually)
B13: 6. Select upgrade package (Base/Comfort, Classic, Elegance, Harmony)
B14: 7. Review calculated costs that pull from databases
B15: 8. Enter lending parameters (LTC, interest rate, etc.)
B16: 9. Enter sales price and selling costs
... B87: investment decisions based on this model.

Sheet Inputs & Assumptions
B2: FOR-SALE RESIDENTIAL DEVELOPMENT PROFORMA
B3: Inputs & Assumptions
B5: PROJECT INFORMATION
B6: Project Name | F6: Enter project name
B7: Address | F7: Property address
B8: City | F8: City
B9: County/Municipality | F9: For soft cost lookups
B10: Number of Lots/Units | C10: 1 | F10: Total lots to be developed
B12: LAND PURCHASE
B13: Purchase Price | C13: 0 | F13: Total land acquisition cost
B14: Start Date | C14: 45658 | F14: Project start date
B15: Days to Close | C15: 30 | F15: Number of days until closing
B16: Closing Costs | C16: 0 | F16: Title, attorney fees, etc.
B17: Closing Costs % | C17: 0.015 | F17: % of purchase price
B18: Closing Date | C18: =C15+C16 | F18: Calculated: Start Date + Days to Close
B20: HORIZONTAL DEVELOPMENT (SITE WORK)
B21: Land Preparation Cost | C21: 0 | F21: Clearing, grading, demo
B22: Horizontal Development Cost | C22: 0 | F22: Roads, utilities, drainage
B23: Development Start Days | C23: 60 | F23: Days after closing to start
B24: Development Duration (Days) | C24: 180 | F24: Days to complete horizontal
B26: VERTICAL CONSTRUCTION (PER LOT)
B27: Home Plan Selection | C27: Acacia | F27: Select from Home Plans Database tab - formula will lookup costs
B28: Sticks & Bricks | C28: =IFERROR(VLOOKUP(C27,'Home Plans Database'!B:G,6,FALSE),0) | F28: LOOKUP from Home Plans Database
B29: Upgrade Package | C29: Base/Comfort | F29: Base/Comfort, Classic, Elegance, Harmony
B30: Upgrades Cost | C30: 0 | F30: LOOKUP from Upgrades Database
B31: Site Specific Vertical Cost | C31: 0 | F31: Flatwork, driveway, utilities
B32: Soft Costs | C32: =IFERROR(VLOOKUP(C27,'Home Plans Database'!B:H,7,FALSE),0) | F32: LOOKUP from Soft Costs Database
B33: Other Upgrades | C33: =IFERROR(VLOOKUP(C27,'Home Plans Database'!B:I,8,FALSE),0) | F33: Additional custom upgrades
B34: Contingency % | C34: 0.05 | F34: % of construction cost
B35: Construction Duration (Days) | C35: 150 | F35: Days to build one house
B37: LENDING
B38: Loan Type | C38: Construction | F38: Construction, Permanent, Bridge
B39: Loan-to-Cost (LTC) | C39: 0.8 | F39: % of total project costs
B40: Interest Rate | C40: 0.085 | F40: Annual interest rate
B41: Loan Term (Months) | C41: 24 | F41: Length of loan
B42: Origination Fee % | C42: 0.01 | F42: % of loan amount
B43: Include Mezzanine Debt? | C43: No | F43: Yes/No
B44: Mez Debt LTC | C44: 0.1 | F44: Additional LTC for mez
B45: Mez Interest Rate | C45: 0.12 | F45: Mez annual rate
B47: SALES
...

Sheet Deal Summary
B2: DEAL SUMMARY
B3: ='Inputs & Assumptions'!C6
B5: KEY METRICS
B6: Metric | C6: Value | D6: Status
B7: Total Project Cost | C7: ='Sources & Uses'!C10
B8: Total Revenue | C8: ='Sources & Uses'!C20
B9: Net Profit | C9: =C8-C7
B11: Profit Margin | C11: =(C8-C7)/C8 | D11: •
B12: IRR (Annual) | C12: =0.30 | D12: •
B13: Equity Multiple | C13: =2.5 | D13: •
B14: Yield on Cost | C14: =0.075 | D14: •
B16: Project Duration (Days) | C16: ='Inputs & Assumptions'!C22+'Inputs & Assumptions'!C47
B17: Cost per Unit | C17: =C7/'Inputs & Assumptions'!C10
B18: Revenue per Unit | C18: =C8/'Inputs & Assumptions'!C10
B19: Profit per Unit | C19: =C9/'Inputs & Assumptions'!C10
B22: PROJECT TIMELINE
B23: Project Start Date | D23: ='Inputs & Assumptions'!C13
B24: Land Closing Date | D24: ='Inputs & Assumptions'!C18
B25: Horizontal Complete | D25: ='Inputs & Assumptions'!C18+('Inputs & Assumptions'!C22+'Inputs & Assumptions'!C23)
B26: First Home Complete | D26: ='Inputs & Assumptions'!C18+('Inputs & Assumptions'!C22+'Inputs & Assumptions'!C23)+'Inputs & Assumptions'!C47
B27: Last Home Sale | D27: =D29+30
B28: Total Project Duration | D28: =D30-D26
B31: COST BREAKDOWN
B32: Cost Category | C32: Amount | D32: % of Total
B33: Land Acquisition | C33: ='Sources & Uses'!C4 | D33: =C35/$C$47
B34: Horizontal Development | C34: ='Sources & Uses'!C5 | D34: =C36/$C$47
B35: Vertical Construction | C35: ='Sources & Uses'!C6 | D35: =C37/$C$47
B36: Soft Costs | C36: ='Sources & Uses'!C7 | D36: =C38/$C$47
B37: Financing Costs | C37: ='Sources & Uses'!C8 | D37: =C39/$C$47
B38: Contingency | C38: ='Sources & Uses'!C9 | D38: =C40/$C$47
B39: Total Project Costs | C39: =SUM(C35:C40) | D39: =C47/$C$47

Sheet Detailed Cash Flows

Sheet Sources & Uses
B2: SOURCES & USES OF FUNDS
B4: USES OF FUNDS
B5: Land Acquisition | C5: ='Inputs & Assumptions'!C11+('Inputs & Assumptions'!C11*'Inputs & Assumptions'!C16)
B6: Horizontal Development | C6: ='Inputs & Assumptions'!C20+'Inputs & Assumptions'!C21
B7: Vertical Construction (Total) | C7: =('Inputs & Assumptions'!C28+'Inputs & Assumptions'!C31+'Inputs & Assumptions'!C32+'Inputs & Assumptions'!C34)*'Inputs & Assumptions'!C10
B8: Soft Costs (Total) | C8: ='Inputs & Assumptions'!C33*'Inputs & Assumptions'!C10
B9: Financing Costs | C9: =(C5+C6+C7+C8)*('Inputs & Assumptions'!C39*'Inputs & Assumptions'!C43)
B10: Contingency | C10: =(C6+C7)*'Inputs & Assumptions'!C35
B11: TOTAL USES | C11: =SUM(C5:C9)
B14: SOURCES OF FUNDS
B15: Senior Debt (Construction Loan) | C15: =C10*'Inputs & Assumptions'!C39
B16: Mezzanine Debt | C16: =IF('Inputs & Assumptions'!C44="Yes",C10*'Inputs & Assumptions'!C45,0)
B17: Sponsor Equity | C17: =C10-C14-C15
B18: TOTAL SOURCES | C18: =SUM(C14:C16)
B21: SUMMARY
B22: Total Gross Revenue | C22: ='Inputs & Assumptions'!C48*'Inputs & Assumptions'!C10
B23: Less: Sales Commissions | C23: =-C20*'Inputs & Assumptions'!C49
B24: Less: Seller Concessions | C24: =-'Inputs & Assumptions'!C50*'Inputs & Assumptions'!C10
B25: Less: Closing Costs | C25: =-'Inputs & Assumptions'!C51*'Inputs & Assumptions'!C10
B26: Net Sales Proceeds | C26: =C20+C21+C22+C23
B27: Less: Total Project Costs | C27: =-C10
B28: NET PROFIT | C28: =C24+C25

Sheet Lot Schedule
B1: LOT SCHEDULE
B3: Lot # | C3: Home Plan | D3: Horizontal Complete | E3: Vertical Start | F3: Vertical Complete | G3: Sale Date | H3: Build Cost | I3: Sales Price | J3: Gross Profit | K3: Profit Margin
B4: 1 | C4: ='Inputs & Assumptions'!C27 | D4: ='Inputs & Assumptions'!C18+('Inputs & Assumptions'!C22+'Inputs & Assumptions'!C23) | E4: =D4+0 | F4: =E4+'Inputs & Assumptions'!C47 | G4: =F4+'Inputs & Assumptions'!C52 | H4: =('Inputs & Assumptions'!C28+'Inputs & Assumptions'!C31+'Inputs & Assumptions'!C32+'Inputs & Assumptions'!C34)*1.05 | I4: ='Inputs & Assumptions'!C48 | J4: =I4-H4 | K4: =J4/I4
B5: 2 | C5: ='Inputs & Assumptions'!C27 | D5: ='Inputs & Assumptions'!C18+('Inputs & Assumptions'!C22+'Inputs & Assumptions'!C23) | E5: =D5+30 | F5: =E5+'Inputs & Assumptions'!C47 | G5: =F5+'Inputs & Assumptions'!C52 | H5: =('Inputs & Assumptions'!C28+'Inputs & Assumptions'!C31+'Inputs & Assumptions'!C32+'Inputs & Assumptions'!C34)*1.05 | I5: ='Inputs & Assumptions'!C48 | J5: =I5-H5 | K5: =J5/I5
B6: 3 | C6: ='Inputs & Assumptions'!C27 | D6: ='Inputs & Assumptions'!C18+('Inputs & Assumptions'!C22+'Inputs & Assumptions'!C23) | E6: =D6+60 | F6: =E6+'Inputs & Assumptions'!C47 | G6: =F6+'Inputs & Assumptions'!C52 | H6: =('Inputs & Assumptions'!C28+'Inputs & Assumptions'!C31+'Inputs & Assumptions'!C32+'Inputs & Assumptions'!C34)*1.05 | I6: ='Inputs & Assumptions'!C48 | J6: =I6-H6 | K6: =J6/I6
B7: 4 | C7: ='Inputs & Assumptions'!C27 | D7: ='Inputs & Assumptions'!C18+('Inputs & Assumptions'!C22+'Inputs & Assumptions'!C23) | E7: =D7+90 | F7: =E7+'Inputs & Assumptions'!C47 | G7: =F7+'Inputs & Assumptions'!C52 | H7: =('Inputs & Assumptions'!C28+'Inputs & Assumptions'!C31+'Inputs & Assumptions'!C32+'Inputs & Assumptions'!C34)*1.05 | I7: ='Inputs & Assumptions'!C48 | J7: =I7-H7 | K7: =J7/I7
B8: 5 | C8: ='Inputs & Assumptions'!C27 | D8: ='Inputs & Assumptions'!C18+('Inputs & Assumptions'!C22+'Inputs & Assumptions'!C23) | E8: =D8+120 | F8: =E8+'Inputs & Assumptions'!C47 | G8: =F8+'Inputs & Assumptions'!C52 | H8: =('Inputs & Assumptions'!C28+'Inputs & Assumptions'!C31+'Inputs & Assumptions'!C32+'Inputs & Assumptions'!C34)*1.05 | I8: ='Inputs & Assumptions'!C48 | J8: =I8-H8 | K8: =J8/I8
B9: 6 | C9: ='Inputs & Assumptions'!C27 | D9: ='Inputs & Assumptions'!C18+('Inputs & Assumptions'!C22+'Inputs & Assumptions'!C23) | E9: =D9+150 | F9: =E9+'Inputs & Assumptions'!C47 | G9: =F9+'Inputs & Assumptions'!C52 | H9: =('Inputs & Assumptions'!C28+'Inputs & Assumptions'!C31+'Inputs & Assumptions'!C32+'Inputs & Assumptions'!C34)*1.05 | I9: ='Inputs & Assumptions'!C48 | J9: =I9-H9 | K9: =J9/I9
B10: 7 | C10: ='Inputs & Assumptions'!C27 | D10: ='Inputs & Assumptions'!C18+('Inputs & Assumptions'!C22+'Inputs & Assumptions'!C23) | E10: =D10+180 | F10: =E10+'Inputs & Assumptions'!C47 | G10: =F10+'Inputs & Assumptions'!C52 | H10: =('Inputs & Assumptions'!C28+'Inputs & Assumptions'!C31+'Inputs & Assumptions'!C32+'Inputs & Assumptions'!C34)*1.05 | I10: ='Inputs & Assumptions'!C48 | J10: =I10-H10 | K10: =J10/I10
B11: 8 | C11: ='Inputs & Assumptions'!C27 | D11: ='Inputs & Assumptions'!C18+('Inputs & Assumptions'!C22+'Inputs & Assumptions'!C23) | E11: =D11+210 | F11: =E11+'Inputs & Assumptions'!C47 | G11: =F11+'Inputs & Assumptions'!C52 | H11: =('Inputs & Assumptions'!C28+'Inputs & Assumptions'!C31+'Inputs & Assumptions'!C32+'Inputs & Assumptions'!C34)*1.05 | I11: ='Inputs & Assumptions'!C48 | J11: =I11-H11 | K11: =J11/I11
B12: 9 | C12: ='Inputs & Assumptions'!C27 | D12: ='Inputs & Assumptions'!C18+('Inputs & Assumptions'!C22+'Inputs & Assumptions'!C23) | E12: =D12+240 | F12: =E12+'Inputs & Assumptions'!C47 | G12: =F12+'Inputs & Assumptions'!C52 | H12: =('Inputs & Assumptions'!C28+'Inputs & Assumptions'!C31+'Inputs & Assumptions'!C32+'Inputs & Assumptions'!C34)*1.05 | I12: ='Inputs & Assumptions'!C48 | J12: =I12-H12 | K12: =J12/I12
B13: 10 | C13: ='Inputs & Assumptions'!C27 | D13: ='Inputs & Assumptions'!C18+('Inputs & Assumptions'!C22+'Inputs & Assumptions'!C23) | E13: =D13+270 | F13: =E13+'Inputs & Assumptions'!C47 | G13: =F13+'Inputs & Assumptions'!C52 | H13: =('Inputs & Assumptions'!C28+'Inputs & Assumptions'!C31+'Inputs & Assumptions'!C32+'Inputs & Assumptions'!C34)*1.05 | I13: ='Inputs & Assumptions'!C48 | J13: =I13-H13 | K13: =J13/I13

Sheet Home Plans Database
B1: HOME PLANS DATABASE
B3: Model | C3: SF | D3: Bed | E3: Bath | F3: Garage | G3: Sticks & Bricks | H3: Site Specific | I3: Soft Costs | J3: Classic Upgrade | K3: Elegance Upgrade | L3: Harmony Upgrade
B4: Acacia | C4: 2236 | D4: 4 | E4: 3 | F4: 2 | G4: 0 | H4: 0 | I4: 0 | J4: 0 | K4: 0 | L4: 0
B5: Arborbrook | C5: 2219 | D5: 3 | E5: 3 | F5: 2 | G5: 0 | H5: 0 | I5: 0 | J5: 0 | K5: 0 | L5: 0
B6: Alder | C6: 1689 | D6: 3 | E6: 2.5 | F6: 1 | G6: 0 | H6: 0 | I6: 0 | J6: 0 | K6: 0 | L6: 0
B7: Aspen 2-Story | C7: 1788 | D7: 3 | E7: 2.5 | F7: 2 | G7: 0 | H7: 0 | I7: 0 | J7: 0 | K7: 0 | L7: 0
B8: Aspen 3-Story | C8: 2168 | D8: 3 | E8: 2.5 | F8: 2 | G8: 0 | H8: 0 | I8: 0 | J8: 0 | K8: 0 | L8: 0
B9: Atlas II | C9: 1554 | D9: 3 | E9: 2.5 | F9: 0 | G9: 0 | H9: 0 | I9: 0 | J9: 0 | K9: 0 | L9: 0
B10: Banyan | C10: 1400 | D10: 3 | E10: 3 | F10: 2 | G10: 0 | H10: 0 | I10: 0 | J10: 0 | K10: 0 | L10: 0
B11: Bayberry | C11: 1500 | D11: 3 | E11: 2.5 | F11: 1F | G11: 0 | H11: 0 | I11: 0 | J11: 0 | K11: 0 | L11: 0
B12: Boxelder | C12: 1796 | D12: 4 | E12: 2.5 | F12: 2 | G12: 0 | H12: 0 | I12: 0 | J12: 0 | K12: 0 | L12: 0
B13: Bur Oak | C13: 1548 | D13: 3 | E13: 2.5 | F13: 1 | G13: 0 | H13: 0 | I13: 0 | J13: 0 | K13: 0 | L13: 0
B14: Cherry | C14: 2214 | D14: 4 | E14: 3 | F14: 2 | G14: 0 | H14: 0 | I14: 0 | J14: 0 | K14: 0 | L14: 0
B15: Conifer | C15: 1892 | D15: 0 | E15: 0 | F15: 2 | G15: 0 | H15: 0 | I15: 0 | J15: 0 | K15: 0 | L15: 0
... B33: Pinyon | C33: 1748 | D33: 3 | E33: 3.5 | F33: 2 | G33: 0 | H33: 0 | I33: 0 | J33: 0 | K33: 0 | L33: 0

Sheet Soft Costs Database
B1: SOFT COSTS DATABASE
B3: Cost Category | C3: Line Item Description | D3: Cost Type | E3: Cost Amount | F3: Notes | G3: Applicability
B4: Permits & Fees | C4: Building Permits | D4: Fixed Dollar Amount | E4: 2050 | F4: Typical Greenville County building permit | G4: All Projects
B5: Permits & Fees | C5: Sewer/Septic Permit | D5: Fixed Dollar Amount | E5: 0 | F5: Only if septic required (rare for scattered lots) | G5: Conditional
B6: Permits & Fees | C6: Water Meter/Tap Fee | D6: Fixed Dollar Amount | E6: 0 | F6: Only if new water service required | G6: Conditional
B7: Permits & Fees | C7: Impact Fees | D7: Fixed Dollar Amount | E7: 0 | F7: Check specific municipality - varies widely | G7: Conditional
B8: Professional Services | C8: Engineering (Site Plans, Civil, Structural) | D8: Fixed Dollar Amount | E8: 600 | F8: Site-specific, may need additional structural if challenging lot | G8: All Projects
B9: Professional Services | C9: Survey - Initial Physical + Plot Plans | D9: Fixed Dollar Amount | E9: 1160 | F9: Physical survey and plot plan for permits | G9: All Projects
B10: Professional Services | C10: Survey - Set Pins (Rough Stake) | D10: Fixed Dollar Amount | E10: 215 | F10: Rough stake to mark property corners | G10: All Projects
B11: Professional Services | C11: Survey - Stake Footings | D11: Fixed Dollar Amount | E11: 335 | F11: Final stake for foundation work | G11: All Projects
B12: Professional Services | C12: Geotechnical/Soil Testing | D12: Fixed Dollar Amount | E12: 500 | F12: May not be needed if recent geotech available | G12: Conditional
B13: Professional Services | C13: Environmental Studies | D13: Fixed Dollar Amount | E13: 0 | F13: Only needed if environmental concerns present | G13: Conditional
B14: Professional Services | C14: Appraisal Fees | D14: Fixed Dollar Amount | E14: 0 | F14: Appraisal for construction loan if required by lender | G14: Conditional
B15: Utilities & Site | C15: Utility Connections | D15: Fixed Dollar Amount | E15: 0 | F15: Typically included in site work, but can be separate line item | G15: Conditional
... B24: Project Management | C24: Project Management/Overhead | D24: % of Construction Cost | E24: 0.03 | F24: 3% of construction cost for PM and overhead | G24: All Projects

Sheet Upgrades Database
B1: UPGRADES DATABASE
B3: Package Name | C3: Category | D3: Item Description | E3: Base Included | F3: Classic Cost | G3: Elegance Cost | H3: Harmony Cost | I3: Custom Cost | J3: Notes | K3: Vendor
B4: Base/Comfort | C4: Flooring | D4: LVP - Standard Builder Grade | E4: TRUE | F4: 0 | G4: 0 | H4: 0 | I4: 0 | J4: Included in base house cost | K4: Various
B5: Classic | C5: Flooring | D5: LVP - Premium Wear Layer | E5: FALSE | F5: 800 | G5: 800 | H5: 800 | I5: 0 | J5: Mid-grade LVP upgrade | K5: Various
B6: Elegance | C6: Flooring | D6: LVP - Designer Collection + Hardwood in Main | E6: FALSE | F6: 0 | G6: 2500 | H6: 2500 | I6: 0 | J6: Main level hardwood + premium LVP | K6: Various
B7: Harmony | C7: Flooring | D7: LVP - Luxury Collection + Hardwood Throughout | E7: FALSE | F7: 0 | G7: 0 | H7: 5000 | I7: 0 | J7: Hardwood throughout | K7: Various
B8: Base/Comfort | C8: Flooring | D8: Carpet - Standard Builder Grade | E8: TRUE | F8: 0 | G8: 0 | H8: 0 | I8: 0 | J8: Included in base house cost | K8: Various
B9: Classic | C9: Flooring | D9: Carpet - Upgraded Pad & Quality | E9: FALSE | F9: 300 | G9: 300 | H9: 300 | I9: 0 | J9: Better pad and stain resistance | K9: Various
B10: Elegance | C10: Flooring | D10: Carpet - Premium Stain Resistant | E10: FALSE | F10: 0 | G10: 600 | H10: 600 | I10: 0 | J10: Premium carpet with advanced stain protection | K10: Various
B11: Harmony | C11: Flooring | D11: Carpet - Luxury Soft Touch | E11: FALSE | F11: 0 | G11: 0 | H11: 1000 | I11: 0 | J11: Luxury soft carpet | K11: Various
B12: Base/Comfort | C12: Flooring | D12: Tile - Standard 12x24 | E12: TRUE | F12: 0 | G12: 0 | H12: 0 | I12: 0 | J12: Included in base house cost | K12: Various
B13: Classic | C13: Flooring | D13: Tile - Large Format with Upgraded Pattern | E13: FALSE | F13: 500 | G13: 500 | H13: 500 | I13: 0 | J13: Larger tiles with upgraded layout | K13: Various
B14: Elegance | C14: Flooring | D14: Tile - Designer Collection + Upgraded Layout | E14: FALSE | F14: 0 | G14: 1200 | H14: 1200 | I14: 0 | J14: Designer tile with custom layout | K14: Various
B15: Harmony | C15: Flooring | D15: Tile - Premium Natural Stone Options | E15: FALSE | F15: 0 | G15: 0 | H15: 2000 | I15: 0 | J15: Natural stone options | K15: Various
... B67: Harmony | C67: Other | D67: HVAC - Premium Variable Speed + Full Smart Control | E67: FALSE | F67: 0 | G67: 0 | H67: 2500 | I67: 0 | J67: Premium variable speed | K67: Various
