Workbook

Sheet Sticks & Bricks Detail
A1: STICKS & BRICKS - ITEMIZED COSTS
A2: Line Item | B2: TULIP | C2: ASH | D2: PALMETTO | E2: LILAC | F2: BANYAN | G2: JASMINE | H2: DOGWOOD | I2: SPRUCE | J2: ATLAS | K2: PALM | L2: ELM | M2: HAZEL | N2: ASPEN 2-Story | O2: FIG | P2: WILLOW | Q2: HOLLY | R2: WHITE OAK | S2: FIR | T2: ASPEN 3-Story | U2: CHERRY | V2: RED OAK | W2: MAGNOLIA
A3: Square Footage | B3: 1170 | C3: 1188 | D3: 1304 | E3: 1383 | F3: 1400 | G3: 1500 | H3: 1541 | I3: 1545 | J3: 1592 | K3: 1700 | L3: 1712 | M3: 1713 | N3: 1788 | O3: 1798 | P3: 1857 | Q3: 2000 | R3: 2005 | S3: 2072 | T3: 2157 | U3: 2214 | V3: 2217 | W3: 2771
A4: Dumpster | B4: 3000 | C4: 3000 | D4: 3000 | E4: 3000 | F4: 3000 | G4: 3000 | H4: 3000 | I4: 3000 | J4: 3000 | K4: 3000 | L4: 3000 | M4: 3000 | N4: 3000 | O4: 3000 | P4: 3000 | Q4: 3000 | R4: 3000 | S4: 3000 | T4: 3000 | U4: 3000 | V4: 3000 | W4: 3000
A5: Utilities | B5: 600 | C5: 600 | D5: 600 | E5: 600 | F5: 600 | G5: 600 | H5: 600 | I5: 600 | J5: 600 | K5: 600 | L5: 600 | M5: 600 | N5: 600 | O5: 600 | P5: 600 | Q5: 600 | R5: 600 | S5: 600 | T5: 600 | U5: 600 | V5: 600 | W5: 600
A6: Portable Toilet | B6: 875 | C6: 875 | D6: 875 | E6: 875 | F6: 875 | G6: 875 | H6: 875 | I6: 875 | J6: 875 | K6: 875 | L6: 875 | M6: 875 | N6: 875 | O6: 875 | P6: 875 | Q6: 875 | R6: 875 | S6: 875 | T6: 875 | U6: 875 | V6: 875 | W6: 875
A7: Permit Box | B7: 50 | C7: 50 | D7: 50 | E7: 50 | F7: 50 | G7: 50 | H7: 50 | I7: 50 | J7: 50 | K7: 50 | L7: 50 | M7: 50 | N7: 50 | O7: 50 | P7: 50 | Q7: 50 | R7: 50 | S7: 50 | T7: 50 | U7: 50 | V7: 50 | W7: 50
A8: Termite | B8: 250 | C8: 250 | D8: 250 | E8: 250 | F8: 250 | G8: 250 | H8: 250 | I8: 250 | J8: 250 | K8: 250 | L8: 250 | M8: 250 | N8: 250 | O8: 250 | P8: 250 | Q8: 250 | R8: 250 | S8: 250 | T8: 250 | U8: 250 | V8: 250 | W8: 250
A9: Lumber All Floors | B9: 6892 | C9: 6998 | D9: 7681 | E9: 8146 | F9: 8246 | G9: 8836 | H9: 9077 | I9: 9101 | J9: 9378 | K9: 10014 | L9: 10084 | M9: 10090 | N9: 10532 | O9: 10591 | P9: 10939 | Q9: 11781 | R9: 11810 | S9: 12205 | T9: 12706 | U9: 13042 | V9: 13059 | W9: 16323
A10: Framing Labor | B10: 4699 | C10: 4772 | D10: 5238 | E10: 5555 | F10: 5623 | G10: 6025 | H10: 6190 | I10: 6206 | J10: 6395 | K10: 6828 | L10: 6877 | M10: 6881 | N10: 7182 | O10: 7222 | P10: 7459 | Q10: 8033 | R10: 8054 | S10: 8323 | T10: 8664 | U10: 8893 | V10: 8905 | W10: 11130
A11: Stairs | B11: 408 | C11: 414 | D11: 455 | E11: 483 | F11: 488 | G11: 523 | H11: 538 | I11: 539 | J11: 556 | K11: 593 | L11: 597 | M11: 598 | N11: 624 | O11: 627 | P11: 648 | Q11: 698 | R11: 700 | S11: 723 | T11: 753 | U11: 773 | V11: 774 | W11: 967
A12: Roof Trusses | B12: 2867 | C12: 2911 | D12: 3196 | E12: 3389 | F12: 3431 | G12: 3676 | H12: 3776 | I12: 3786 | J12: 3902 | K12: 4166 | L12: 4196 | M12: 4198 | N12: 4382 | O12: 4406 | P12: 4551 | Q12: 4902 | R12: 4914 | S12: 5078 | T12: 5286 | U12: 5426 | V12: 5433 | W12: 6791
A13: I-Joist/EWP | B13: 2421 | C13: 2458 | D13: 2698 | E13: 2862 | F13: 2897 | G13: 3104 | H13: 3189 | I13: 3197 | J13: 3295 | K13: 3518 | L13: 3543 | M13: 3545 | N13: 3700 | O13: 3721 | P13: 3843 | Q13: 4139 | R13: 4149 | S13: 4288 | T13: 4464 | U13: 4582 | V13: 4588 | W13: 5735
A14: Roofing Shingle | B14: 2145 | C14: 2178 | D14: 2391 | E14: 2536 | F14: 2567 | G14: 2751 | H14: 2826 | I14: 2833 | J14: 2920 | K14: 3118 | L14: 3140 | M14: 3141 | N14: 3279 | O14: 3297 | P14: 3406 | Q14: 3668 | R14: 3677 | S14: 3800 | T14: 3956 | U14: 4060 | V14: 4066 | W14: 5082
... A55: Building Permits | B55: 2050 | C55: 2050 | D55: 2050 | E55: 2050 | F55: 2050 | G55: 2050 | H55: 2050 | I55: 2050 | J55: 2050 | K55: 2050 | L55: 2050 | M55: 2050 | N55: 2050 | O55: 2050 | P55: 2050 | Q55: 2050 | R55: 2050 | S55: 2050 | T55: 2050 | U55: 2050 | V55: 2050 | W55: 2050
A56: STICKS & BRICKS TOTAL | B56: =SUM(B4:B55) -> 96076 | C56: =SUM(C4:C55) -> 97831 | D56: =SUM(D4:D55) -> 105668 | E56: =SUM(E4:E55) -> 113798 | F56: =SUM(F4:F55) -> 115510 | G56: =SUM(G4:G55) -> 120582 | H56: =SUM(H4:H55) -> 123967 | I56: =SUM(I4:I55) -> 122622 | ... W56: =SUM(W4:W55) -> 213313
A57: Price per SF | B57: =B56/B3 -> 82.116239 | C57: =C56/C3 -> 82.349327 | D57: =D56/D3 -> 81.033742 | E57: =E56/E3 -> 82.283442 | F57: =F56/F3 -> 82.507143 | G57: =G56/G3 -> 80.388 | H57: =H56/H3 -> 80.445814 | I57: =I56/I3 -> 79.36699 | ... W57: =W56/W3 -> 76.980512

Sheet Pricing Summary
A1: RED CEDAR HOMES - PRICING SUMMARY (Contract Format)
A2: Plan Name | B2: Sq Ft | C2: Bed/Bath | D2: Garage | E2: 1. Sticks & Bricks | F2: 2. Upgrades | G2: 3. Lot Prep | H2: 4. Vert Costs | I2: 5. Soft Costs | J2: 6. Contingency | K2: 7. Builder Fee & Overhead | L2: TOTAL
A3: TULIP | B3: 1170 | C3: 3/2 | D3: 1-Car | E3: ='Sticks & Bricks Detail'!B56 -> 96076 | F3: 3500 | G3: 15000 | H3: 0 | I3: 15000 | J3: =MIN(10000, 0.05*SUM(E3:I3)) -> 6478.8 | K3: 29500 | L3: =SUM(E3:K3) -> 165554.8
A4: ASH | B4: 1188 | C4: 3/2 | D4: 2-Car | E4: ='Sticks & Bricks Detail'!C56 -> 97831 | F4: 3500 | G4: 15000 | H4: 0 | I4: 15000 | J4: =MIN(10000, 0.05*SUM(E4:I4)) -> 6566.55 | K4: 29500 | L4: =SUM(E4:K4) -> 167397.55
A5: PALMETTO | B5: 1304 | C5: 3/2.5 | D5: None | E5: ='Sticks & Bricks Detail'!D56 -> 105668 | F5: 3500 | G5: 15000 | H5: 0 | I5: 15000 | J5: =MIN(10000, 0.05*SUM(E5:I5)) -> 6958.4 | K5: 29500 | L5: =SUM(E5:K5) -> 175626.4
A6: LILAC | B6: 1383 | C6: 3/3 | D6: 1-Car | E6: ='Sticks & Bricks Detail'!E56 -> 113798 | F6: 3500 | G6: 15000 | H6: 0 | I6: 15000 | J6: =MIN(10000, 0.05*SUM(E6:I6)) -> 7364.9 | K6: 29500 | L6: =SUM(E6:K6) -> 184162.9
A7: BANYAN | B7: 1400 | C7: 3/3 | D7: 2-Car | E7: ='Sticks & Bricks Detail'!F56 -> 115510 | F7: 3500 | G7: 15000 | H7: 0 | I7: 15000 | J7: =MIN(10000, 0.05*SUM(E7:I7)) -> 7450.5 | K7: 29500 | L7: =SUM(E7:K7) -> 185960.5
A8: JASMINE | B8: 1500 | C8: 3/2.5 | D8: 1-Car | E8: ='Sticks & Bricks Detail'!G56 -> 120582 | F8: 3500 | G8: 15000 | H8: 0 | I8: 15000 | J8: =MIN(10000, 0.05*SUM(E8:I8)) -> 7704.1 | K8: 29500 | L8: =SUM(E8:K8) -> 191286.1
A9: DOGWOOD | B9: 1541 | C9: 3/2.5 | D9: 2-Car | E9: ='Sticks & Bricks Detail'!H56 -> 123967 | F9: 3500 | G9: 15000 | H9: 0 | I9: 15000 | J9: =MIN(10000, 0.05*SUM(E9:I9)) -> 7873.35 | K9: 29500 | L9: =SUM(E9:K9) -> 194840.35
A10: SPRUCE | B10: 1545 | C10: 3/2 | D10: 2-Car | E10: ='Sticks & Bricks Detail'!I56 -> 122622 | F10: 3500 | G10: 15000 | H10: 0 | I10: 15000 | J10: =MIN(10000, 0.05*SUM(E10:I10)) -> 7806.1 | K10: 29500 | L10: =SUM(E10:K10) -> 193428.1
A11: ATLAS | B11: 1592 | C11: 3/2.5 | D11: None | E11: ='Sticks & Bricks Detail'!J56 -> 125978 | F11: 3500 | G11: 15000 | H11: 0 | I11: 15000 | J11: =MIN(10000, 0.05*SUM(E11:I11)) -> 7973.9 | K11: 29500 | L11: =SUM(E11:K11) -> 196951.9
A12: PALM | B12: 1700 | C12: 3/2.5 | D12: 1-Car | E12: ='Sticks & Bricks Detail'!K56 -> 134662 | F12: 3500 | G12: 15000 | H12: 0 | I12: 15000 | J12: =MIN(10000, 0.05*SUM(E12:I12)) -> 8408.1 | K12: 29500 | L12: =SUM(E12:K12) -> 206070.1
A13: ELM | B13: 1712 | C13: 4/2.5 | D13: 2-Car | E13: ='Sticks & Bricks Detail'!L56 -> 136009 | F13: 3500 | G13: 15000 | H13: 0 | I13: 15000 | J13: =MIN(10000, 0.05*SUM(E13:I13)) -> 8475.45 | K13: 29500 | L13: =SUM(E13:K13) -> 207484.45
A14: HAZEL | B14: 1713 | C14: 4/2.5 | D14: 2-Car | E14: ='Sticks & Bricks Detail'!M56 -> 136078 | F14: 3500 | G14: 15000 | H14: 0 | I14: 15000 | J14: =MIN(10000, 0.05*SUM(E14:I14)) -> 8478.9 | K14: 29500 | L14: =SUM(E14:K14) -> 207556.9
A15: ASPEN 2-Story | B15: 1788 | C15: 3/2.5 | D15: 2-Car | E15: ='Sticks & Bricks Detail'!N56 -> 141355 | F15: 3500 | G15: 15000 | H15: 0 | I15: 15000 | J15: =MIN(10000, 0.05*SUM(E15:I15)) -> 8742.75 | K15: 29500 | L15: =SUM(E15:K15) -> 213097.75
A16: FIG | B16: 1798 | C16: 3/3.5 | D16: 1-Car | E16: ='Sticks & Bricks Detail'!O56 -> 145350 | F16: 3500 | G16: 15000 | H16: 0 | I16: 15000 | J16: =MIN(10000, 0.05*SUM(E16:I16)) -> 8942.5 | K16: 29500 | L16: =SUM(E16:K16) -> 217292.5
A17: WILLOW | B17: 1857 | C17: 4/2.5 | D17: 1-Car | E17: ='Sticks & Bricks Detail'!P56 -> 145710 | F17: 3500 | G17: 15000 | H17: 0 | I17: 15000 | J17: =MIN(10000, 0.05*SUM(E17:I17)) -> 8960.5 | K17: 29500 | L17: =SUM(E17:K17) -> 217670.5
A18: HOLLY | B18: 2000 | C18: 4/2.5 | D18: 2-Car | E18: ='Sticks & Bricks Detail'!Q56 -> 156262 | F18: 3500 | G18: 15000 | H18: 0 | I18: 15000 | J18: =MIN(10000, 0.05*SUM(E18:I18)) -> 9488.1 | K18: 29500 | L18: =SUM(E18:K18) -> 228750.1
A19: WHITE OAK | B19: 2005 | C19: 4/2.5 | D19: 2-Car | E19: ='Sticks & Bricks Detail'!R56 -> 156615 | F19: 3500 | G19: 15000 | H19: 0 | I19: 15000 | J19: =MIN(10000, 0.05*SUM(E19:I19)) -> 9505.75 | K19: 29500 | L19: =SUM(E19:K19) -> 229120.75
A20: FIR | B20: 2072 | C20: 4/3.5 | D20: 2-Car | E20: ='Sticks & Bricks Detail'!S56 -> 165696 | F20: 3500 | G20: 15000 | H20: 0 | I20: 15000 | J20: =MIN(10000, 0.05*SUM(E20:I20)) -> 9959.8 | K20: 29500 | L20: =SUM(E20:K20) -> 238655.8
A21: ASPEN 3-Story | B21: 2157 | C21: 4/3.5 | D21: 2-Car | E21: ='Sticks & Bricks Detail'!T56 -> 171846 | F21: 3500 | G21: 15000 | H21: 0 | I21: 15000 | J21: =MIN(10000, 0.05*SUM(E21:I21)) -> 10000 | K21: 29500 | L21: =SUM(E21:K21) -> 244846
A22: CHERRY | B22: 2214 | C22: 4/3 | D22: 2-Car | E22: ='Sticks & Bricks Detail'!U56 -> 173637 | F22: 3500 | G22: 15000 | H22: 0 | I22: 15000 | J22: =MIN(10000, 0.05*SUM(E22:I22)) -> 10000 | K22: 29500 | L22: =SUM(E22:K22) -> 246637
A23: RED OAK | B23: 2217 | C23: 4/3 | D23: 2-Car | E23: ='Sticks & Bricks Detail'!V56 -> 173846 | F23: 3500 | G23: 15000 | H23: 0 | I23: 15000 | J23: =MIN(10000, 0.05*SUM(E23:I23)) -> 10000 | K23: 29500 | L23: =SUM(E23:K23) -> 246846
A24: MAGNOLIA | B24: 2771 | C24: 4/3 | D24: 2-Car | E24: ='Sticks & Bricks Detail'!W56 -> 213313 | F24: 3500 | G24: 15000 | H24: 0 | I24: 15000 | J24: =MIN(10000, 0.05*SUM(E24:I24)) -> 10000 | K24: 29500 | L24: =SUM(E24:K24) -> 286313

Sheet Detailed Breakdown
A1: TULIP | 1170 SF | 3BD/2BA | 1-Car Garage
A2: Section | B2: Description | C2: Amount | D2: Notes
A3: 1. STICKS & BRICKS | B3: See 'Sticks & Bricks Detail' Tab | C3: ='Sticks & Bricks Detail'!B56 -> 96076 | D3: Full itemization in detail tab
A4: 2. UPGRADES | B4: Hardie Color-Plus Siding | C4: 0 | D4: $3,500-$4,000 if selected
B5: Exterior Elevation Upgrade | C5: 0 | D5: $3,000-$4,000 if selected
B6: Interior Package Upgrade | C6: 0 | D6: $3,795-$8,623 per level
B7: Upgrades Subtotal | C7: =SUM(C4:C6) -> 0
A8: 3. LOT PREP | B8: Homesite Preparation & Excavation | C8: 5000
B9: Utility Trenching & Connections | C9: 3000
B10: Backfill & Final Grade | C10: 2500
B11: Exterior Flatwork | C11: 3500
B12: Other (to meet $15K min) | C12: 1000 | D12: Minimum $15,000 total
B13: Lot Prep Subtotal | C13: =SUM(C8:C12) -> 15000
A14: 4. ADDED VERTICAL | B14: Stepped Foundation Upgrade | C14: 0
B15: Rock Hammering | C15: 0
B16: Fill Import/Export | C16: 0
B17: Added Vertical Subtotal | C17: =SUM(C14:C16) -> 0
A18: 5. SOFT COSTS | B18: Permitting & Plan Submittal | C18: 3500
B19: Architectural Fees | C19: 2500
B20: Engineering | C20: 1500
B21: Survey | C21: 1700
B22: Construction Insurance | C22: 2000
B23: Blueprints & Misc Supplies | C23: 1500
B24: Other (to meet $15K min) | C24: 2300 | D24: Minimum $15,000 total
B25: Soft Costs Subtotal | C25: =SUM(C18:C24) -> 15000
A26: 6. CONTINGENCY | B26: Contingency (≤$10K or 5%) | C26: =MIN(10000,0.05*(C3+C7+C13+C17+C25)) -> 6303.8 | D26: Per contract terms
A27: 7. BUILDER FEE & OVERHEAD | B27: Builder Fee | C27: 15000 | D27: Fixed per home
B28: Warranty | C28: 5000
B29: Builder's Risk | C29: 1500
B30: Bookkeeping | C30: 1500
B31: Project Management (PM) | C31: 3500
B32: Purchase Orders (PO) | C32: 3000
B33: Builder Fee & Overhead Subtotal | C33: =SUM(C27:C32) -> 29500
A34: TOTAL COST | C34: =C3+C7+C13+C17+C25+C26+C33 -> 161879.8
B35: Price per SF | C35: =C34/1170 -> 138.3588
A38: ASH | 1188 SF | 3BD/2BA | 2-Car Garage
A39: Section | B39: Description | C39: Amount | D39: Notes
A40: 1. STICKS & BRICKS | B40: See 'Sticks & Bricks Detail' Tab | C40: ='Sticks & Bricks Detail'!C56 -> 97831 | D40: Full itemization in detail tab
A41: 2. UPGRADES | B41: Hardie Color-Plus Siding | C41: 0 | D41: $3,500-$4,000 if selected
B42: Exterior Elevation Upgrade | C42: 0 | D42: $3,000-$4,000 if selected
...

Sheet Upgrades Menu
A1: RED CEDAR HOMES - UPGRADE OPTIONS
A2: Category | B2: Upgrade Name | C2: Price Range | D2: Description
A3: EXTERIOR | B3: Hardie Color-Plus Siding | C3: $3,500 - $4,000 | D3: Premium fiber cement siding
A4: EXTERIOR | B4: Elevation Upgrade - 1 | C4: $3,000 - $4,000 | D4: Enhanced architectural details
A5: EXTERIOR | B5: Elevation Upgrade - 2 | C5: $3,000 - $4,000 | D5: Premium elevation design
A6: INTERIOR - CLASSIC | B6: Foxcroft Classic | C6: $4,059 | D6: Classic finish level
A7: INTERIOR - CLASSIC | B7: Midwood Classic | C7: $3,792 | D7: Classic finish level
A8: INTERIOR - CLASSIC | B8: Madison Classic | C8: $3,852 | D8: Classic finish level
A9: INTERIOR - CLASSIC | B9: Uptown Classic | C9: $3,984 | D9: Classic finish level
A10: INTERIOR - ELEGANCE | B10: Foxcroft Elegance | C10: $6,181 | D10: Elegance finish level
A11: INTERIOR - ELEGANCE | B11: Midwood Elegance | C11: $6,468 | D11: Elegance finish level
A12: INTERIOR - ELEGANCE | B12: Madison Elegance | C12: $8,197 | D12: Premium elegance finishes
A13: INTERIOR - ELEGANCE | B13: Uptown Elegance | C13: $8,623 | D13: Top-tier elegance finishes

Sheet Floor Plan Specs
A1: RED CEDAR HOMES - FLOOR PLAN SPECIFICATIONS
A2: Plan Name | B2: Sq Ft | C2: Bedrooms | D2: Bathrooms | E2: Garage | F2: Width | G2: Depth | H2: Stories | I2: Type
A3: TULIP | B3: 1170 | C3: 3 | D3: 2 | E3: 1-Car | F3: 30' | G3: 50' | H3: 1 | I3: Single Family
A4: ASH | B4: 1188 | C4: 3 | D4: 2 | E4: 2-Car | F4: 29' | G4: 36' | H4: 1 | I4: Single Family
A5: PALMETTO | B5: 1304 | C5: 3 | D5: 2.5 | E5: None | F5: 20' | G5: 42' | H5: 2 | I5: Townhome
A6: LILAC | B6: 1383 | C6: 3 | D6: 3 | E6: 1-Car | F6: 30' | G6: 46' | H6: 1.5 | I6: Single Family
A7: BANYAN | B7: 1400 | C7: 3 | D7: 3 | E7: 2-Car | F7: 28' | G7: 24' | H7: 3 | I7: Single Family
A8: JASMINE | B8: 1500 | C8: 3 | D8: 2.5 | E8: 1-Car | F8: 20' | G8: 49' | H8: 2 | I8: Townhome
A9: DOGWOOD | B9: 1541 | C9: 3 | D9: 2.5 | E9: 2-Car | F9: 29' | G9: 36' | H9: 2 | I9: Single Family
A10: SPRUCE | B10: 1545 | C10: 3 | D10: 2 | E10: 2-Car | F10: 39' | G10: 54' | H10: 1 | I10: Single Family
A11: ATLAS | B11: 1592 | C11: 3 | D11: 2.5 | E11: None | F11: 24' | G11: 33' | H11: 2 | I11: Single Family
A12: PALM | B12: 1700 | C12: 3 | D12: 2.5 | E12: 1-Car | F12: 20' | G12: 50' | H12: 2 | I12: Townhome
A13: ELM | B13: 1712 | C13: 4 | D13: 2.5 | E13: 2-Car | F13: 28' | G13: 35' | H13: 2 | I13: Single Family
A14: HAZEL | B14: 1713 | C14: 4 | D14: 2.5 | E14: 2-Car | F14: 30' | G14: 43' | H14: 2 | I14: Single Family
... A24: MAGNOLIA | B24: 2771 | C24: 4 | D24: 3 | E24: 2-Car | F24: 38' | G24: 40' | H24: 2 | I24: Single Family

Sheet Exclusions & Notes
A1: EXCLUSIONS - Items NOT Included in Pricing
A2: • Stepped foundations (assumes flat lots)
A3: • Fill Import/Export (assumes balanced lots)
A4: • Rock Hammering
A5: • Curb Cuts & Approaches
A6: • City Sidewalks
A7: • SDC Fees / Permitting Fees
A8: • ARC Review Fees
A9: • Utility Connection Fees (beyond standard)
A10: • Landscaping (beyond standard allowance)
A11: • Fencing
A12: • Refrigerators
... A25: • All finishes per Inclusive Features Sheet unless upgrades selected
