Workbook

Sheet Deal Analyzer
A1: VANROCK HOLDINGS — SL DEAL SHEET
A3: PROPERTY ADDRESS
B4: Street Address | E4: City
B5: State | C5: SC | E5: Zip Code
A7: PROJECT INFO
B8: Purchase Price | E8: Closing / Purchase Date
B9: Project Duration (Days) | C9: 120 | E9: Calculated Sale Date | F9: =IF(AND(F8<>"",C9<>""),F8+C9,"")
B10: Interest Rate (Annual %) | C10: 0.1
A12: FLOOR PLAN (from Pricing Guide)
A13: Most likely scattered lot builds: ATLAS (1,592 SF infill), DOGWOOD (1,541 SF w/ garage), PALMETTO (1,304 SF affordable), HOLLY (2,000 SF suburban)
B14: Select Floor Plan | C14: ATLAS | E14: Total Contract Cost | F14: =IFERROR(INDEX('Floor Plans'!$R$4:$R$33,MATCH(C14,'Floor Plans'!$B$4:$B$33,0)),0) -> 192451.9
B15: Bedrooms | C15: =IFERROR(INDEX('Floor Plans'!$D$4:$D$33,MATCH(C14,'Floor Plans'!$B$4:$B$33,0)),"") -> 3 | E15: Bathrooms | F15: =IFERROR(INDEX('Floor Plans'!$E$4:$E$33,MATCH(C14,'Floor Plans'!$B$4:$B$33,0)),"") -> 2.5
B16: Square Footage | C16: =IFERROR(INDEX('Floor Plans'!$C$4:$C$33,MATCH(C14,'Floor Plans'!$B$4:$B$33,0)),0) -> 1592 | E16: Garage | F16: =IFERROR(INDEX('Floor Plans'!$F$4:$F$33,MATCH(C14,'Floor Plans'!$B$4:$B$33,0)),"") -> None
B17: Stories | C17: =IFERROR(INDEX('Floor Plans'!$G$4:$G$33,MATCH(C14,'Floor Plans'!$B$4:$B$33,0)),"") -> 2 | E17: Type | F17: =IFERROR(INDEX('Floor Plans'!$H$4:$H$33,MATCH(C14,'Floor Plans'!$B$4:$B$33,0)),"") -> Single Family
B18: Width / Depth | C18: =IFERROR(INDEX('Floor Plans'!$I$4:$I$33,MATCH(C14,'Floor Plans'!$B$4:$B$33,0)),"")&" x "&IFERROR(INDEX('Floor Plans'!$J$4:$J$33,MATCH(C14,'Floor Plans'!$B$4:$B$33,0)),"") -> 24' x 33' | E18: Upgrade Package | F18: C
B19: Upgrade $/SF | C19: =IF(F18="A",8,IF(F18="B",6,IF(F18="C",4.5,IF(F18="D",3,0)))) -> 4.5 | E19: Total Upgrade Cost | F19: =C19*C16 -> 7164
A21: MUNICIPALITY SOFT COSTS (from Municipalities tab)
B22: Select Municipality | C22: City of Greenville | E22: Total Municipality Soft Costs | F22: =IFERROR(INDEX(Municipalities!$K$4:$K$33,MATCH(C22,Municipalities!$B$4:$B$33,0)),0) -> 0
B23: Water Tap Fee | C23: =IFERROR(INDEX(Municipalities!$C$4:$C$33,MATCH(C22,Municipalities!$B$4:$B$33,0)),0) -> 0 | E23: Sewer Tap Fee | F23: =IFERROR(INDEX(Municipalities!$D$4:$D$33,MATCH(C22,Municipalities!$B$4:$B$33,0)),0) -> 0
B24: Gas Tap Fee | C24: =IFERROR(INDEX(Municipalities!$E$4:$E$33,MATCH(C22,Municipalities!$B$4:$B$33,0)),0) -> 0 | E24: Permitting Fees | F24: =IFERROR(INDEX(Municipalities!$F$4:$F$33,MATCH(C22,Municipalities!$B$4:$B$33,0)),0) -> 0
B25: Impact Fees | C25: =IFERROR(INDEX(Municipalities!$G$4:$G$33,MATCH(C22,Municipalities!$B$4:$B$33,0)),0) -> 0 | E25: Architect Fee | F25: =IFERROR(INDEX(Municipalities!$H$4:$H$33,MATCH(C22,Municipalities!$B$4:$B$33,0)),0) -> 0
B26: Engineering | C26: =IFERROR(INDEX(Municipalities!$I$4:$I$33,MATCH(C22,Municipalities!$B$4:$B$33,0)),0) -> 0 | E26: Survey | F26: =IFERROR(INDEX(Municipalities!$J$4:$J$33,MATCH(C22,Municipalities!$B$4:$B$33,0)),0) -> 0
A28: SITE-SPECIFIC COSTS (or use Site Work Itemization tab)
B29: Site Work / Grading | C29: =IFERROR('Site Work Itemization'!C22,0) -> 0 | E29: Other Site Costs | F29: 0
A31: FIXED PER-HOUSE COSTS
B32: Builder Warranty | C32: =5000 -> 5000 | E32: Builder's Risk Insurance | F32: =1500 -> 1500
B33: PO Fee | C33: =3000 -> 3000 | E33: PM Fee | F33: =3500 -> 3500
B34: Builder Fee | C34: =17000 -> 17000 | E34: Closing Costs (5% of Purch.) | F34: =IF(C8="",0,C8*0.05) -> 0
B35: Utility Charges | C35: =ROUND(C9/30,0)*350 -> 1400 | E35: Misc | F35: =11000 -> 11000
A37: SALES INFO
B38: Asset Sales Price (ASP) | E38: Selling Costs (8.5% of ASP) | F38: =IF(C38="",0,C38*0.085) -> 0
B39: Selling Concessions ($) | C39: 0
A41: COST SUMMARY & FINANCING
B42: Total Contract Cost | C42: =F14 -> 192451.9 | E42: Total Upgrade Cost | F42: =F19 -> 7164
B43: Total Municipality Soft Costs | C43: =F22 -> 0 | E43: Total Site-Specific Costs | F43: =C29+F29 -> 0
B44: Total Fixed Per-House | C44: =C32+F32+C33+F33+C34+F35 -> 41000 | E44: Closing Costs + Utilities | F44: =F34+C35 -> 1400
B45: TOTAL PROJECT COST (excl. carry) | C45: =IF(C8="",0,C8)+C42+F42+C43+F43+C44+F44 -> 242015.9 | E45: Lender LTC (85%) | F45: =C45*0.85 -> 205713.52
B46: Equity Required (before carry) | C46: =C45-F45 -> 36302.385 | E46: Loan Amount | F46: =F45 -> 205713.52
A48: CARRY COSTS & COST OF CAPITAL
B49: Interest on Loan | C49: =ROUND(F46*(C10/360)*C9,0) -> 6857 | E49: Duration (Days) | F49: =C9 -> 120
...

Sheet Instructions
A1: SL DEAL SHEET — INSTRUCTIONS
B4: OVERVIEW
B5: This workbook is VanRock Holdings' back-of-the-napkin deal analyzer for scattered lot acquisitions built with Homes. It allows you to quickly evaluate whether a lot purchase and build makes financial sense before committing capital. Select a floor plan and municipality, enter the lot purchase price and expected sale price, and the sheet calculates your net profit margin with a color-coded go/no-go indicator.
B7: TAB-BY-TAB GUIDE
A9: 1. | B9: DEAL ANALYZER (Input + Results) — This is the main working tab. Start at the top with the property address and work your way down. Yellow cells are your inputs. Green cells pull automatically from the Floor Plans and Municipalities tabs. The bottom section shows your all-in cost, net profit, and margin with color coding.
A11: 2. | B11: FLOOR PLANS — Contains all 22 floor plans with the full 7-category cost breakdown (Sticks & Bricks, Upgrades, Lot Prep, Vertical, Soft Costs, Contingency, Builder Fee). Column R auto-sums to Total Contract Cost. You can edit any blue cell to adjust pricing as updates their guide.
A13: 3. | B13: STICKS & BRICKS DETAIL — The full 53-line-item breakdown of construction costs per plan. This is the detailed backup for the Sticks & Bricks totals on the Floor Plans tab. Reference only unless you need to audit a specific line item.
A15: 4. | B15: MUNICIPALITIES — Enter standardized soft costs (tap fees, permitting, impact fees, architect, engineering, survey) for each municipality you build in. Once populated, selecting a municipality on the Deal Analyzer auto-fills all soft cost fields.
A17: 5. | B17: SITE WORK ITEMIZATION — Optional detailed breakdown of site work costs (clearing, grading, fill, retaining walls, etc.). The total from this tab flows into the Site Work / Grading field on the Deal Analyzer. Use this for complex lots that need detailed site cost tracking.
A19: 6. | B19: COMPS — Enter comparable sales with MLS links, beds/baths/SF, location, sale date, and price. The sheet calculates average, median, and average $/SF to support your ASP assumption.
A21: 7. | B21: UPGRADES — 's upgrade menu (Hardie siding, elevation upgrades, interior packages at Classic and Elegance tiers). Reference when selecting upgrade packages on the Deal Analyzer.
A23: 8. | B23: JENNY'S CHECKLIST — Verification checklist for Jenny to validate soft costs, sticks & bricks totals, and site work estimates against actuals before finalizing a deal.
B25: HOW TO USE
A27: 1. | B27: Enter the property address, city, state, and zip at the top of the Deal Analyzer tab.
A28: 2. | B28: Enter the lot purchase price, closing date, estimated project duration (120–450 days), and interest rate.
A29: 3. | B29: Select the floor plan from the dropdown. All plan specs and the total contract cost will auto-populate.
A30: 4. | B30: Select the municipality. All soft costs will auto-populate (assuming the Municipalities tab has been filled in for that jurisdiction).
A31: 5. | B31: Enter any site-specific costs (or use the Site Work Itemization tab for complex lots).
A32: 6. | B32: Select an upgrade package (A/B/C/D or None).
A33: 7. | B33: Enter the Asset Sales Price (ASP) based on your comps analysis and any selling concessions.
A34: 8. | B34: Review the Deal Results section at the bottom. Green = strong deal (10%+), Blue = good (7–10%), Yellow = marginal (5–7%), Red = no go (below 5%).
B36: MOST LIKELY FLOOR PLANS FOR SCATTERED LOTS
B38: Based on our current pipeline and lot inventory, the four plans we are most likely to build on scattered lots are:
A40: 1. | B40: ATLAS — 1,592 SF, 3/2.5, no garage, 2-story, 24' x 33' footprint. Our most versatile infill plan for narrow urban lots. No garage keeps costs down and fits tight setbacks.
A41: 2. | B41: DOGWOOD — 1,541 SF, 3/2.5, 2-car garage, 2-story, 29' x 36'. Strong suburban scattered lot plan with garage. Works on standard 50'+ lots.
A42: 3. | B42: PALMETTO — 1,304 SF, 3/2.5, no garage, 2-story townhome, 20' x 42'. Ideal for affordable housing scattered lots where we need to hit lower price points.
A43: 4. | B43: HOLLY — 2,000 SF, 4/2.5, 2-car garage, 2-story, 29' x 48'. Our go-to for larger suburban lots where the comps support a higher ASP.
B45: IMPORTANT NOTES
B47: All contract pricing includes a fixed $25,000 Builder Fee and contingency capped at the lower of $10,000 or 5% of costs. Lot Prep and Soft Costs each have a $15,000 minimum per contract terms. The fixed per-house costs on the Deal Analyzer (Builder Warranty, Builder's Risk, PO Fee, PM Fee, Builder Fee) are VanRock's costs on top of the contract and should be updated if our standard rates change.
B49: Municipality soft costs should be verified by Jenny against current fee schedules before relying on them for deal analysis. Tap fees and permitting costs change periodically.

Sheet Floor Plans
A1: FLOOR PLAN BUILD COSTS
A2: Source: Builder Pricing Guide. Column R (Total Contract) is referenced by Deal Analyzer. Blue cells are editable.
A3: # | B3: Plan Name | C3: Sq Ft | D3: Beds | E3: Baths | F3: Garage | G3: Stories | H3: Type | I3: Width | J3: Depth | K3: 1. Sticks & Bricks | L3: 2. Upgrades | M3: 3. Lot Prep | N3: 4. Vert Costs | O3: 5. Soft Costs | P3: 6. Contingency | Q3: 7. Builder Fee | R3: TOTAL CONTRACT
A4: 1 | B4: TULIP | C4: 1170 | D4: 3 | E4: 2 | F4: 1-Car | G4: 1 | H4: Single Family | I4: 30' | J4: 50' | K4: 96076 | L4: 3500 | M4: 15000 | N4: 0 | O4: 15000 | P4: 6478.8 | Q4: 25000 | R4: =SUM(K4:Q4) -> 161054.8
A5: 2 | B5: ASH | C5: 1188 | D5: 3 | E5: 2 | F5: 2-Car | G5: 1 | H5: Single Family | I5: 29' | J5: 36' | K5: 97831 | L5: 3500 | M5: 15000 | N5: 0 | O5: 15000 | P5: 6566.55 | Q5: 25000 | R5: =SUM(K5:Q5) -> 162897.55
A6: 3 | B6: PALMETTO | C6: 1304 | D6: 3 | E6: 2.5 | F6: None | G6: 2 | H6: Townhome | I6: 20' | J6: 42' | K6: 105668 | L6: 3500 | M6: 15000 | N6: 0 | O6: 15000 | P6: 6958.4 | Q6: 25000 | R6: =SUM(K6:Q6) -> 171126.4
A7: 4 | B7: LILAC | C7: 1383 | D7: 3 | E7: 3 | F7: 1-Car | G7: 1.5 | H7: Single Family | I7: 30' | J7: 46' | K7: 113798 | L7: 3500 | M7: 15000 | N7: 0 | O7: 15000 | P7: 7364.9 | Q7: 25000 | R7: =SUM(K7:Q7) -> 179662.9
A8: 5 | B8: BANYAN | C8: 1400 | D8: 3 | E8: 3 | F8: 2-Car | G8: 3 | H8: Single Family | I8: 28' | J8: 24' | K8: 115510 | L8: 3500 | M8: 15000 | N8: 0 | O8: 15000 | P8: 7450.5 | Q8: 25000 | R8: =SUM(K8:Q8) -> 181460.5
A9: 6 | B9: JASMINE | C9: 1500 | D9: 3 | E9: 2.5 | F9: 1-Car | G9: 2 | H9: Townhome | I9: 20' | J9: 49' | K9: 120582 | L9: 3500 | M9: 15000 | N9: 0 | O9: 15000 | P9: 7704.1 | Q9: 25000 | R9: =SUM(K9:Q9) -> 186786.1
A10: 7 | B10: DOGWOOD | C10: 1541 | D10: 3 | E10: 2.5 | F10: 2-Car | G10: 2 | H10: Single Family | I10: 29' | J10: 36' | K10: 123967 | L10: 3500 | M10: 15000 | N10: 0 | O10: 15000 | P10: 7873.35 | Q10: 25000 | R10: =SUM(K10:Q10) -> 190340.35
A11: 8 | B11: SPRUCE | C11: 1545 | D11: 3 | E11: 2 | F11: 2-Car | G11: 1 | H11: Single Family | I11: 39' | J11: 54' | K11: 122622 | L11: 3500 | M11: 15000 | N11: 0 | O11: 15000 | P11: 7806.1 | Q11: 25000 | R11: =SUM(K11:Q11) -> 188928.1
A12: 9 | B12: ATLAS | C12: 1592 | D12: 3 | E12: 2.5 | F12: None | G12: 2 | H12: Single Family | I12: 24' | J12: 33' | K12: 125978 | L12: 3500 | M12: 15000 | N12: 0 | O12: 15000 | P12: 7973.9 | Q12: 25000 | R12: =SUM(K12:Q12) -> 192451.9
A13: 10 | B13: PALM | C13: 1700 | D13: 3 | E13: 2.5 | F13: 1-Car | G13: 2 | H13: Townhome | I13: 20' | J13: 50' | K13: 134662 | L13: 3500 | M13: 15000 | N13: 0 | O13: 15000 | P13: 8408.1 | Q13: 25000 | R13: =SUM(K13:Q13) -> 201570.1
A14: 11 | B14: ELM | C14: 1712 | D14: 4 | E14: 2.5 | F14: 2-Car | G14: 2 | H14: Single Family | I14: 28' | J14: 35' | K14: 136009 | L14: 3500 | M14: 15000 | N14: 0 | O14: 15000 | P14: 8475.45 | Q14: 25000 | R14: =SUM(K14:Q14) -> 202984.45
A15: 12 | B15: HAZEL | C15: 1713 | D15: 4 | E15: 2.5 | F15: 2-Car | G15: 2 | H15: Single Family | I15: 30' | J15: 43' | K15: 136078 | L15: 3500 | M15: 15000 | N15: 0 | O15: 15000 | P15: 8478.9 | Q15: 25000 | R15: =SUM(K15:Q15) -> 203056.9
... A25: 22 | B25: MAGNOLIA | C25: 2771 | D25: 4 | E25: 3 | F25: 2-Car | G25: 2 | H25: Single Family | I25: 38' | J25: 40' | K25: 213313 | L25: 3500 | M25: 15000 | N25: 0 | O25: 15000 | P25: 10000 | Q25: 25000 | R25: =SUM(K25:Q25) -> 281813
A26: 23 | R26: =SUM(K26:Q26) -> 0
A27: 24 | R27: =SUM(K27:Q27) -> 0
A28: 25 | R28: =SUM(K28:Q28) -> 0
A29: 26 | R29: =SUM(K29:Q29) -> 0
A30: 27 | R30: =SUM(K30:Q30) -> 0
A31: 28 | R31: =SUM(K31:Q31) -> 0
A32: 29 | R32: =SUM(K32:Q32) -> 0
A33: 30 | R33: =SUM(K33:Q33) -> 0

Sheet Sticks & Bricks Detail
A1: STICKS & BRICKS — ITEMIZED COSTS PER FLOOR PLAN
A2: Line Item | B2: TULIP | C2: ASH | D2: PALMETTO | E2: LILAC | F2: BANYAN | G2: JASMINE | H2: DOGWOOD | I2: SPRUCE | J2: ATLAS | K2: PALM | L2: ELM | M2: HAZEL | N2: ASPEN 2-Story | O2: FIG | P2: WILLOW | Q2: HOLLY | R2: WHITE OAK | S2: FIR | T2: ASPEN 3-Story | U2: CHERRY | V2: RED OAK | W2: MAGNOLIA
A3: Square Footage | B3: 1170 | C3: 1188 | D3: 1304 | E3: 1383 | F3: 1400 | G3: 1500 | H3: 1541 | I3: 1545 | J3: 1592 | K3: 1700 | L3: 1712 | M3: 1713 | N3: 1788 | O3: 1798 | P3: 1857 | Q3: 2000 | R3: 2005 | S3: 2072 | T3: 2157 | U3: 2214 | V3: 2217 | W3: 2771
A4: Dumpster | B4: 3000 | C4: 3000 | D4: 3000 | E4: 3000 | F4: 3000 | G4: 3000 | H4: 3000 | I4: 3000 | J4: 3000 | K4: 3000 | L4: 3000 | M4: 3000 | N4: 3000 | O4: 3000 | P4: 3000 | Q4: 3000 | R4: 3000 | S4: 3000 | T4: 3000 | U4: 3000 | V4: 3000 | W4: 3000
A5: Utilities | B5: 600 | C5: 600 | D5: 600 | E5: 600 | F5: 600 | G5: 600 | H5: 600 | I5: 600 | J5: 600 | K5: 600 | L5: 600 | M5: 600 | N5: 600 | O5: 600 | P5: 600 | Q5: 600 | R5: 600 | S5: 600 | T5: 600 | U5: 600 | V5: 600 | W5: 600
A6: Portable Toilet | B6: 875 | C6: 875 | D6: 875 | E6: 875 | F6: 875 | G6: 875 | H6: 875 | I6: 875 | J6: 875 | K6: 875 | L6: 875 | M6: 875 | N6: 875 | O6: 875 | P6: 875 | Q6: 875 | R6: 875 | S6: 875 | T6: 875 | U6: 875 | V6: 875 | W6: 875
A7: Permit Box | B7: 50 | C7: 50 | D7: 50 | E7: 50 | F7: 50 | G7: 50 | H7: 50 | I7: 50 | J7: 50 | K7: 50 | L7: 50 | M7: 50 | N7: 50 | O7: 50 | P7: 50 | Q7: 50 | R7: 50 | S7: 50 | T7: 50 | U7: 50 | V7: 50 | W7: 50
A8: Termite | B8: 250 | C8: 250 | D8: 250 | E8: 250 | F8: 250 | G8: 250 | H8: 250 | I8: 250 | J8: 250 | K8: 250 | L8: 250 | M8: 250 | N8: 250 | O8: 250 | P8: 250 | Q8: 250 | R8: 250 | S8: 250 | T8: 250 | U8: 250 | V8: 250 | W8: 250
A9: Lumber All Floors | B9: 6892 | C9: 6998 | D9: 7681 | E9: 8146 | F9: 8246 | G9: 8836 | H9: 9077 | I9: 9101 | J9: 9378 | K9: 10014 | L9: 10084 | M9: 10090 | N9: 10532 | O9: 10591 | P9: 10939 | Q9: 11781 | R9: 11810 | S9: 12205 | T9: 12706 | U9: 13042 | V9: 13059 | W9: 16323
A10: Framing Labor | B10: 4699 | C10: 4772 | D10: 5238 | E10: 5555 | F10: 5623 | G10: 6025 | H10: 6190 | I10: 6206 | J10: 6395 | K10: 6828 | L10: 6877 | M10: 6881 | N10: 7182 | O10: 7222 | P10: 7459 | Q10: 8033 | R10: 8054 | S10: 8323 | T10: 8664 | U10: 8893 | V10: 8905 | W10: 11130
A11: Stairs | B11: 408 | C11: 414 | D11: 455 | E11: 483 | F11: 488 | G11: 523 | H11: 538 | I11: 539 | J11: 556 | K11: 593 | L11: 597 | M11: 598 | N11: 624 | O11: 627 | P11: 648 | Q11: 698 | R11: 700 | S11: 723 | T11: 753 | U11: 773 | V11: 774 | W11: 967
A12: Roof Trusses | B12: 2867 | C12: 2911 | D12: 3196 | E12: 3389 | F12: 3431 | G12: 3676 | H12: 3776 | I12: 3786 | J12: 3902 | K12: 4166 | L12: 4196 | M12: 4198 | N12: 4382 | O12: 4406 | P12: 4551 | Q12: 4902 | R12: 4914 | S12: 5078 | T12: 5286 | U12: 5426 | V12: 5433 | W12: 6791
A13: I-Joist/EWP | B13: 2421 | C13: 2458 | D13: 2698 | E13: 2862 | F13: 2897 | G13: 3104 | H13: 3189 | I13: 3197 | J13: 3295 | K13: 3518 | L13: 3543 | M13: 3545 | N13: 3700 | O13: 3721 | P13: 3843 | Q13: 4139 | R13: 4149 | S13: 4288 | T13: 4464 | U13: 4582 | V13: 4588 | W13: 5735
A14: Roofing Shingle | B14: 2145 | C14: 2178 | D14: 2391 | E14: 2536 | F14: 2567 | G14: 2751 | H14: 2826 | I14: 2833 | J14: 2920 | K14: 3118 | L14: 3140 | M14: 3141 | N14: 3279 | O14: 3297 | P14: 3406 | Q14: 3668 | R14: 3677 | S14: 3800 | T14: 3956 | U14: 4060 | V14: 4066 | W14: 5082
... A56: STICKS & BRICKS TOTAL | B56: 96076 | C56: 97831 | D56: 105668 | E56: 113798 | F56: 115510 | G56: 120582 | H56: 123967 | I56: 122622 | J56: 125978 | K56: 134662 | L56: 136009 | M56: 136078 | N56: 141355 | O56: 145350 | P56: 145710 | Q56: 156262 | R56: 156615 | S56: 165696 | T56: 171846 | U56: 173637 | V56: 173846 | W56: 213313

Sheet Municipalities
A1: MUNICIPALITY SOFT COSTS
A2: Enter standardized soft costs per municipality. Deal Analyzer pulls full row via municipality selection. Blue = inputs.
A3: # | B3: Municipality | C3: Water Tap | D3: Sewer Tap | E3: Gas Tap | F3: Permitting | G3: Impact Fees | H3: Architect | I3: Engineering | J3: Survey | K3: TOTAL SOFT
A4: 1 | B4: City of Greenville | C4: 0 | D4: 0 | E4: 0 | F4: 0 | G4: 0 | H4: 0 | I4: 0 | J4: 0 | K4: =SUM(C4:J4) -> 0
A5: 2 | B5: City of Spartanburg | C5: 0 | D5: 0 | E5: 0 | F5: 0 | G5: 0 | H5: 0 | I5: 0 | J5: 0 | K5: =SUM(C5:J5) -> 0
A6: 3 | B6: City of Greer | C6: 0 | D6: 0 | E6: 0 | F6: 0 | G6: 0 | H6: 0 | I6: 0 | J6: 0 | K6: =SUM(C6:J6) -> 0
A7: 4 | B7: City of Mauldin | C7: 0 | D7: 0 | E7: 0 | F7: 0 | G7: 0 | H7: 0 | I7: 0 | J7: 0 | K7: =SUM(C7:J7) -> 0
A8: 5 | B8: City of Simpsonville | C8: 0 | D8: 0 | E8: 0 | F8: 0 | G8: 0 | H8: 0 | I8: 0 | J8: 0 | K8: =SUM(C8:J8) -> 0
A9: 6 | B9: Greenville County | C9: 0 | D9: 0 | E9: 0 | F9: 0 | G9: 0 | H9: 0 | I9: 0 | J9: 0 | K9: =SUM(C9:J9) -> 0
A10: 7 | B10: Spartanburg County | C10: 0 | D10: 0 | E10: 0 | F10: 0 | G10: 0 | H10: 0 | I10: 0 | J10: 0 | K10: =SUM(C10:J10) -> 0
A11: 8 | B11: Town of Travelers Rest | C11: 0 | D11: 0 | E11: 0 | F11: 0 | G11: 0 | H11: 0 | I11: 0 | J11: 0 | K11: =SUM(C11:J11) -> 0
A12: 9 | B12: Town of Lyman | C12: 0 | D12: 0 | E12: 0 | F12: 0 | G12: 0 | H12: 0 | I12: 0 | J12: 0 | K12: =SUM(C12:J12) -> 0
A13: 10 | B13: Town of Duncan | C13: 0 | D13: 0 | E13: 0 | F13: 0 | G13: 0 | H13: 0 | I13: 0 | J13: 0 | K13: =SUM(C13:J13) -> 0
A14: 11 | B14: Town of Wellford | C14: 0 | D14: 0 | E14: 0 | F14: 0 | G14: 0 | H14: 0 | I14: 0 | J14: 0 | K14: =SUM(C14:J14) -> 0
A15: 12 | B15: Town of Inman | C15: 0 | D15: 0 | E15: 0 | F15: 0 | G15: 0 | H15: 0 | I15: 0 | J15: 0 | K15: =SUM(C15:J15) -> 0
... A18: 15 | B18: Laurens County | C18: 0 | D18: 0 | E18: 0 | F18: 0 | G18: 0 | H18: 0 | I18: 0 | J18: 0 | K18: =SUM(C18:J18) -> 0
A19: 16 | K19: =SUM(C19:J19) -> 0
A20: 17 | K20: =SUM(C20:J20) -> 0
A21: 18 | K21: =SUM(C21:J21) -> 0
A22: 19 | K22: =SUM(C22:J22) -> 0
A23: 20 | K23: =SUM(C23:J23) -> 0
A24: 21 | K24: =SUM(C24:J24) -> 0
A25: 22 | K25: =SUM(C25:J25) -> 0
A26: 23 | K26: =SUM(C26:J26) -> 0
A27: 24 | K27: =SUM(C27:J27) -> 0
A28: 25 | K28: =SUM(C28:J28) -> 0
A29: 26 | K29: =SUM(C29:J29) -> 0
A30: 27 | K30: =SUM(C30:J30) -> 0
... A33: 30 | K33: =SUM(C33:J33) -> 0

Sheet Site Work Itemization
A1: SITE WORK — ITEMIZED BREAKDOWN
A2: The TOTAL (row 22) flows into the Deal Analyzer Site Work / Grading field automatically. Blue = inputs.
A3: # | B3: Site Work Item | C3: Cost | D3: Notes
A4: 1 | B4: Clearing & Demolition | C4: 0
A5: 2 | B5: Tree Removal | C5: 0
A6: 3 | B6: Grading & Earthwork | C6: 0
A7: 4 | B7: Fill Dirt (Import) | C7: 0
A8: 5 | B8: Cut & Export | C8: 0
A9: 6 | B9: Retaining Walls | C9: 0
A10: 7 | B10: Erosion Control / Silt Fence | C10: 0
A11: 8 | B11: Storm Water Management | C11: 0
A12: 9 | B12: Driveway Apron / Curb Cut | C12: 0
A13: 10 | B13: Temporary Road / Access | C13: 0
A14: 11 | B14: Utility Trenching (beyond std) | C14: 0
A15: 12 | B15: Rock Removal / Hammering | C15: 0
... A21: 18 | B21: Other | C21: 0
B22: TOTAL SITE WORK | C22: =SUM(C4:C21) -> 0

Sheet Comps
A1: COMPARABLE SALES
A3: # | B3: Comp Link / MLS | C3: Beds | D3: Baths | E3: Sq Ft | F3: Location / Address | G3: Sale Date | H3: Sale Price
A4: 1
A5: 2
A6: 3
A7: 4
A8: 5
A9: 6
A10: 7
A11: 8
A12: 9
A13: 10
A14: 11
A15: 12
... A18: 15
D20: Avg SF: | E20: =IF(COUNTA(E4:E18)>0,AVERAGE(E4:E18),"") | H20: =IF(COUNTA(H4:H18)>0,AVERAGE(H4:H18),"")
E21: Median: | H21: =IF(COUNTA(H4:H18)>0,MEDIAN(H4:H18),"")
E22: Avg $/SF: | H22: =IF(AND(COUNTA(H4:H18)>0,COUNTA(E4:E18)>0),AVERAGE(H4:H18)/AVERAGE(E4:E18),"")

Sheet Upgrades
A1: UPGRADE OPTIONS
A3: EXTERIOR | B3: Hardie Color-Plus Siding | C3: $3,500 - $4,000 | D3: Premium fiber cement siding
A4: EXTERIOR | B4: Elevation Upgrade - 1 | C4: $3,000 - $4,000 | D4: Enhanced architectural details
A5: EXTERIOR | B5: Elevation Upgrade - 2 | C5: $3,000 - $4,000 | D5: Premium elevation design
A6: INTERIOR - CLASSIC | B6: Foxcroft Classic | C6: $4,059 | D6: Classic finish level
A7: INTERIOR - CLASSIC | B7: Midwood Classic | C7: $3,792 | D7: Classic finish level
A8: INTERIOR - CLASSIC | B8: Madison Classic | C8: $3,852 | D8: Classic finish level
A9: INTERIOR - CLASSIC | B9: Uptown Classic | C9: $3,984 | D9: Classic finish level
A10: INTERIOR - ELEGANCE | B10: Foxcroft Elegance | C10: $6,181 | D10: Elegance finish level
A11: INTERIOR - ELEGANCE | B11: Midwood Elegance | C11: $6,468 | D11: Elegance finish level
A12: INTERIOR - ELEGANCE | B12: Madison Elegance | C12: $8,197 | D12: Premium elegance finishes
A13: INTERIOR - ELEGANCE | B13: Uptown Elegance | C13: $8,623 | D13: Top-tier elegance finishes

Sheet Jenny's Checklist
A1: JENNY'S VERIFICATION CHECKLIST — DEAL COST REVIEW
A2: Use this checklist to verify soft costs, sticks & bricks totals, and site work estimates against actual fee schedules and contractor quotes before finalizing any deal.
A3: # | B3: Verification Item | C3: Status | D3: Date Verified | E3: Notes / Source
A4: MUNICIPALITY SOFT COSTS
A5: 1 | B5: Verify water tap fee against current municipality fee schedule | C5: Pending
A6: 2 | B6: Verify sewer tap fee against current municipality fee schedule | C6: Pending
A7: 3 | B7: Verify gas tap fee against current gas utility provider rates | C7: Pending
A8: 4 | B8: Verify permitting fees against current municipality building dept. | C8: Pending
A9: 5 | B9: Verify impact fees (if applicable) against current ordinance | C9: Pending
A10: 6 | B10: Verify architect fee matches current contract / quote | C10: Pending
A11: 7 | B11: Verify engineering fee matches current contract / quote | C11: Pending
A12: 8 | B12: Verify survey fee matches current surveyor quote | C12: Pending
A13: 9 | B13: Confirm municipality selected matches actual lot jurisdiction | C13: Pending
A14: 10 | B14: Check for any new fees added since last update (ARC, stormwater, etc.) | C14: Pending
A16: STICKS & BRICKS / CONTRACT COSTS
A17: 1 | B17: Confirm selected floor plan matches lot dimensions and setbacks | C17: Pending
A18: 2 | B18: Verify Sticks & Bricks total against current Pricing Guide | C18: Pending
A19: 3 | B19: Verify Lot Prep allowance ($15K min) is sufficient for this lot | C19: Pending
A20: 4 | B20: Verify Soft Costs allowance ($15K min) within contract | C20: Pending
A21: 5 | B21: Verify Contingency calculation (lower of $10K or 5%) | C21: Pending
A22: 6 | B22: Confirm Builder Fee is $25,000 per contract terms | C22: Pending
A23: 7 | B23: Check if any Added Vertical costs apply (stepped foundation, rock, fill) | C23: Pending
A24: 8 | B24: Verify upgrade selections and pricing against Upgrades Menu | C24: Pending
A25: 9 | B25: Confirm contract total matches Floor Plans tab total | C25: Pending
A26: 10 | B26: Check for any price updates or change orders since last quote | C26: Pending
A28: SITE WORK / GRADING
A29: 1 | B29: Obtain grading contractor quote for this specific lot | C29: Pending
A30: 2 | B30: Verify clearing / demo scope and estimate | C30: Pending
A31: 3 | B31: Check for rock presence (may need hammering allowance) | C31: Pending
A32: 4 | B32: Verify fill import/export needs based on topo survey | C32: Pending
A33: 5 | B33: Confirm retaining wall requirements (if any) per engineering | C33: Pending
A34: 6 | B34: Verify erosion control / silt fence requirements per municipality | C34: Pending
A35: 7 | B35: Confirm driveway apron / curb cut costs with municipality | C35: Pending
A36: 8 | B36: Check stormwater management requirements | C36: Pending
A37: 9 | B37: Verify utility trenching scope (beyond standard 50 LF) | C37: Pending
A38: 10 | B38: Confirm Site Work Itemization tab total matches Deal Analyzer | C38: Pending
A40: GENERAL DEAL VERIFICATION
A41: 1 | B41: Verify purchase price matches executed contract / LOI | C41: Pending
A42: 2 | B42: Confirm closing date and project duration are realistic | C42: Pending
A43: 3 | B43: Verify interest rate matches current lender terms | C43: Pending
...
